2023-06-15 04:48:40 WARNING django.request Not Found: /
2023-06-15 04:48:40 WARNING django.server "GET / HTTP/1.1" 404 2425
2023-06-15 05:11:26 WARNING django.request Not Found: /
2023-06-15 05:11:26 WARNING django.server "GET / HTTP/1.1" 404 2425
2023-06-15 05:32:46 WARNING django.request Bad Request: /api/v1/notifications/create
2023-06-15 05:32:46 WARNING django.server "POST /api/v1/notifications/create HTTP/1.1" 400 36
2023-06-15 05:33:00 WARNING django.request Bad Request: /api/v1/notifications/create
2023-06-15 05:33:00 WARNING django.server "POST /api/v1/notifications/create HTTP/1.1" 400 51
2023-06-15 05:33:06 WARNING django.request Bad Request: /api/v1/notifications/create
2023-06-15 05:33:06 WARNING django.server "POST /api/v1/notifications/create HTTP/1.1" 400 41
2023-06-15 05:35:17 WARNING django.request Bad Request: /api/v1/notifications/create
2023-06-15 05:35:17 WARNING django.server "POST /api/v1/notifications/create HTTP/1.1" 400 92
2023-06-15 05:36:03 WARNING django.request Bad Request: /api/v1/notifications/create
2023-06-15 05:36:03 WARNING django.server "POST /api/v1/notifications/create HTTP/1.1" 400 92
2023-06-15 05:36:33 WARNING django.request Bad Request: /api/v1/notifications/create
2023-06-15 05:36:33 WARNING django.server "POST /api/v1/notifications/create HTTP/1.1" 400 92
2023-06-15 05:36:47 WARNING django.request Bad Request: /api/v1/notifications/create
2023-06-15 05:36:47 WARNING django.server "POST /api/v1/notifications/create HTTP/1.1" 400 41
2023-06-15 05:36:55 WARNING django.request Bad Request: /api/v1/notifications/create
2023-06-15 05:36:55 WARNING django.server "POST /api/v1/notifications/create HTTP/1.1" 400 43
2023-06-15 05:37:05 ERROR django.request Internal Server Error: /api/v1/notifications/create
Traceback (most recent call last):
  File "/home/suraj/.local/lib/python3.10/site-packages/django/db/backends/utils.py", line 89, in _execute
    return self.cursor.execute(sql, params)
  File "/home/suraj/.local/lib/python3.10/site-packages/django/db/backends/sqlite3/base.py", line 328, in execute
    return super().execute(query, params)
sqlite3.IntegrityError: NOT NULL constraint failed: notifications_fcmtokenobject.user_id

The above exception was the direct cause of the following exception:

Traceback (most recent call last):
  File "/home/suraj/.local/lib/python3.10/site-packages/django/core/handlers/exception.py", line 55, in inner
    response = get_response(request)
  File "/home/suraj/.local/lib/python3.10/site-packages/django/core/handlers/base.py", line 197, in _get_response
    response = wrapped_callback(request, *callback_args, **callback_kwargs)
  File "/home/suraj/.local/lib/python3.10/site-packages/django/views/decorators/csrf.py", line 56, in wrapper_view
    return view_func(*args, **kwargs)
  File "/home/suraj/.local/lib/python3.10/site-packages/django/views/generic/base.py", line 104, in view
    return self.dispatch(request, *args, **kwargs)
  File "/home/suraj/.local/lib/python3.10/site-packages/rest_framework/views.py", line 509, in dispatch
    response = self.handle_exception(exc)
  File "/home/suraj/.local/lib/python3.10/site-packages/rest_framework/views.py", line 469, in handle_exception
    self.raise_uncaught_exception(exc)
  File "/home/suraj/.local/lib/python3.10/site-packages/rest_framework/views.py", line 480, in raise_uncaught_exception
    raise exc
  File "/home/suraj/.local/lib/python3.10/site-packages/rest_framework/views.py", line 506, in dispatch
    response = handler(request, *args, **kwargs)
  File "/home/suraj/.local/lib/python3.10/site-packages/drf_spectacular/drainage.py", line 193, in wrapped_method
    return method(self, request, *args, **kwargs)
  File "/home/suraj/.local/lib/python3.10/site-packages/rest_framework/generics.py", line 190, in post
    return self.create(request, *args, **kwargs)
  File "/home/suraj/Desktop/Python/JobBackend/JobPortalBackend/notifications/api/viewsets/fcm_token.py", line 36, in create
    response = super().create(request, *args, **kwargs)
  File "/home/suraj/.local/lib/python3.10/site-packages/rest_framework/mixins.py", line 19, in create
    self.perform_create(serializer)
  File "/home/suraj/.local/lib/python3.10/site-packages/rest_framework/mixins.py", line 24, in perform_create
    serializer.save()
  File "/home/suraj/.local/lib/python3.10/site-packages/rest_framework/serializers.py", line 212, in save
    self.instance = self.create(validated_data)
  File "/home/suraj/.local/lib/python3.10/site-packages/rest_framework/serializers.py", line 962, in create
    instance = ModelClass._default_manager.create(**validated_data)
  File "/home/suraj/.local/lib/python3.10/site-packages/django/db/models/manager.py", line 87, in manager_method
    return getattr(self.get_queryset(), name)(*args, **kwargs)
  File "/home/suraj/.local/lib/python3.10/site-packages/django/db/models/query.py", line 658, in create
    obj.save(force_insert=True, using=self.db)
  File "/home/suraj/.local/lib/python3.10/site-packages/django/db/models/base.py", line 814, in save
    self.save_base(
  File "/home/suraj/.local/lib/python3.10/site-packages/django/db/models/base.py", line 877, in save_base
    updated = self._save_table(
  File "/home/suraj/.local/lib/python3.10/site-packages/django/db/models/base.py", line 1020, in _save_table
    results = self._do_insert(
  File "/home/suraj/.local/lib/python3.10/site-packages/django/db/models/base.py", line 1061, in _do_insert
    return manager._insert(
  File "/home/suraj/.local/lib/python3.10/site-packages/django/db/models/manager.py", line 87, in manager_method
    return getattr(self.get_queryset(), name)(*args, **kwargs)
  File "/home/suraj/.local/lib/python3.10/site-packages/django/db/models/query.py", line 1805, in _insert
    return query.get_compiler(using=using).execute_sql(returning_fields)
  File "/home/suraj/.local/lib/python3.10/site-packages/django/db/models/sql/compiler.py", line 1820, in execute_sql
    cursor.execute(sql, params)
  File "/home/suraj/.local/lib/python3.10/site-packages/django/db/backends/utils.py", line 102, in execute
    return super().execute(sql, params)
  File "/home/suraj/.local/lib/python3.10/site-packages/django/db/backends/utils.py", line 67, in execute
    return self._execute_with_wrappers(
  File "/home/suraj/.local/lib/python3.10/site-packages/django/db/backends/utils.py", line 80, in _execute_with_wrappers
    return executor(sql, params, many, context)
  File "/home/suraj/.local/lib/python3.10/site-packages/django/db/backends/utils.py", line 84, in _execute
    with self.db.wrap_database_errors:
  File "/home/suraj/.local/lib/python3.10/site-packages/django/db/utils.py", line 91, in __exit__
    raise dj_exc_value.with_traceback(traceback) from exc_value
  File "/home/suraj/.local/lib/python3.10/site-packages/django/db/backends/utils.py", line 89, in _execute
    return self.cursor.execute(sql, params)
  File "/home/suraj/.local/lib/python3.10/site-packages/django/db/backends/sqlite3/base.py", line 328, in execute
    return super().execute(query, params)
django.db.utils.IntegrityError: NOT NULL constraint failed: notifications_fcmtokenobject.user_id
2023-06-15 05:37:05 ERROR django.server "POST /api/v1/notifications/create HTTP/1.1" 500 24093
2023-06-15 05:37:31 WARNING django.request Bad Request: /api/v1/notifications/create
2023-06-15 05:37:31 WARNING django.server "POST /api/v1/notifications/create HTTP/1.1" 400 62
2023-06-15 05:37:52 WARNING django.request Bad Request: /api/v1/notifications/create
2023-06-15 05:37:52 WARNING django.server "POST /api/v1/notifications/create HTTP/1.1" 400 62
2023-06-15 05:42:55 WARNING django.request Bad Request: /api/v1/notifications/create
2023-06-15 05:42:55 WARNING django.server "POST /api/v1/notifications/create HTTP/1.1" 400 69
2023-06-15 05:53:48 ERROR django.request Internal Server Error: /api/v1/notifications/create
Traceback (most recent call last):
  File "/home/suraj/.local/lib/python3.10/site-packages/django/db/models/fields/__init__.py", line 2055, in get_prep_value
    return int(value)
  File "/home/suraj/.local/lib/python3.10/site-packages/django/contrib/auth/models.py", line 437, in __int__
    raise TypeError(
TypeError: Cannot cast AnonymousUser to int. Are you trying to use it in place of User?

The above exception was the direct cause of the following exception:

Traceback (most recent call last):
  File "/home/suraj/.local/lib/python3.10/site-packages/django/core/handlers/exception.py", line 55, in inner
    response = get_response(request)
  File "/home/suraj/.local/lib/python3.10/site-packages/django/core/handlers/base.py", line 197, in _get_response
    response = wrapped_callback(request, *callback_args, **callback_kwargs)
  File "/home/suraj/.local/lib/python3.10/site-packages/django/views/decorators/csrf.py", line 56, in wrapper_view
    return view_func(*args, **kwargs)
  File "/home/suraj/.local/lib/python3.10/site-packages/django/views/generic/base.py", line 104, in view
    return self.dispatch(request, *args, **kwargs)
  File "/home/suraj/.local/lib/python3.10/site-packages/rest_framework/views.py", line 509, in dispatch
    response = self.handle_exception(exc)
  File "/home/suraj/.local/lib/python3.10/site-packages/rest_framework/views.py", line 469, in handle_exception
    self.raise_uncaught_exception(exc)
  File "/home/suraj/.local/lib/python3.10/site-packages/rest_framework/views.py", line 480, in raise_uncaught_exception
    raise exc
  File "/home/suraj/.local/lib/python3.10/site-packages/rest_framework/views.py", line 506, in dispatch
    response = handler(request, *args, **kwargs)
  File "/home/suraj/.local/lib/python3.10/site-packages/drf_spectacular/drainage.py", line 193, in wrapped_method
    return method(self, request, *args, **kwargs)
  File "/home/suraj/.local/lib/python3.10/site-packages/rest_framework/generics.py", line 190, in post
    return self.create(request, *args, **kwargs)
  File "/home/suraj/Desktop/Python/JobBackend/JobPortalBackend/notifications/api/viewsets/fcm_token.py", line 36, in create
    response = super().create(request, *args, **kwargs)
  File "/home/suraj/.local/lib/python3.10/site-packages/rest_framework/mixins.py", line 19, in create
    self.perform_create(serializer)
  File "/home/suraj/.local/lib/python3.10/site-packages/rest_framework/mixins.py", line 24, in perform_create
    serializer.save()
  File "/home/suraj/.local/lib/python3.10/site-packages/rest_framework/serializers.py", line 212, in save
    self.instance = self.create(validated_data)
  File "/home/suraj/Desktop/Python/JobBackend/JobPortalBackend/notifications/api/serializers/fcm_token.py", line 44, in create
    instance = FCMTokenObject.objects.filter(user=user, type=device_type).first()
  File "/home/suraj/.local/lib/python3.10/site-packages/django/db/models/manager.py", line 87, in manager_method
    return getattr(self.get_queryset(), name)(*args, **kwargs)
  File "/home/suraj/.local/lib/python3.10/site-packages/django/db/models/query.py", line 1436, in filter
    return self._filter_or_exclude(False, args, kwargs)
  File "/home/suraj/.local/lib/python3.10/site-packages/django/db/models/query.py", line 1454, in _filter_or_exclude
    clone._filter_or_exclude_inplace(negate, args, kwargs)
  File "/home/suraj/.local/lib/python3.10/site-packages/django/db/models/query.py", line 1461, in _filter_or_exclude_inplace
    self._query.add_q(Q(*args, **kwargs))
  File "/home/suraj/.local/lib/python3.10/site-packages/django/db/models/sql/query.py", line 1498, in add_q
    clause, _ = self._add_q(q_object, self.used_aliases)
  File "/home/suraj/.local/lib/python3.10/site-packages/django/db/models/sql/query.py", line 1529, in _add_q
    child_clause, needed_inner = self.build_filter(
  File "/home/suraj/.local/lib/python3.10/site-packages/django/db/models/sql/query.py", line 1444, in build_filter
    condition = self.build_lookup(lookups, col, value)
  File "/home/suraj/.local/lib/python3.10/site-packages/django/db/models/sql/query.py", line 1271, in build_lookup
    lookup = lookup_class(lhs, rhs)
  File "/home/suraj/.local/lib/python3.10/site-packages/django/db/models/lookups.py", line 27, in __init__
    self.rhs = self.get_prep_lookup()
  File "/home/suraj/.local/lib/python3.10/site-packages/django/db/models/fields/related_lookups.py", line 166, in get_prep_lookup
    self.rhs = target_field.get_prep_value(self.rhs)
  File "/home/suraj/.local/lib/python3.10/site-packages/django/db/models/fields/__init__.py", line 2057, in get_prep_value
    raise e.__class__(
TypeError: Field 'id' expected a number but got <django.contrib.auth.models.AnonymousUser object at 0x7f47e43c0c40>.
2023-06-15 05:53:48 ERROR django.server "POST /api/v1/notifications/create HTTP/1.1" 500 23536
2023-06-15 05:53:58 ERROR django.request Internal Server Error: /api/v1/notifications/create
Traceback (most recent call last):
  File "/home/suraj/.local/lib/python3.10/site-packages/django/db/models/fields/__init__.py", line 2055, in get_prep_value
    return int(value)
  File "/home/suraj/.local/lib/python3.10/site-packages/django/contrib/auth/models.py", line 437, in __int__
    raise TypeError(
TypeError: Cannot cast AnonymousUser to int. Are you trying to use it in place of User?

The above exception was the direct cause of the following exception:

Traceback (most recent call last):
  File "/home/suraj/.local/lib/python3.10/site-packages/django/core/handlers/exception.py", line 55, in inner
    response = get_response(request)
  File "/home/suraj/.local/lib/python3.10/site-packages/django/core/handlers/base.py", line 197, in _get_response
    response = wrapped_callback(request, *callback_args, **callback_kwargs)
  File "/home/suraj/.local/lib/python3.10/site-packages/django/views/decorators/csrf.py", line 56, in wrapper_view
    return view_func(*args, **kwargs)
  File "/home/suraj/.local/lib/python3.10/site-packages/django/views/generic/base.py", line 104, in view
    return self.dispatch(request, *args, **kwargs)
  File "/home/suraj/.local/lib/python3.10/site-packages/rest_framework/views.py", line 509, in dispatch
    response = self.handle_exception(exc)
  File "/home/suraj/.local/lib/python3.10/site-packages/rest_framework/views.py", line 469, in handle_exception
    self.raise_uncaught_exception(exc)
  File "/home/suraj/.local/lib/python3.10/site-packages/rest_framework/views.py", line 480, in raise_uncaught_exception
    raise exc
  File "/home/suraj/.local/lib/python3.10/site-packages/rest_framework/views.py", line 506, in dispatch
    response = handler(request, *args, **kwargs)
  File "/home/suraj/.local/lib/python3.10/site-packages/drf_spectacular/drainage.py", line 193, in wrapped_method
    return method(self, request, *args, **kwargs)
  File "/home/suraj/.local/lib/python3.10/site-packages/rest_framework/generics.py", line 190, in post
    return self.create(request, *args, **kwargs)
  File "/home/suraj/Desktop/Python/JobBackend/JobPortalBackend/notifications/api/viewsets/fcm_token.py", line 36, in create
    response = super().create(request, *args, **kwargs)
  File "/home/suraj/.local/lib/python3.10/site-packages/rest_framework/mixins.py", line 19, in create
    self.perform_create(serializer)
  File "/home/suraj/.local/lib/python3.10/site-packages/rest_framework/mixins.py", line 24, in perform_create
    serializer.save()
  File "/home/suraj/.local/lib/python3.10/site-packages/rest_framework/serializers.py", line 212, in save
    self.instance = self.create(validated_data)
  File "/home/suraj/Desktop/Python/JobBackend/JobPortalBackend/notifications/api/serializers/fcm_token.py", line 44, in create
    instance = FCMTokenObject.objects.filter(user=user, type=device_type).first()
  File "/home/suraj/.local/lib/python3.10/site-packages/django/db/models/manager.py", line 87, in manager_method
    return getattr(self.get_queryset(), name)(*args, **kwargs)
  File "/home/suraj/.local/lib/python3.10/site-packages/django/db/models/query.py", line 1436, in filter
    return self._filter_or_exclude(False, args, kwargs)
  File "/home/suraj/.local/lib/python3.10/site-packages/django/db/models/query.py", line 1454, in _filter_or_exclude
    clone._filter_or_exclude_inplace(negate, args, kwargs)
  File "/home/suraj/.local/lib/python3.10/site-packages/django/db/models/query.py", line 1461, in _filter_or_exclude_inplace
    self._query.add_q(Q(*args, **kwargs))
  File "/home/suraj/.local/lib/python3.10/site-packages/django/db/models/sql/query.py", line 1498, in add_q
    clause, _ = self._add_q(q_object, self.used_aliases)
  File "/home/suraj/.local/lib/python3.10/site-packages/django/db/models/sql/query.py", line 1529, in _add_q
    child_clause, needed_inner = self.build_filter(
  File "/home/suraj/.local/lib/python3.10/site-packages/django/db/models/sql/query.py", line 1444, in build_filter
    condition = self.build_lookup(lookups, col, value)
  File "/home/suraj/.local/lib/python3.10/site-packages/django/db/models/sql/query.py", line 1271, in build_lookup
    lookup = lookup_class(lhs, rhs)
  File "/home/suraj/.local/lib/python3.10/site-packages/django/db/models/lookups.py", line 27, in __init__
    self.rhs = self.get_prep_lookup()
  File "/home/suraj/.local/lib/python3.10/site-packages/django/db/models/fields/related_lookups.py", line 166, in get_prep_lookup
    self.rhs = target_field.get_prep_value(self.rhs)
  File "/home/suraj/.local/lib/python3.10/site-packages/django/db/models/fields/__init__.py", line 2057, in get_prep_value
    raise e.__class__(
TypeError: Field 'id' expected a number but got <django.contrib.auth.models.AnonymousUser object at 0x7f47e436e9e0>.
2023-06-15 05:53:58 ERROR django.server "POST /api/v1/notifications/create HTTP/1.1" 500 23536
2023-06-15 05:54:07 ERROR django.request Internal Server Error: /api/v1/notifications/create
Traceback (most recent call last):
  File "/home/suraj/.local/lib/python3.10/site-packages/django/db/models/fields/__init__.py", line 2055, in get_prep_value
    return int(value)
  File "/home/suraj/.local/lib/python3.10/site-packages/django/contrib/auth/models.py", line 437, in __int__
    raise TypeError(
TypeError: Cannot cast AnonymousUser to int. Are you trying to use it in place of User?

The above exception was the direct cause of the following exception:

Traceback (most recent call last):
  File "/home/suraj/.local/lib/python3.10/site-packages/django/core/handlers/exception.py", line 55, in inner
    response = get_response(request)
  File "/home/suraj/.local/lib/python3.10/site-packages/django/core/handlers/base.py", line 197, in _get_response
    response = wrapped_callback(request, *callback_args, **callback_kwargs)
  File "/home/suraj/.local/lib/python3.10/site-packages/django/views/decorators/csrf.py", line 56, in wrapper_view
    return view_func(*args, **kwargs)
  File "/home/suraj/.local/lib/python3.10/site-packages/django/views/generic/base.py", line 104, in view
    return self.dispatch(request, *args, **kwargs)
  File "/home/suraj/.local/lib/python3.10/site-packages/rest_framework/views.py", line 509, in dispatch
    response = self.handle_exception(exc)
  File "/home/suraj/.local/lib/python3.10/site-packages/rest_framework/views.py", line 469, in handle_exception
    self.raise_uncaught_exception(exc)
  File "/home/suraj/.local/lib/python3.10/site-packages/rest_framework/views.py", line 480, in raise_uncaught_exception
    raise exc
  File "/home/suraj/.local/lib/python3.10/site-packages/rest_framework/views.py", line 506, in dispatch
    response = handler(request, *args, **kwargs)
  File "/home/suraj/.local/lib/python3.10/site-packages/drf_spectacular/drainage.py", line 193, in wrapped_method
    return method(self, request, *args, **kwargs)
  File "/home/suraj/.local/lib/python3.10/site-packages/rest_framework/generics.py", line 190, in post
    return self.create(request, *args, **kwargs)
  File "/home/suraj/Desktop/Python/JobBackend/JobPortalBackend/notifications/api/viewsets/fcm_token.py", line 36, in create
    response = super().create(request, *args, **kwargs)
  File "/home/suraj/.local/lib/python3.10/site-packages/rest_framework/mixins.py", line 19, in create
    self.perform_create(serializer)
  File "/home/suraj/.local/lib/python3.10/site-packages/rest_framework/mixins.py", line 24, in perform_create
    serializer.save()
  File "/home/suraj/.local/lib/python3.10/site-packages/rest_framework/serializers.py", line 212, in save
    self.instance = self.create(validated_data)
  File "/home/suraj/Desktop/Python/JobBackend/JobPortalBackend/notifications/api/serializers/fcm_token.py", line 44, in create
    instance = FCMTokenObject.objects.filter(user=user, type=device_type).first()
  File "/home/suraj/.local/lib/python3.10/site-packages/django/db/models/manager.py", line 87, in manager_method
    return getattr(self.get_queryset(), name)(*args, **kwargs)
  File "/home/suraj/.local/lib/python3.10/site-packages/django/db/models/query.py", line 1436, in filter
    return self._filter_or_exclude(False, args, kwargs)
  File "/home/suraj/.local/lib/python3.10/site-packages/django/db/models/query.py", line 1454, in _filter_or_exclude
    clone._filter_or_exclude_inplace(negate, args, kwargs)
  File "/home/suraj/.local/lib/python3.10/site-packages/django/db/models/query.py", line 1461, in _filter_or_exclude_inplace
    self._query.add_q(Q(*args, **kwargs))
  File "/home/suraj/.local/lib/python3.10/site-packages/django/db/models/sql/query.py", line 1498, in add_q
    clause, _ = self._add_q(q_object, self.used_aliases)
  File "/home/suraj/.local/lib/python3.10/site-packages/django/db/models/sql/query.py", line 1529, in _add_q
    child_clause, needed_inner = self.build_filter(
  File "/home/suraj/.local/lib/python3.10/site-packages/django/db/models/sql/query.py", line 1444, in build_filter
    condition = self.build_lookup(lookups, col, value)
  File "/home/suraj/.local/lib/python3.10/site-packages/django/db/models/sql/query.py", line 1271, in build_lookup
    lookup = lookup_class(lhs, rhs)
  File "/home/suraj/.local/lib/python3.10/site-packages/django/db/models/lookups.py", line 27, in __init__
    self.rhs = self.get_prep_lookup()
  File "/home/suraj/.local/lib/python3.10/site-packages/django/db/models/fields/related_lookups.py", line 166, in get_prep_lookup
    self.rhs = target_field.get_prep_value(self.rhs)
  File "/home/suraj/.local/lib/python3.10/site-packages/django/db/models/fields/__init__.py", line 2057, in get_prep_value
    raise e.__class__(
TypeError: Field 'id' expected a number but got <django.contrib.auth.models.AnonymousUser object at 0x7f47e4399c30>.
2023-06-15 05:54:07 ERROR django.server "POST /api/v1/notifications/create HTTP/1.1" 500 23536
2023-06-15 05:54:23 WARNING django.request Unauthorized: /api/v1/notifications/create
2023-06-15 05:54:23 WARNING django.server "POST /api/v1/notifications/create HTTP/1.1" 401 183
2023-06-15 05:55:23 WARNING django.request Unauthorized: /api/v1/accounts/student-login/
2023-06-15 05:55:23 WARNING django.server "POST /api/v1/accounts/student-login/ HTTP/1.1" 401 183
2023-06-15 05:55:35 WARNING django.request Unprocessable Entity: /api/v1/accounts/student-login/
2023-06-15 05:55:35 WARNING django.server "POST /api/v1/accounts/student-login/ HTTP/1.1" 422 66
2023-06-15 06:44:49 WARNING django.request Unauthorized: /api/v1/doc/
2023-06-15 06:44:49 WARNING django.server "GET /api/v1/doc/ HTTP/1.1" 401 16
2023-06-15 06:45:25 WARNING django.request Unauthorized: /api/v1/notifications/mark-all-notifications-as-read/
2023-06-15 06:45:25 WARNING django.server "POST /api/v1/notifications/mark-all-notifications-as-read/ HTTP/1.1" 401 57
2023-06-15 06:52:00 WARNING django.request Bad Request: /api/v1/notifications/mark_notification_as_read/xxxz/
2023-06-15 06:52:00 WARNING django.server "POST /api/v1/notifications/mark_notification_as_read/xxxz/ HTTP/1.1" 400 51
2023-06-15 09:36:59 ERROR django.request Internal Server Error: /api/v1/doc/schema/
Traceback (most recent call last):
  File "/home/suraj/.local/lib/python3.10/site-packages/django/core/handlers/exception.py", line 55, in inner
    response = get_response(request)
  File "/home/suraj/.local/lib/python3.10/site-packages/django/core/handlers/base.py", line 197, in _get_response
    response = wrapped_callback(request, *callback_args, **callback_kwargs)
  File "/home/suraj/.local/lib/python3.10/site-packages/django/views/decorators/csrf.py", line 56, in wrapper_view
    return view_func(*args, **kwargs)
  File "/home/suraj/.local/lib/python3.10/site-packages/django/views/generic/base.py", line 104, in view
    return self.dispatch(request, *args, **kwargs)
  File "/home/suraj/.local/lib/python3.10/site-packages/rest_framework/views.py", line 509, in dispatch
    response = self.handle_exception(exc)
  File "/home/suraj/.local/lib/python3.10/site-packages/rest_framework/views.py", line 469, in handle_exception
    self.raise_uncaught_exception(exc)
  File "/home/suraj/.local/lib/python3.10/site-packages/rest_framework/views.py", line 480, in raise_uncaught_exception
    raise exc
  File "/home/suraj/.local/lib/python3.10/site-packages/rest_framework/views.py", line 506, in dispatch
    response = handler(request, *args, **kwargs)
  File "/home/suraj/.local/lib/python3.10/site-packages/drf_spectacular/views.py", line 83, in get
    return self._get_schema_response(request)
  File "/home/suraj/.local/lib/python3.10/site-packages/drf_spectacular/views.py", line 91, in _get_schema_response
    data=generator.get_schema(request=request, public=self.serve_public),
  File "/home/suraj/.local/lib/python3.10/site-packages/drf_spectacular/generators.py", line 268, in get_schema
    paths=self.parse(request, public),
  File "/home/suraj/.local/lib/python3.10/site-packages/drf_spectacular/generators.py", line 239, in parse
    operation = view.schema.get_operation(
  File "/home/suraj/.local/lib/python3.10/site-packages/drf_spectacular/openapi.py", line 95, in get_operation
    operation['responses'] = self._get_response_bodies()
  File "/home/suraj/.local/lib/python3.10/site-packages/drf_spectacular/openapi.py", line 1348, in _get_response_bodies
    return {'200': self._get_response_for_code(response_serializers, '200', direction=direction)}
  File "/home/suraj/.local/lib/python3.10/site-packages/drf_spectacular/openapi.py", line 1404, in _get_response_for_code
    component = self.resolve_serializer(serializer, direction)
  File "/home/suraj/.local/lib/python3.10/site-packages/drf_spectacular/openapi.py", line 1575, in resolve_serializer
    component.schema = self._map_serializer(serializer, direction, bypass_extensions)
  File "/home/suraj/.local/lib/python3.10/site-packages/drf_spectacular/openapi.py", line 907, in _map_serializer
    schema = self._map_basic_serializer(serializer, direction)
  File "/home/suraj/.local/lib/python3.10/site-packages/drf_spectacular/openapi.py", line 999, in _map_basic_serializer
    for field in serializer.fields.values():
  File "/home/suraj/.local/lib/python3.10/site-packages/django/utils/functional.py", line 57, in __get__
    res = instance.__dict__[self.name] = self.func(instance)
  File "/home/suraj/.local/lib/python3.10/site-packages/rest_framework/serializers.py", line 356, in fields
    for key, value in self.get_fields().items():
  File "/home/suraj/.local/lib/python3.10/site-packages/rest_framework/serializers.py", line 1032, in get_fields
    assert hasattr(self.Meta, 'model'), (
AssertionError: Class CommentSerializer missing "Meta.model" attribute
2023-06-15 09:36:59 ERROR django.server "GET /api/v1/doc/schema/ HTTP/1.1" 500 166814
2023-06-15 09:36:59 ERROR django.request Internal Server Error: /api/v1/doc/schema/
Traceback (most recent call last):
  File "/home/suraj/.local/lib/python3.10/site-packages/django/core/handlers/exception.py", line 55, in inner
    response = get_response(request)
  File "/home/suraj/.local/lib/python3.10/site-packages/django/core/handlers/base.py", line 197, in _get_response
    response = wrapped_callback(request, *callback_args, **callback_kwargs)
  File "/home/suraj/.local/lib/python3.10/site-packages/django/views/decorators/csrf.py", line 56, in wrapper_view
    return view_func(*args, **kwargs)
  File "/home/suraj/.local/lib/python3.10/site-packages/django/views/generic/base.py", line 104, in view
    return self.dispatch(request, *args, **kwargs)
  File "/home/suraj/.local/lib/python3.10/site-packages/rest_framework/views.py", line 509, in dispatch
    response = self.handle_exception(exc)
  File "/home/suraj/.local/lib/python3.10/site-packages/rest_framework/views.py", line 469, in handle_exception
    self.raise_uncaught_exception(exc)
  File "/home/suraj/.local/lib/python3.10/site-packages/rest_framework/views.py", line 480, in raise_uncaught_exception
    raise exc
  File "/home/suraj/.local/lib/python3.10/site-packages/rest_framework/views.py", line 506, in dispatch
    response = handler(request, *args, **kwargs)
  File "/home/suraj/.local/lib/python3.10/site-packages/drf_spectacular/views.py", line 83, in get
    return self._get_schema_response(request)
  File "/home/suraj/.local/lib/python3.10/site-packages/drf_spectacular/views.py", line 91, in _get_schema_response
    data=generator.get_schema(request=request, public=self.serve_public),
  File "/home/suraj/.local/lib/python3.10/site-packages/drf_spectacular/generators.py", line 268, in get_schema
    paths=self.parse(request, public),
  File "/home/suraj/.local/lib/python3.10/site-packages/drf_spectacular/generators.py", line 239, in parse
    operation = view.schema.get_operation(
  File "/home/suraj/.local/lib/python3.10/site-packages/drf_spectacular/openapi.py", line 95, in get_operation
    operation['responses'] = self._get_response_bodies()
  File "/home/suraj/.local/lib/python3.10/site-packages/drf_spectacular/openapi.py", line 1348, in _get_response_bodies
    return {'200': self._get_response_for_code(response_serializers, '200', direction=direction)}
  File "/home/suraj/.local/lib/python3.10/site-packages/drf_spectacular/openapi.py", line 1404, in _get_response_for_code
    component = self.resolve_serializer(serializer, direction)
  File "/home/suraj/.local/lib/python3.10/site-packages/drf_spectacular/openapi.py", line 1575, in resolve_serializer
    component.schema = self._map_serializer(serializer, direction, bypass_extensions)
  File "/home/suraj/.local/lib/python3.10/site-packages/drf_spectacular/openapi.py", line 907, in _map_serializer
    schema = self._map_basic_serializer(serializer, direction)
  File "/home/suraj/.local/lib/python3.10/site-packages/drf_spectacular/openapi.py", line 999, in _map_basic_serializer
    for field in serializer.fields.values():
  File "/home/suraj/.local/lib/python3.10/site-packages/django/utils/functional.py", line 57, in __get__
    res = instance.__dict__[self.name] = self.func(instance)
  File "/home/suraj/.local/lib/python3.10/site-packages/rest_framework/serializers.py", line 356, in fields
    for key, value in self.get_fields().items():
  File "/home/suraj/.local/lib/python3.10/site-packages/rest_framework/serializers.py", line 1032, in get_fields
    assert hasattr(self.Meta, 'model'), (
AssertionError: Class CommentSerializer missing "Meta.model" attribute
2023-06-15 09:36:59 ERROR django.server "GET /api/v1/doc/schema/ HTTP/1.1" 500 166814
2023-06-15 09:37:02 ERROR django.request Internal Server Error: /api/v1/doc/schema/
Traceback (most recent call last):
  File "/home/suraj/.local/lib/python3.10/site-packages/django/core/handlers/exception.py", line 55, in inner
    response = get_response(request)
  File "/home/suraj/.local/lib/python3.10/site-packages/django/core/handlers/base.py", line 197, in _get_response
    response = wrapped_callback(request, *callback_args, **callback_kwargs)
  File "/home/suraj/.local/lib/python3.10/site-packages/django/views/decorators/csrf.py", line 56, in wrapper_view
    return view_func(*args, **kwargs)
  File "/home/suraj/.local/lib/python3.10/site-packages/django/views/generic/base.py", line 104, in view
    return self.dispatch(request, *args, **kwargs)
  File "/home/suraj/.local/lib/python3.10/site-packages/rest_framework/views.py", line 509, in dispatch
    response = self.handle_exception(exc)
  File "/home/suraj/.local/lib/python3.10/site-packages/rest_framework/views.py", line 469, in handle_exception
    self.raise_uncaught_exception(exc)
  File "/home/suraj/.local/lib/python3.10/site-packages/rest_framework/views.py", line 480, in raise_uncaught_exception
    raise exc
  File "/home/suraj/.local/lib/python3.10/site-packages/rest_framework/views.py", line 506, in dispatch
    response = handler(request, *args, **kwargs)
  File "/home/suraj/.local/lib/python3.10/site-packages/drf_spectacular/views.py", line 83, in get
    return self._get_schema_response(request)
  File "/home/suraj/.local/lib/python3.10/site-packages/drf_spectacular/views.py", line 91, in _get_schema_response
    data=generator.get_schema(request=request, public=self.serve_public),
  File "/home/suraj/.local/lib/python3.10/site-packages/drf_spectacular/generators.py", line 268, in get_schema
    paths=self.parse(request, public),
  File "/home/suraj/.local/lib/python3.10/site-packages/drf_spectacular/generators.py", line 239, in parse
    operation = view.schema.get_operation(
  File "/home/suraj/.local/lib/python3.10/site-packages/drf_spectacular/openapi.py", line 95, in get_operation
    operation['responses'] = self._get_response_bodies()
  File "/home/suraj/.local/lib/python3.10/site-packages/drf_spectacular/openapi.py", line 1348, in _get_response_bodies
    return {'200': self._get_response_for_code(response_serializers, '200', direction=direction)}
  File "/home/suraj/.local/lib/python3.10/site-packages/drf_spectacular/openapi.py", line 1404, in _get_response_for_code
    component = self.resolve_serializer(serializer, direction)
  File "/home/suraj/.local/lib/python3.10/site-packages/drf_spectacular/openapi.py", line 1575, in resolve_serializer
    component.schema = self._map_serializer(serializer, direction, bypass_extensions)
  File "/home/suraj/.local/lib/python3.10/site-packages/drf_spectacular/openapi.py", line 907, in _map_serializer
    schema = self._map_basic_serializer(serializer, direction)
  File "/home/suraj/.local/lib/python3.10/site-packages/drf_spectacular/openapi.py", line 999, in _map_basic_serializer
    for field in serializer.fields.values():
  File "/home/suraj/.local/lib/python3.10/site-packages/django/utils/functional.py", line 57, in __get__
    res = instance.__dict__[self.name] = self.func(instance)
  File "/home/suraj/.local/lib/python3.10/site-packages/rest_framework/serializers.py", line 356, in fields
    for key, value in self.get_fields().items():
  File "/home/suraj/.local/lib/python3.10/site-packages/rest_framework/serializers.py", line 1032, in get_fields
    assert hasattr(self.Meta, 'model'), (
AssertionError: Class CommentSerializer missing "Meta.model" attribute
2023-06-15 09:37:02 ERROR django.server "GET /api/v1/doc/schema/ HTTP/1.1" 500 166814
2023-06-15 09:37:02 ERROR django.request Internal Server Error: /api/v1/doc/schema/
Traceback (most recent call last):
  File "/home/suraj/.local/lib/python3.10/site-packages/django/core/handlers/exception.py", line 55, in inner
    response = get_response(request)
  File "/home/suraj/.local/lib/python3.10/site-packages/django/core/handlers/base.py", line 197, in _get_response
    response = wrapped_callback(request, *callback_args, **callback_kwargs)
  File "/home/suraj/.local/lib/python3.10/site-packages/django/views/decorators/csrf.py", line 56, in wrapper_view
    return view_func(*args, **kwargs)
  File "/home/suraj/.local/lib/python3.10/site-packages/django/views/generic/base.py", line 104, in view
    return self.dispatch(request, *args, **kwargs)
  File "/home/suraj/.local/lib/python3.10/site-packages/rest_framework/views.py", line 509, in dispatch
    response = self.handle_exception(exc)
  File "/home/suraj/.local/lib/python3.10/site-packages/rest_framework/views.py", line 469, in handle_exception
    self.raise_uncaught_exception(exc)
  File "/home/suraj/.local/lib/python3.10/site-packages/rest_framework/views.py", line 480, in raise_uncaught_exception
    raise exc
  File "/home/suraj/.local/lib/python3.10/site-packages/rest_framework/views.py", line 506, in dispatch
    response = handler(request, *args, **kwargs)
  File "/home/suraj/.local/lib/python3.10/site-packages/drf_spectacular/views.py", line 83, in get
    return self._get_schema_response(request)
  File "/home/suraj/.local/lib/python3.10/site-packages/drf_spectacular/views.py", line 91, in _get_schema_response
    data=generator.get_schema(request=request, public=self.serve_public),
  File "/home/suraj/.local/lib/python3.10/site-packages/drf_spectacular/generators.py", line 268, in get_schema
    paths=self.parse(request, public),
  File "/home/suraj/.local/lib/python3.10/site-packages/drf_spectacular/generators.py", line 239, in parse
    operation = view.schema.get_operation(
  File "/home/suraj/.local/lib/python3.10/site-packages/drf_spectacular/openapi.py", line 95, in get_operation
    operation['responses'] = self._get_response_bodies()
  File "/home/suraj/.local/lib/python3.10/site-packages/drf_spectacular/openapi.py", line 1348, in _get_response_bodies
    return {'200': self._get_response_for_code(response_serializers, '200', direction=direction)}
  File "/home/suraj/.local/lib/python3.10/site-packages/drf_spectacular/openapi.py", line 1404, in _get_response_for_code
    component = self.resolve_serializer(serializer, direction)
  File "/home/suraj/.local/lib/python3.10/site-packages/drf_spectacular/openapi.py", line 1575, in resolve_serializer
    component.schema = self._map_serializer(serializer, direction, bypass_extensions)
  File "/home/suraj/.local/lib/python3.10/site-packages/drf_spectacular/openapi.py", line 907, in _map_serializer
    schema = self._map_basic_serializer(serializer, direction)
  File "/home/suraj/.local/lib/python3.10/site-packages/drf_spectacular/openapi.py", line 999, in _map_basic_serializer
    for field in serializer.fields.values():
  File "/home/suraj/.local/lib/python3.10/site-packages/django/utils/functional.py", line 57, in __get__
    res = instance.__dict__[self.name] = self.func(instance)
  File "/home/suraj/.local/lib/python3.10/site-packages/rest_framework/serializers.py", line 356, in fields
    for key, value in self.get_fields().items():
  File "/home/suraj/.local/lib/python3.10/site-packages/rest_framework/serializers.py", line 1032, in get_fields
    assert hasattr(self.Meta, 'model'), (
AssertionError: Class CommentSerializer missing "Meta.model" attribute
2023-06-15 09:37:02 ERROR django.server "GET /api/v1/doc/schema/ HTTP/1.1" 500 166814
2023-06-15 09:37:21 ERROR django.request Internal Server Error: /api/v1/doc/schema/
Traceback (most recent call last):
  File "/home/suraj/.local/lib/python3.10/site-packages/django/core/handlers/exception.py", line 55, in inner
    response = get_response(request)
  File "/home/suraj/.local/lib/python3.10/site-packages/django/core/handlers/base.py", line 197, in _get_response
    response = wrapped_callback(request, *callback_args, **callback_kwargs)
  File "/home/suraj/.local/lib/python3.10/site-packages/django/views/decorators/csrf.py", line 56, in wrapper_view
    return view_func(*args, **kwargs)
  File "/home/suraj/.local/lib/python3.10/site-packages/django/views/generic/base.py", line 104, in view
    return self.dispatch(request, *args, **kwargs)
  File "/home/suraj/.local/lib/python3.10/site-packages/rest_framework/views.py", line 509, in dispatch
    response = self.handle_exception(exc)
  File "/home/suraj/.local/lib/python3.10/site-packages/rest_framework/views.py", line 469, in handle_exception
    self.raise_uncaught_exception(exc)
  File "/home/suraj/.local/lib/python3.10/site-packages/rest_framework/views.py", line 480, in raise_uncaught_exception
    raise exc
  File "/home/suraj/.local/lib/python3.10/site-packages/rest_framework/views.py", line 506, in dispatch
    response = handler(request, *args, **kwargs)
  File "/home/suraj/.local/lib/python3.10/site-packages/drf_spectacular/views.py", line 83, in get
    return self._get_schema_response(request)
  File "/home/suraj/.local/lib/python3.10/site-packages/drf_spectacular/views.py", line 91, in _get_schema_response
    data=generator.get_schema(request=request, public=self.serve_public),
  File "/home/suraj/.local/lib/python3.10/site-packages/drf_spectacular/generators.py", line 268, in get_schema
    paths=self.parse(request, public),
  File "/home/suraj/.local/lib/python3.10/site-packages/drf_spectacular/generators.py", line 239, in parse
    operation = view.schema.get_operation(
  File "/home/suraj/.local/lib/python3.10/site-packages/drf_spectacular/openapi.py", line 95, in get_operation
    operation['responses'] = self._get_response_bodies()
  File "/home/suraj/.local/lib/python3.10/site-packages/drf_spectacular/openapi.py", line 1348, in _get_response_bodies
    return {'200': self._get_response_for_code(response_serializers, '200', direction=direction)}
  File "/home/suraj/.local/lib/python3.10/site-packages/drf_spectacular/openapi.py", line 1404, in _get_response_for_code
    component = self.resolve_serializer(serializer, direction)
  File "/home/suraj/.local/lib/python3.10/site-packages/drf_spectacular/openapi.py", line 1575, in resolve_serializer
    component.schema = self._map_serializer(serializer, direction, bypass_extensions)
  File "/home/suraj/.local/lib/python3.10/site-packages/drf_spectacular/openapi.py", line 907, in _map_serializer
    schema = self._map_basic_serializer(serializer, direction)
  File "/home/suraj/.local/lib/python3.10/site-packages/drf_spectacular/openapi.py", line 999, in _map_basic_serializer
    for field in serializer.fields.values():
  File "/home/suraj/.local/lib/python3.10/site-packages/django/utils/functional.py", line 57, in __get__
    res = instance.__dict__[self.name] = self.func(instance)
  File "/home/suraj/.local/lib/python3.10/site-packages/rest_framework/serializers.py", line 356, in fields
    for key, value in self.get_fields().items():
  File "/home/suraj/.local/lib/python3.10/site-packages/rest_framework/serializers.py", line 1032, in get_fields
    assert hasattr(self.Meta, 'model'), (
AssertionError: Class CommentSerializer missing "Meta.model" attribute
2023-06-15 09:37:21 ERROR django.server "GET /api/v1/doc/schema/ HTTP/1.1" 500 166814
2023-06-15 09:37:22 ERROR django.request Internal Server Error: /api/v1/doc/schema/
Traceback (most recent call last):
  File "/home/suraj/.local/lib/python3.10/site-packages/django/core/handlers/exception.py", line 55, in inner
    response = get_response(request)
  File "/home/suraj/.local/lib/python3.10/site-packages/django/core/handlers/base.py", line 197, in _get_response
    response = wrapped_callback(request, *callback_args, **callback_kwargs)
  File "/home/suraj/.local/lib/python3.10/site-packages/django/views/decorators/csrf.py", line 56, in wrapper_view
    return view_func(*args, **kwargs)
  File "/home/suraj/.local/lib/python3.10/site-packages/django/views/generic/base.py", line 104, in view
    return self.dispatch(request, *args, **kwargs)
  File "/home/suraj/.local/lib/python3.10/site-packages/rest_framework/views.py", line 509, in dispatch
    response = self.handle_exception(exc)
  File "/home/suraj/.local/lib/python3.10/site-packages/rest_framework/views.py", line 469, in handle_exception
    self.raise_uncaught_exception(exc)
  File "/home/suraj/.local/lib/python3.10/site-packages/rest_framework/views.py", line 480, in raise_uncaught_exception
    raise exc
  File "/home/suraj/.local/lib/python3.10/site-packages/rest_framework/views.py", line 506, in dispatch
    response = handler(request, *args, **kwargs)
  File "/home/suraj/.local/lib/python3.10/site-packages/drf_spectacular/views.py", line 83, in get
    return self._get_schema_response(request)
  File "/home/suraj/.local/lib/python3.10/site-packages/drf_spectacular/views.py", line 91, in _get_schema_response
    data=generator.get_schema(request=request, public=self.serve_public),
  File "/home/suraj/.local/lib/python3.10/site-packages/drf_spectacular/generators.py", line 268, in get_schema
    paths=self.parse(request, public),
  File "/home/suraj/.local/lib/python3.10/site-packages/drf_spectacular/generators.py", line 239, in parse
    operation = view.schema.get_operation(
  File "/home/suraj/.local/lib/python3.10/site-packages/drf_spectacular/openapi.py", line 95, in get_operation
    operation['responses'] = self._get_response_bodies()
  File "/home/suraj/.local/lib/python3.10/site-packages/drf_spectacular/openapi.py", line 1348, in _get_response_bodies
    return {'200': self._get_response_for_code(response_serializers, '200', direction=direction)}
  File "/home/suraj/.local/lib/python3.10/site-packages/drf_spectacular/openapi.py", line 1404, in _get_response_for_code
    component = self.resolve_serializer(serializer, direction)
  File "/home/suraj/.local/lib/python3.10/site-packages/drf_spectacular/openapi.py", line 1575, in resolve_serializer
    component.schema = self._map_serializer(serializer, direction, bypass_extensions)
  File "/home/suraj/.local/lib/python3.10/site-packages/drf_spectacular/openapi.py", line 907, in _map_serializer
    schema = self._map_basic_serializer(serializer, direction)
  File "/home/suraj/.local/lib/python3.10/site-packages/drf_spectacular/openapi.py", line 999, in _map_basic_serializer
    for field in serializer.fields.values():
  File "/home/suraj/.local/lib/python3.10/site-packages/django/utils/functional.py", line 57, in __get__
    res = instance.__dict__[self.name] = self.func(instance)
  File "/home/suraj/.local/lib/python3.10/site-packages/rest_framework/serializers.py", line 356, in fields
    for key, value in self.get_fields().items():
  File "/home/suraj/.local/lib/python3.10/site-packages/rest_framework/serializers.py", line 1032, in get_fields
    assert hasattr(self.Meta, 'model'), (
AssertionError: Class CommentSerializer missing "Meta.model" attribute
2023-06-15 09:37:22 ERROR django.server "GET /api/v1/doc/schema/ HTTP/1.1" 500 166814
2023-06-15 09:38:44 ERROR django.request Internal Server Error: /api/v1/doc/schema/
Traceback (most recent call last):
  File "/home/suraj/.local/lib/python3.10/site-packages/django/core/handlers/exception.py", line 55, in inner
    response = get_response(request)
  File "/home/suraj/.local/lib/python3.10/site-packages/django/core/handlers/base.py", line 197, in _get_response
    response = wrapped_callback(request, *callback_args, **callback_kwargs)
  File "/home/suraj/.local/lib/python3.10/site-packages/django/views/decorators/csrf.py", line 56, in wrapper_view
    return view_func(*args, **kwargs)
  File "/home/suraj/.local/lib/python3.10/site-packages/django/views/generic/base.py", line 104, in view
    return self.dispatch(request, *args, **kwargs)
  File "/home/suraj/.local/lib/python3.10/site-packages/rest_framework/views.py", line 509, in dispatch
    response = self.handle_exception(exc)
  File "/home/suraj/.local/lib/python3.10/site-packages/rest_framework/views.py", line 469, in handle_exception
    self.raise_uncaught_exception(exc)
  File "/home/suraj/.local/lib/python3.10/site-packages/rest_framework/views.py", line 480, in raise_uncaught_exception
    raise exc
  File "/home/suraj/.local/lib/python3.10/site-packages/rest_framework/views.py", line 506, in dispatch
    response = handler(request, *args, **kwargs)
  File "/home/suraj/.local/lib/python3.10/site-packages/drf_spectacular/views.py", line 83, in get
    return self._get_schema_response(request)
  File "/home/suraj/.local/lib/python3.10/site-packages/drf_spectacular/views.py", line 91, in _get_schema_response
    data=generator.get_schema(request=request, public=self.serve_public),
  File "/home/suraj/.local/lib/python3.10/site-packages/drf_spectacular/generators.py", line 268, in get_schema
    paths=self.parse(request, public),
  File "/home/suraj/.local/lib/python3.10/site-packages/drf_spectacular/generators.py", line 239, in parse
    operation = view.schema.get_operation(
  File "/home/suraj/.local/lib/python3.10/site-packages/drf_spectacular/openapi.py", line 95, in get_operation
    operation['responses'] = self._get_response_bodies()
  File "/home/suraj/.local/lib/python3.10/site-packages/drf_spectacular/openapi.py", line 1348, in _get_response_bodies
    return {'200': self._get_response_for_code(response_serializers, '200', direction=direction)}
  File "/home/suraj/.local/lib/python3.10/site-packages/drf_spectacular/openapi.py", line 1404, in _get_response_for_code
    component = self.resolve_serializer(serializer, direction)
  File "/home/suraj/.local/lib/python3.10/site-packages/drf_spectacular/openapi.py", line 1575, in resolve_serializer
    component.schema = self._map_serializer(serializer, direction, bypass_extensions)
  File "/home/suraj/.local/lib/python3.10/site-packages/drf_spectacular/openapi.py", line 907, in _map_serializer
    schema = self._map_basic_serializer(serializer, direction)
  File "/home/suraj/.local/lib/python3.10/site-packages/drf_spectacular/openapi.py", line 999, in _map_basic_serializer
    for field in serializer.fields.values():
  File "/home/suraj/.local/lib/python3.10/site-packages/django/utils/functional.py", line 57, in __get__
    res = instance.__dict__[self.name] = self.func(instance)
  File "/home/suraj/.local/lib/python3.10/site-packages/rest_framework/serializers.py", line 356, in fields
    for key, value in self.get_fields().items():
  File "/home/suraj/.local/lib/python3.10/site-packages/rest_framework/serializers.py", line 1032, in get_fields
    assert hasattr(self.Meta, 'model'), (
AssertionError: Class CommentSerializer missing "Meta.model" attribute
2023-06-15 09:38:44 ERROR django.server "GET /api/v1/doc/schema/ HTTP/1.1" 500 166817
2023-06-15 09:38:45 ERROR django.request Internal Server Error: /api/v1/doc/schema/
Traceback (most recent call last):
  File "/home/suraj/.local/lib/python3.10/site-packages/django/core/handlers/exception.py", line 55, in inner
    response = get_response(request)
  File "/home/suraj/.local/lib/python3.10/site-packages/django/core/handlers/base.py", line 197, in _get_response
    response = wrapped_callback(request, *callback_args, **callback_kwargs)
  File "/home/suraj/.local/lib/python3.10/site-packages/django/views/decorators/csrf.py", line 56, in wrapper_view
    return view_func(*args, **kwargs)
  File "/home/suraj/.local/lib/python3.10/site-packages/django/views/generic/base.py", line 104, in view
    return self.dispatch(request, *args, **kwargs)
  File "/home/suraj/.local/lib/python3.10/site-packages/rest_framework/views.py", line 509, in dispatch
    response = self.handle_exception(exc)
  File "/home/suraj/.local/lib/python3.10/site-packages/rest_framework/views.py", line 469, in handle_exception
    self.raise_uncaught_exception(exc)
  File "/home/suraj/.local/lib/python3.10/site-packages/rest_framework/views.py", line 480, in raise_uncaught_exception
    raise exc
  File "/home/suraj/.local/lib/python3.10/site-packages/rest_framework/views.py", line 506, in dispatch
    response = handler(request, *args, **kwargs)
  File "/home/suraj/.local/lib/python3.10/site-packages/drf_spectacular/views.py", line 83, in get
    return self._get_schema_response(request)
  File "/home/suraj/.local/lib/python3.10/site-packages/drf_spectacular/views.py", line 91, in _get_schema_response
    data=generator.get_schema(request=request, public=self.serve_public),
  File "/home/suraj/.local/lib/python3.10/site-packages/drf_spectacular/generators.py", line 268, in get_schema
    paths=self.parse(request, public),
  File "/home/suraj/.local/lib/python3.10/site-packages/drf_spectacular/generators.py", line 239, in parse
    operation = view.schema.get_operation(
  File "/home/suraj/.local/lib/python3.10/site-packages/drf_spectacular/openapi.py", line 95, in get_operation
    operation['responses'] = self._get_response_bodies()
  File "/home/suraj/.local/lib/python3.10/site-packages/drf_spectacular/openapi.py", line 1348, in _get_response_bodies
    return {'200': self._get_response_for_code(response_serializers, '200', direction=direction)}
  File "/home/suraj/.local/lib/python3.10/site-packages/drf_spectacular/openapi.py", line 1404, in _get_response_for_code
    component = self.resolve_serializer(serializer, direction)
  File "/home/suraj/.local/lib/python3.10/site-packages/drf_spectacular/openapi.py", line 1575, in resolve_serializer
    component.schema = self._map_serializer(serializer, direction, bypass_extensions)
  File "/home/suraj/.local/lib/python3.10/site-packages/drf_spectacular/openapi.py", line 907, in _map_serializer
    schema = self._map_basic_serializer(serializer, direction)
  File "/home/suraj/.local/lib/python3.10/site-packages/drf_spectacular/openapi.py", line 999, in _map_basic_serializer
    for field in serializer.fields.values():
  File "/home/suraj/.local/lib/python3.10/site-packages/django/utils/functional.py", line 57, in __get__
    res = instance.__dict__[self.name] = self.func(instance)
  File "/home/suraj/.local/lib/python3.10/site-packages/rest_framework/serializers.py", line 356, in fields
    for key, value in self.get_fields().items():
  File "/home/suraj/.local/lib/python3.10/site-packages/rest_framework/serializers.py", line 1032, in get_fields
    assert hasattr(self.Meta, 'model'), (
AssertionError: Class CommentSerializer missing "Meta.model" attribute
2023-06-15 09:38:45 ERROR django.server "GET /api/v1/doc/schema/ HTTP/1.1" 500 166817
2023-06-15 09:40:56 ERROR django.request Internal Server Error: /api/v1/doc/schema/
Traceback (most recent call last):
  File "/home/suraj/.local/lib/python3.10/site-packages/django/core/handlers/exception.py", line 55, in inner
    response = get_response(request)
  File "/home/suraj/.local/lib/python3.10/site-packages/django/core/handlers/base.py", line 197, in _get_response
    response = wrapped_callback(request, *callback_args, **callback_kwargs)
  File "/home/suraj/.local/lib/python3.10/site-packages/django/views/decorators/csrf.py", line 56, in wrapper_view
    return view_func(*args, **kwargs)
  File "/home/suraj/.local/lib/python3.10/site-packages/django/views/generic/base.py", line 104, in view
    return self.dispatch(request, *args, **kwargs)
  File "/home/suraj/.local/lib/python3.10/site-packages/rest_framework/views.py", line 509, in dispatch
    response = self.handle_exception(exc)
  File "/home/suraj/.local/lib/python3.10/site-packages/rest_framework/views.py", line 469, in handle_exception
    self.raise_uncaught_exception(exc)
  File "/home/suraj/.local/lib/python3.10/site-packages/rest_framework/views.py", line 480, in raise_uncaught_exception
    raise exc
  File "/home/suraj/.local/lib/python3.10/site-packages/rest_framework/views.py", line 506, in dispatch
    response = handler(request, *args, **kwargs)
  File "/home/suraj/.local/lib/python3.10/site-packages/drf_spectacular/views.py", line 83, in get
    return self._get_schema_response(request)
  File "/home/suraj/.local/lib/python3.10/site-packages/drf_spectacular/views.py", line 91, in _get_schema_response
    data=generator.get_schema(request=request, public=self.serve_public),
  File "/home/suraj/.local/lib/python3.10/site-packages/drf_spectacular/generators.py", line 268, in get_schema
    paths=self.parse(request, public),
  File "/home/suraj/.local/lib/python3.10/site-packages/drf_spectacular/generators.py", line 239, in parse
    operation = view.schema.get_operation(
  File "/home/suraj/.local/lib/python3.10/site-packages/drf_spectacular/openapi.py", line 95, in get_operation
    operation['responses'] = self._get_response_bodies()
  File "/home/suraj/.local/lib/python3.10/site-packages/drf_spectacular/openapi.py", line 1348, in _get_response_bodies
    return {'200': self._get_response_for_code(response_serializers, '200', direction=direction)}
  File "/home/suraj/.local/lib/python3.10/site-packages/drf_spectacular/openapi.py", line 1404, in _get_response_for_code
    component = self.resolve_serializer(serializer, direction)
  File "/home/suraj/.local/lib/python3.10/site-packages/drf_spectacular/openapi.py", line 1575, in resolve_serializer
    component.schema = self._map_serializer(serializer, direction, bypass_extensions)
  File "/home/suraj/.local/lib/python3.10/site-packages/drf_spectacular/openapi.py", line 907, in _map_serializer
    schema = self._map_basic_serializer(serializer, direction)
  File "/home/suraj/.local/lib/python3.10/site-packages/drf_spectacular/openapi.py", line 999, in _map_basic_serializer
    for field in serializer.fields.values():
  File "/home/suraj/.local/lib/python3.10/site-packages/django/utils/functional.py", line 57, in __get__
    res = instance.__dict__[self.name] = self.func(instance)
  File "/home/suraj/.local/lib/python3.10/site-packages/rest_framework/serializers.py", line 356, in fields
    for key, value in self.get_fields().items():
  File "/home/suraj/.local/lib/python3.10/site-packages/rest_framework/serializers.py", line 1032, in get_fields
    assert hasattr(self.Meta, 'model'), (
AssertionError: Class CommentSerializer missing "Meta.model" attribute
2023-06-15 09:40:56 ERROR django.server "GET /api/v1/doc/schema/ HTTP/1.1" 500 166817
2023-06-15 09:40:56 ERROR django.request Internal Server Error: /api/v1/doc/schema/
Traceback (most recent call last):
  File "/home/suraj/.local/lib/python3.10/site-packages/django/core/handlers/exception.py", line 55, in inner
    response = get_response(request)
  File "/home/suraj/.local/lib/python3.10/site-packages/django/core/handlers/base.py", line 197, in _get_response
    response = wrapped_callback(request, *callback_args, **callback_kwargs)
  File "/home/suraj/.local/lib/python3.10/site-packages/django/views/decorators/csrf.py", line 56, in wrapper_view
    return view_func(*args, **kwargs)
  File "/home/suraj/.local/lib/python3.10/site-packages/django/views/generic/base.py", line 104, in view
    return self.dispatch(request, *args, **kwargs)
  File "/home/suraj/.local/lib/python3.10/site-packages/rest_framework/views.py", line 509, in dispatch
    response = self.handle_exception(exc)
  File "/home/suraj/.local/lib/python3.10/site-packages/rest_framework/views.py", line 469, in handle_exception
    self.raise_uncaught_exception(exc)
  File "/home/suraj/.local/lib/python3.10/site-packages/rest_framework/views.py", line 480, in raise_uncaught_exception
    raise exc
  File "/home/suraj/.local/lib/python3.10/site-packages/rest_framework/views.py", line 506, in dispatch
    response = handler(request, *args, **kwargs)
  File "/home/suraj/.local/lib/python3.10/site-packages/drf_spectacular/views.py", line 83, in get
    return self._get_schema_response(request)
  File "/home/suraj/.local/lib/python3.10/site-packages/drf_spectacular/views.py", line 91, in _get_schema_response
    data=generator.get_schema(request=request, public=self.serve_public),
  File "/home/suraj/.local/lib/python3.10/site-packages/drf_spectacular/generators.py", line 268, in get_schema
    paths=self.parse(request, public),
  File "/home/suraj/.local/lib/python3.10/site-packages/drf_spectacular/generators.py", line 239, in parse
    operation = view.schema.get_operation(
  File "/home/suraj/.local/lib/python3.10/site-packages/drf_spectacular/openapi.py", line 95, in get_operation
    operation['responses'] = self._get_response_bodies()
  File "/home/suraj/.local/lib/python3.10/site-packages/drf_spectacular/openapi.py", line 1348, in _get_response_bodies
    return {'200': self._get_response_for_code(response_serializers, '200', direction=direction)}
  File "/home/suraj/.local/lib/python3.10/site-packages/drf_spectacular/openapi.py", line 1404, in _get_response_for_code
    component = self.resolve_serializer(serializer, direction)
  File "/home/suraj/.local/lib/python3.10/site-packages/drf_spectacular/openapi.py", line 1575, in resolve_serializer
    component.schema = self._map_serializer(serializer, direction, bypass_extensions)
  File "/home/suraj/.local/lib/python3.10/site-packages/drf_spectacular/openapi.py", line 907, in _map_serializer
    schema = self._map_basic_serializer(serializer, direction)
  File "/home/suraj/.local/lib/python3.10/site-packages/drf_spectacular/openapi.py", line 999, in _map_basic_serializer
    for field in serializer.fields.values():
  File "/home/suraj/.local/lib/python3.10/site-packages/django/utils/functional.py", line 57, in __get__
    res = instance.__dict__[self.name] = self.func(instance)
  File "/home/suraj/.local/lib/python3.10/site-packages/rest_framework/serializers.py", line 356, in fields
    for key, value in self.get_fields().items():
  File "/home/suraj/.local/lib/python3.10/site-packages/rest_framework/serializers.py", line 1032, in get_fields
    assert hasattr(self.Meta, 'model'), (
AssertionError: Class CommentSerializer missing "Meta.model" attribute
2023-06-15 09:40:56 ERROR django.server "GET /api/v1/doc/schema/ HTTP/1.1" 500 166817
2023-06-15 09:41:07 ERROR django.request Internal Server Error: /api/v1/doc/schema/
Traceback (most recent call last):
  File "/home/suraj/.local/lib/python3.10/site-packages/django/core/handlers/exception.py", line 55, in inner
    response = get_response(request)
  File "/home/suraj/.local/lib/python3.10/site-packages/django/core/handlers/base.py", line 197, in _get_response
    response = wrapped_callback(request, *callback_args, **callback_kwargs)
  File "/home/suraj/.local/lib/python3.10/site-packages/django/views/decorators/csrf.py", line 56, in wrapper_view
    return view_func(*args, **kwargs)
  File "/home/suraj/.local/lib/python3.10/site-packages/django/views/generic/base.py", line 104, in view
    return self.dispatch(request, *args, **kwargs)
  File "/home/suraj/.local/lib/python3.10/site-packages/rest_framework/views.py", line 509, in dispatch
    response = self.handle_exception(exc)
  File "/home/suraj/.local/lib/python3.10/site-packages/rest_framework/views.py", line 469, in handle_exception
    self.raise_uncaught_exception(exc)
  File "/home/suraj/.local/lib/python3.10/site-packages/rest_framework/views.py", line 480, in raise_uncaught_exception
    raise exc
  File "/home/suraj/.local/lib/python3.10/site-packages/rest_framework/views.py", line 506, in dispatch
    response = handler(request, *args, **kwargs)
  File "/home/suraj/.local/lib/python3.10/site-packages/drf_spectacular/views.py", line 83, in get
    return self._get_schema_response(request)
  File "/home/suraj/.local/lib/python3.10/site-packages/drf_spectacular/views.py", line 91, in _get_schema_response
    data=generator.get_schema(request=request, public=self.serve_public),
  File "/home/suraj/.local/lib/python3.10/site-packages/drf_spectacular/generators.py", line 268, in get_schema
    paths=self.parse(request, public),
  File "/home/suraj/.local/lib/python3.10/site-packages/drf_spectacular/generators.py", line 239, in parse
    operation = view.schema.get_operation(
  File "/home/suraj/.local/lib/python3.10/site-packages/drf_spectacular/openapi.py", line 95, in get_operation
    operation['responses'] = self._get_response_bodies()
  File "/home/suraj/.local/lib/python3.10/site-packages/drf_spectacular/openapi.py", line 1348, in _get_response_bodies
    return {'200': self._get_response_for_code(response_serializers, '200', direction=direction)}
  File "/home/suraj/.local/lib/python3.10/site-packages/drf_spectacular/openapi.py", line 1404, in _get_response_for_code
    component = self.resolve_serializer(serializer, direction)
  File "/home/suraj/.local/lib/python3.10/site-packages/drf_spectacular/openapi.py", line 1575, in resolve_serializer
    component.schema = self._map_serializer(serializer, direction, bypass_extensions)
  File "/home/suraj/.local/lib/python3.10/site-packages/drf_spectacular/openapi.py", line 907, in _map_serializer
    schema = self._map_basic_serializer(serializer, direction)
  File "/home/suraj/.local/lib/python3.10/site-packages/drf_spectacular/openapi.py", line 999, in _map_basic_serializer
    for field in serializer.fields.values():
  File "/home/suraj/.local/lib/python3.10/site-packages/django/utils/functional.py", line 57, in __get__
    res = instance.__dict__[self.name] = self.func(instance)
  File "/home/suraj/.local/lib/python3.10/site-packages/rest_framework/serializers.py", line 356, in fields
    for key, value in self.get_fields().items():
  File "/home/suraj/.local/lib/python3.10/site-packages/rest_framework/serializers.py", line 1076, in get_fields
    field_class, field_kwargs = self.build_field(
  File "/home/suraj/.local/lib/python3.10/site-packages/rest_framework/serializers.py", line 1222, in build_field
    return self.build_unknown_field(field_name, model_class)
  File "/home/suraj/.local/lib/python3.10/site-packages/rest_framework/serializers.py", line 1340, in build_unknown_field
    raise ImproperlyConfigured(
django.core.exceptions.ImproperlyConfigured: Field name `product` is not valid for model `Comments`.
2023-06-15 09:41:07 ERROR django.server "GET /api/v1/doc/schema/ HTTP/1.1" 500 184170
2023-06-15 09:41:07 ERROR django.request Internal Server Error: /api/v1/doc/schema/
Traceback (most recent call last):
  File "/home/suraj/.local/lib/python3.10/site-packages/django/core/handlers/exception.py", line 55, in inner
    response = get_response(request)
  File "/home/suraj/.local/lib/python3.10/site-packages/django/core/handlers/base.py", line 197, in _get_response
    response = wrapped_callback(request, *callback_args, **callback_kwargs)
  File "/home/suraj/.local/lib/python3.10/site-packages/django/views/decorators/csrf.py", line 56, in wrapper_view
    return view_func(*args, **kwargs)
  File "/home/suraj/.local/lib/python3.10/site-packages/django/views/generic/base.py", line 104, in view
    return self.dispatch(request, *args, **kwargs)
  File "/home/suraj/.local/lib/python3.10/site-packages/rest_framework/views.py", line 509, in dispatch
    response = self.handle_exception(exc)
  File "/home/suraj/.local/lib/python3.10/site-packages/rest_framework/views.py", line 469, in handle_exception
    self.raise_uncaught_exception(exc)
  File "/home/suraj/.local/lib/python3.10/site-packages/rest_framework/views.py", line 480, in raise_uncaught_exception
    raise exc
  File "/home/suraj/.local/lib/python3.10/site-packages/rest_framework/views.py", line 506, in dispatch
    response = handler(request, *args, **kwargs)
  File "/home/suraj/.local/lib/python3.10/site-packages/drf_spectacular/views.py", line 83, in get
    return self._get_schema_response(request)
  File "/home/suraj/.local/lib/python3.10/site-packages/drf_spectacular/views.py", line 91, in _get_schema_response
    data=generator.get_schema(request=request, public=self.serve_public),
  File "/home/suraj/.local/lib/python3.10/site-packages/drf_spectacular/generators.py", line 268, in get_schema
    paths=self.parse(request, public),
  File "/home/suraj/.local/lib/python3.10/site-packages/drf_spectacular/generators.py", line 239, in parse
    operation = view.schema.get_operation(
  File "/home/suraj/.local/lib/python3.10/site-packages/drf_spectacular/openapi.py", line 95, in get_operation
    operation['responses'] = self._get_response_bodies()
  File "/home/suraj/.local/lib/python3.10/site-packages/drf_spectacular/openapi.py", line 1348, in _get_response_bodies
    return {'200': self._get_response_for_code(response_serializers, '200', direction=direction)}
  File "/home/suraj/.local/lib/python3.10/site-packages/drf_spectacular/openapi.py", line 1404, in _get_response_for_code
    component = self.resolve_serializer(serializer, direction)
  File "/home/suraj/.local/lib/python3.10/site-packages/drf_spectacular/openapi.py", line 1575, in resolve_serializer
    component.schema = self._map_serializer(serializer, direction, bypass_extensions)
  File "/home/suraj/.local/lib/python3.10/site-packages/drf_spectacular/openapi.py", line 907, in _map_serializer
    schema = self._map_basic_serializer(serializer, direction)
  File "/home/suraj/.local/lib/python3.10/site-packages/drf_spectacular/openapi.py", line 999, in _map_basic_serializer
    for field in serializer.fields.values():
  File "/home/suraj/.local/lib/python3.10/site-packages/django/utils/functional.py", line 57, in __get__
    res = instance.__dict__[self.name] = self.func(instance)
  File "/home/suraj/.local/lib/python3.10/site-packages/rest_framework/serializers.py", line 356, in fields
    for key, value in self.get_fields().items():
  File "/home/suraj/.local/lib/python3.10/site-packages/rest_framework/serializers.py", line 1076, in get_fields
    field_class, field_kwargs = self.build_field(
  File "/home/suraj/.local/lib/python3.10/site-packages/rest_framework/serializers.py", line 1222, in build_field
    return self.build_unknown_field(field_name, model_class)
  File "/home/suraj/.local/lib/python3.10/site-packages/rest_framework/serializers.py", line 1340, in build_unknown_field
    raise ImproperlyConfigured(
django.core.exceptions.ImproperlyConfigured: Field name `product` is not valid for model `Comments`.
2023-06-15 09:41:07 ERROR django.server "GET /api/v1/doc/schema/ HTTP/1.1" 500 184170
2023-06-15 09:49:23 ERROR django.request Internal Server Error: /api/v1/comments/job-comment/
Traceback (most recent call last):
  File "/home/suraj/.local/lib/python3.10/site-packages/django/core/handlers/exception.py", line 55, in inner
    response = get_response(request)
  File "/home/suraj/.local/lib/python3.10/site-packages/django/core/handlers/base.py", line 197, in _get_response
    response = wrapped_callback(request, *callback_args, **callback_kwargs)
  File "/home/suraj/.local/lib/python3.10/site-packages/django/views/decorators/csrf.py", line 56, in wrapper_view
    return view_func(*args, **kwargs)
  File "/home/suraj/.local/lib/python3.10/site-packages/rest_framework/viewsets.py", line 125, in view
    return self.dispatch(request, *args, **kwargs)
  File "/home/suraj/.local/lib/python3.10/site-packages/rest_framework/views.py", line 509, in dispatch
    response = self.handle_exception(exc)
  File "/home/suraj/.local/lib/python3.10/site-packages/rest_framework/views.py", line 469, in handle_exception
    self.raise_uncaught_exception(exc)
  File "/home/suraj/.local/lib/python3.10/site-packages/rest_framework/views.py", line 480, in raise_uncaught_exception
    raise exc
  File "/home/suraj/.local/lib/python3.10/site-packages/rest_framework/views.py", line 506, in dispatch
    response = handler(request, *args, **kwargs)
  File "/home/suraj/Desktop/Python/JobBackend/JobPortalBackend/common/permissions.py", line 71, in decorated_func
    self.check_permissions(self.request)
  File "/home/suraj/.local/lib/python3.10/site-packages/rest_framework/views.py", line 331, in check_permissions
    for permission in self.get_permissions():
  File "/home/suraj/.local/lib/python3.10/site-packages/rest_framework/views.py", line 278, in get_permissions
    return [permission() for permission in self.permission_classes]
TypeError: 'BasePermissionMetaclass' object is not iterable
2023-06-15 09:49:23 ERROR django.server "GET /api/v1/comments/job-comment/ HTTP/1.1" 500 20127
2023-06-15 09:50:45 ERROR django.request Internal Server Error: /api/v1/comments/job-comment/
Traceback (most recent call last):
  File "/home/suraj/.local/lib/python3.10/site-packages/django/core/handlers/exception.py", line 55, in inner
    response = get_response(request)
  File "/home/suraj/.local/lib/python3.10/site-packages/django/core/handlers/base.py", line 197, in _get_response
    response = wrapped_callback(request, *callback_args, **callback_kwargs)
  File "/home/suraj/.local/lib/python3.10/site-packages/django/views/decorators/csrf.py", line 56, in wrapper_view
    return view_func(*args, **kwargs)
  File "/home/suraj/.local/lib/python3.10/site-packages/rest_framework/viewsets.py", line 125, in view
    return self.dispatch(request, *args, **kwargs)
  File "/home/suraj/.local/lib/python3.10/site-packages/rest_framework/views.py", line 509, in dispatch
    response = self.handle_exception(exc)
  File "/home/suraj/.local/lib/python3.10/site-packages/rest_framework/views.py", line 469, in handle_exception
    self.raise_uncaught_exception(exc)
  File "/home/suraj/.local/lib/python3.10/site-packages/rest_framework/views.py", line 480, in raise_uncaught_exception
    raise exc
  File "/home/suraj/.local/lib/python3.10/site-packages/rest_framework/views.py", line 506, in dispatch
    response = handler(request, *args, **kwargs)
  File "/home/suraj/Desktop/Python/JobBackend/JobPortalBackend/common/permissions.py", line 71, in decorated_func
    self.check_permissions(self.request)
  File "/home/suraj/.local/lib/python3.10/site-packages/rest_framework/views.py", line 331, in check_permissions
    for permission in self.get_permissions():
  File "/home/suraj/.local/lib/python3.10/site-packages/rest_framework/views.py", line 278, in get_permissions
    return [permission() for permission in self.permission_classes]
TypeError: 'BasePermissionMetaclass' object is not iterable
2023-06-15 09:50:45 ERROR django.server "GET /api/v1/comments/job-comment/ HTTP/1.1" 500 20127
2023-06-15 09:51:13 ERROR django.request Internal Server Error: /api/v1/comments/job-comment/
Traceback (most recent call last):
  File "/home/suraj/.local/lib/python3.10/site-packages/django/core/handlers/exception.py", line 55, in inner
    response = get_response(request)
  File "/home/suraj/.local/lib/python3.10/site-packages/django/core/handlers/base.py", line 197, in _get_response
    response = wrapped_callback(request, *callback_args, **callback_kwargs)
  File "/home/suraj/.local/lib/python3.10/site-packages/django/views/decorators/csrf.py", line 56, in wrapper_view
    return view_func(*args, **kwargs)
  File "/home/suraj/.local/lib/python3.10/site-packages/rest_framework/viewsets.py", line 125, in view
    return self.dispatch(request, *args, **kwargs)
  File "/home/suraj/.local/lib/python3.10/site-packages/rest_framework/views.py", line 509, in dispatch
    response = self.handle_exception(exc)
  File "/home/suraj/.local/lib/python3.10/site-packages/rest_framework/views.py", line 469, in handle_exception
    self.raise_uncaught_exception(exc)
  File "/home/suraj/.local/lib/python3.10/site-packages/rest_framework/views.py", line 480, in raise_uncaught_exception
    raise exc
  File "/home/suraj/.local/lib/python3.10/site-packages/rest_framework/views.py", line 506, in dispatch
    response = handler(request, *args, **kwargs)
  File "/home/suraj/Desktop/Python/JobBackend/JobPortalBackend/common/permissions.py", line 71, in decorated_func
    self.check_permissions(self.request)
  File "/home/suraj/.local/lib/python3.10/site-packages/rest_framework/views.py", line 331, in check_permissions
    for permission in self.get_permissions():
  File "/home/suraj/.local/lib/python3.10/site-packages/rest_framework/views.py", line 278, in get_permissions
    return [permission() for permission in self.permission_classes]
TypeError: 'BasePermissionMetaclass' object is not iterable
2023-06-15 09:51:13 ERROR django.server "GET /api/v1/comments/job-comment/ HTTP/1.1" 500 20398
2023-06-15 09:51:17 ERROR django.request Internal Server Error: /api/v1/comments/job-comment/
Traceback (most recent call last):
  File "/home/suraj/.local/lib/python3.10/site-packages/django/core/handlers/exception.py", line 55, in inner
    response = get_response(request)
  File "/home/suraj/.local/lib/python3.10/site-packages/django/core/handlers/base.py", line 197, in _get_response
    response = wrapped_callback(request, *callback_args, **callback_kwargs)
  File "/home/suraj/.local/lib/python3.10/site-packages/django/views/decorators/csrf.py", line 56, in wrapper_view
    return view_func(*args, **kwargs)
  File "/home/suraj/.local/lib/python3.10/site-packages/rest_framework/viewsets.py", line 125, in view
    return self.dispatch(request, *args, **kwargs)
  File "/home/suraj/.local/lib/python3.10/site-packages/rest_framework/views.py", line 509, in dispatch
    response = self.handle_exception(exc)
  File "/home/suraj/.local/lib/python3.10/site-packages/rest_framework/views.py", line 469, in handle_exception
    self.raise_uncaught_exception(exc)
  File "/home/suraj/.local/lib/python3.10/site-packages/rest_framework/views.py", line 480, in raise_uncaught_exception
    raise exc
  File "/home/suraj/.local/lib/python3.10/site-packages/rest_framework/views.py", line 506, in dispatch
    response = handler(request, *args, **kwargs)
  File "/home/suraj/Desktop/Python/JobBackend/JobPortalBackend/common/permissions.py", line 71, in decorated_func
    self.check_permissions(self.request)
  File "/home/suraj/.local/lib/python3.10/site-packages/rest_framework/views.py", line 331, in check_permissions
    for permission in self.get_permissions():
  File "/home/suraj/.local/lib/python3.10/site-packages/rest_framework/views.py", line 278, in get_permissions
    return [permission() for permission in self.permission_classes]
TypeError: 'BasePermissionMetaclass' object is not iterable
2023-06-15 09:51:17 ERROR django.server "GET /api/v1/comments/job-comment/ HTTP/1.1" 500 20398
2023-06-15 09:51:27 ERROR django.request Internal Server Error: /api/v1/comments/job-comment/
Traceback (most recent call last):
  File "/home/suraj/.local/lib/python3.10/site-packages/django/core/handlers/exception.py", line 55, in inner
    response = get_response(request)
  File "/home/suraj/.local/lib/python3.10/site-packages/django/core/handlers/base.py", line 197, in _get_response
    response = wrapped_callback(request, *callback_args, **callback_kwargs)
  File "/home/suraj/.local/lib/python3.10/site-packages/django/views/decorators/csrf.py", line 56, in wrapper_view
    return view_func(*args, **kwargs)
  File "/home/suraj/.local/lib/python3.10/site-packages/rest_framework/viewsets.py", line 125, in view
    return self.dispatch(request, *args, **kwargs)
  File "/home/suraj/.local/lib/python3.10/site-packages/rest_framework/views.py", line 509, in dispatch
    response = self.handle_exception(exc)
  File "/home/suraj/.local/lib/python3.10/site-packages/rest_framework/views.py", line 469, in handle_exception
    self.raise_uncaught_exception(exc)
  File "/home/suraj/.local/lib/python3.10/site-packages/rest_framework/views.py", line 480, in raise_uncaught_exception
    raise exc
  File "/home/suraj/.local/lib/python3.10/site-packages/rest_framework/views.py", line 506, in dispatch
    response = handler(request, *args, **kwargs)
  File "/home/suraj/Desktop/Python/JobBackend/JobPortalBackend/comments/api/viewsets/comments.py", line 48, in list
    queryset = self.filter_queryset(self.get_queryset())
  File "/home/suraj/.local/lib/python3.10/site-packages/rest_framework/generics.py", line 150, in filter_queryset
    queryset = backend().filter_queryset(self.request, queryset, self)
  File "/home/suraj/.local/lib/python3.10/site-packages/django_filters/rest_framework/backends.py", line 68, in filter_queryset
    filterset = self.get_filterset(request, queryset, view)
  File "/home/suraj/.local/lib/python3.10/site-packages/django_filters/rest_framework/backends.py", line 20, in get_filterset
    filterset_class = self.get_filterset_class(view, queryset)
  File "/home/suraj/.local/lib/python3.10/site-packages/django_filters/rest_framework/backends.py", line 51, in get_filterset_class
    class AutoFilterSet(self.filterset_base):
  File "/home/suraj/.local/lib/python3.10/site-packages/django_filters/rest_framework/backends.py", line 52, in AutoFilterSet
    class Meta(MetaBase):
  File "/home/suraj/.local/lib/python3.10/site-packages/django_filters/rest_framework/backends.py", line 53, in Meta
    model = queryset.model
AttributeError: type object 'Comments' has no attribute 'model'
2023-06-15 09:51:27 ERROR django.server "GET /api/v1/comments/job-comment/ HTTP/1.1" 500 21122
2023-06-15 09:52:38 ERROR django.request Internal Server Error: /api/v1/comments/job-comment/
Traceback (most recent call last):
  File "/home/suraj/.local/lib/python3.10/site-packages/django/core/handlers/exception.py", line 55, in inner
    response = get_response(request)
  File "/home/suraj/.local/lib/python3.10/site-packages/django/core/handlers/base.py", line 197, in _get_response
    response = wrapped_callback(request, *callback_args, **callback_kwargs)
  File "/home/suraj/.local/lib/python3.10/site-packages/django/views/decorators/csrf.py", line 56, in wrapper_view
    return view_func(*args, **kwargs)
  File "/home/suraj/.local/lib/python3.10/site-packages/rest_framework/viewsets.py", line 125, in view
    return self.dispatch(request, *args, **kwargs)
  File "/home/suraj/.local/lib/python3.10/site-packages/rest_framework/views.py", line 509, in dispatch
    response = self.handle_exception(exc)
  File "/home/suraj/.local/lib/python3.10/site-packages/rest_framework/views.py", line 469, in handle_exception
    self.raise_uncaught_exception(exc)
  File "/home/suraj/.local/lib/python3.10/site-packages/rest_framework/views.py", line 480, in raise_uncaught_exception
    raise exc
  File "/home/suraj/.local/lib/python3.10/site-packages/rest_framework/views.py", line 506, in dispatch
    response = handler(request, *args, **kwargs)
  File "/home/suraj/Desktop/Python/JobBackend/JobPortalBackend/common/permissions.py", line 71, in decorated_func
    self.check_permissions(self.request)
  File "/home/suraj/.local/lib/python3.10/site-packages/rest_framework/views.py", line 331, in check_permissions
    for permission in self.get_permissions():
  File "/home/suraj/.local/lib/python3.10/site-packages/rest_framework/views.py", line 278, in get_permissions
    return [permission() for permission in self.permission_classes]
TypeError: 'BasePermissionMetaclass' object is not iterable
2023-06-15 09:52:38 ERROR django.server "GET /api/v1/comments/job-comment/ HTTP/1.1" 500 20398
2023-06-15 09:53:36 WARNING django.request Unauthorized: /api/v1/comments/job-comment/
2023-06-15 09:53:36 WARNING django.server "GET /api/v1/comments/job-comment/ HTTP/1.1" 401 57
2023-06-15 09:54:36 ERROR django.request Internal Server Error: /api/v1/comments/job-comment/
Traceback (most recent call last):
  File "/home/suraj/.local/lib/python3.10/site-packages/django/core/handlers/exception.py", line 55, in inner
    response = get_response(request)
  File "/home/suraj/.local/lib/python3.10/site-packages/django/core/handlers/base.py", line 197, in _get_response
    response = wrapped_callback(request, *callback_args, **callback_kwargs)
  File "/home/suraj/.local/lib/python3.10/site-packages/django/views/decorators/csrf.py", line 56, in wrapper_view
    return view_func(*args, **kwargs)
  File "/home/suraj/.local/lib/python3.10/site-packages/rest_framework/viewsets.py", line 125, in view
    return self.dispatch(request, *args, **kwargs)
  File "/home/suraj/.local/lib/python3.10/site-packages/rest_framework/views.py", line 509, in dispatch
    response = self.handle_exception(exc)
  File "/home/suraj/.local/lib/python3.10/site-packages/rest_framework/views.py", line 469, in handle_exception
    self.raise_uncaught_exception(exc)
  File "/home/suraj/.local/lib/python3.10/site-packages/rest_framework/views.py", line 480, in raise_uncaught_exception
    raise exc
  File "/home/suraj/.local/lib/python3.10/site-packages/rest_framework/views.py", line 506, in dispatch
    response = handler(request, *args, **kwargs)
  File "/home/suraj/Desktop/Python/JobBackend/JobPortalBackend/common/permissions.py", line 71, in decorated_func
    self.check_permissions(self.request)
  File "/home/suraj/.local/lib/python3.10/site-packages/rest_framework/views.py", line 331, in check_permissions
    for permission in self.get_permissions():
  File "/home/suraj/.local/lib/python3.10/site-packages/rest_framework/views.py", line 278, in get_permissions
    return [permission() for permission in self.permission_classes]
TypeError: 'BasePermissionMetaclass' object is not iterable
2023-06-15 09:54:36 ERROR django.server "GET /api/v1/comments/job-comment/ HTTP/1.1" 500 20398
2023-06-15 09:54:48 ERROR django.request Internal Server Error: /api/v1/comments/job-comment/
Traceback (most recent call last):
  File "/home/suraj/.local/lib/python3.10/site-packages/django/core/handlers/exception.py", line 55, in inner
    response = get_response(request)
  File "/home/suraj/.local/lib/python3.10/site-packages/django/core/handlers/base.py", line 197, in _get_response
    response = wrapped_callback(request, *callback_args, **callback_kwargs)
  File "/home/suraj/.local/lib/python3.10/site-packages/django/views/decorators/csrf.py", line 56, in wrapper_view
    return view_func(*args, **kwargs)
  File "/home/suraj/.local/lib/python3.10/site-packages/rest_framework/viewsets.py", line 125, in view
    return self.dispatch(request, *args, **kwargs)
  File "/home/suraj/.local/lib/python3.10/site-packages/rest_framework/views.py", line 509, in dispatch
    response = self.handle_exception(exc)
  File "/home/suraj/.local/lib/python3.10/site-packages/rest_framework/views.py", line 469, in handle_exception
    self.raise_uncaught_exception(exc)
  File "/home/suraj/.local/lib/python3.10/site-packages/rest_framework/views.py", line 480, in raise_uncaught_exception
    raise exc
  File "/home/suraj/.local/lib/python3.10/site-packages/rest_framework/views.py", line 506, in dispatch
    response = handler(request, *args, **kwargs)
  File "/home/suraj/Desktop/Python/JobBackend/JobPortalBackend/common/permissions.py", line 71, in decorated_func
    self.check_permissions(self.request)
  File "/home/suraj/.local/lib/python3.10/site-packages/rest_framework/views.py", line 331, in check_permissions
    for permission in self.get_permissions():
  File "/home/suraj/.local/lib/python3.10/site-packages/rest_framework/views.py", line 278, in get_permissions
    return [permission() for permission in self.permission_classes]
TypeError: 'BasePermissionMetaclass' object is not iterable
2023-06-15 09:54:48 ERROR django.server "GET /api/v1/comments/job-comment/ HTTP/1.1" 500 20398
2023-06-15 10:00:35 WARNING django.request Unauthorized: /api/v1/comments/job-comment/
2023-06-15 10:00:35 WARNING django.server "GET /api/v1/comments/job-comment/ HTTP/1.1" 401 57
2023-06-15 10:00:49 WARNING django.request Not Found: /favicon.ico
2023-06-15 10:00:49 WARNING django.server "GET /favicon.ico HTTP/1.1" 404 2476
2023-06-15 10:02:28 ERROR django.request Internal Server Error: /api/v1/comments/job-comment/
Traceback (most recent call last):
  File "/home/suraj/.local/lib/python3.10/site-packages/django/core/handlers/exception.py", line 55, in inner
    response = get_response(request)
  File "/home/suraj/.local/lib/python3.10/site-packages/django/core/handlers/base.py", line 220, in _get_response
    response = response.render()
  File "/home/suraj/.local/lib/python3.10/site-packages/django/template/response.py", line 111, in render
    self.content = self.rendered_content
  File "/home/suraj/.local/lib/python3.10/site-packages/rest_framework/response.py", line 70, in rendered_content
    ret = renderer.render(self.data, accepted_media_type, context)
  File "/home/suraj/.local/lib/python3.10/site-packages/rest_framework/renderers.py", line 99, in render
    ret = json.dumps(
  File "/home/suraj/.local/lib/python3.10/site-packages/rest_framework/utils/json.py", line 25, in dumps
    return json.dumps(*args, **kwargs)
  File "/usr/lib/python3.10/json/__init__.py", line 238, in dumps
    **kw).encode(obj)
  File "/usr/lib/python3.10/json/encoder.py", line 199, in encode
    chunks = self.iterencode(o, _one_shot=True)
  File "/usr/lib/python3.10/json/encoder.py", line 257, in iterencode
    return _iterencode(o, 0)
  File "/home/suraj/.local/lib/python3.10/site-packages/rest_framework/utils/encoders.py", line 67, in default
    return super().default(obj)
  File "/usr/lib/python3.10/json/encoder.py", line 179, in default
    raise TypeError(f'Object of type {o.__class__.__name__} '
TypeError: Object of type type is not JSON serializable
2023-06-15 10:02:28 ERROR django.server "GET /api/v1/comments/job-comment/ HTTP/1.1" 500 20135
2023-06-15 10:03:02 ERROR django.request Internal Server Error: /api/v1/comments/job-comment/
Traceback (most recent call last):
  File "/home/suraj/.local/lib/python3.10/site-packages/django/core/handlers/exception.py", line 55, in inner
    response = get_response(request)
  File "/home/suraj/.local/lib/python3.10/site-packages/django/core/handlers/base.py", line 220, in _get_response
    response = response.render()
  File "/home/suraj/.local/lib/python3.10/site-packages/django/template/response.py", line 111, in render
    self.content = self.rendered_content
  File "/home/suraj/.local/lib/python3.10/site-packages/rest_framework/response.py", line 70, in rendered_content
    ret = renderer.render(self.data, accepted_media_type, context)
  File "/home/suraj/.local/lib/python3.10/site-packages/rest_framework/renderers.py", line 99, in render
    ret = json.dumps(
  File "/home/suraj/.local/lib/python3.10/site-packages/rest_framework/utils/json.py", line 25, in dumps
    return json.dumps(*args, **kwargs)
  File "/usr/lib/python3.10/json/__init__.py", line 238, in dumps
    **kw).encode(obj)
  File "/usr/lib/python3.10/json/encoder.py", line 199, in encode
    chunks = self.iterencode(o, _one_shot=True)
  File "/usr/lib/python3.10/json/encoder.py", line 257, in iterencode
    return _iterencode(o, 0)
  File "/home/suraj/.local/lib/python3.10/site-packages/rest_framework/utils/encoders.py", line 67, in default
    return super().default(obj)
  File "/usr/lib/python3.10/json/encoder.py", line 179, in default
    raise TypeError(f'Object of type {o.__class__.__name__} '
TypeError: Object of type type is not JSON serializable
2023-06-15 10:03:02 ERROR django.server "GET /api/v1/comments/job-comment/ HTTP/1.1" 500 20135
2023-06-15 10:04:05 ERROR django.request Internal Server Error: /api/v1/comments/job-comment/
Traceback (most recent call last):
  File "/home/suraj/.local/lib/python3.10/site-packages/django/core/handlers/exception.py", line 55, in inner
    response = get_response(request)
  File "/home/suraj/.local/lib/python3.10/site-packages/django/core/handlers/base.py", line 220, in _get_response
    response = response.render()
  File "/home/suraj/.local/lib/python3.10/site-packages/django/template/response.py", line 111, in render
    self.content = self.rendered_content
  File "/home/suraj/.local/lib/python3.10/site-packages/rest_framework/response.py", line 70, in rendered_content
    ret = renderer.render(self.data, accepted_media_type, context)
  File "/home/suraj/.local/lib/python3.10/site-packages/rest_framework/renderers.py", line 99, in render
    ret = json.dumps(
  File "/home/suraj/.local/lib/python3.10/site-packages/rest_framework/utils/json.py", line 25, in dumps
    return json.dumps(*args, **kwargs)
  File "/usr/lib/python3.10/json/__init__.py", line 238, in dumps
    **kw).encode(obj)
  File "/usr/lib/python3.10/json/encoder.py", line 199, in encode
    chunks = self.iterencode(o, _one_shot=True)
  File "/usr/lib/python3.10/json/encoder.py", line 257, in iterencode
    return _iterencode(o, 0)
  File "/home/suraj/.local/lib/python3.10/site-packages/rest_framework/utils/encoders.py", line 67, in default
    return super().default(obj)
  File "/usr/lib/python3.10/json/encoder.py", line 179, in default
    raise TypeError(f'Object of type {o.__class__.__name__} '
TypeError: Object of type type is not JSON serializable
2023-06-15 10:04:05 ERROR django.server "GET /api/v1/comments/job-comment/ HTTP/1.1" 500 20135
2023-06-15 10:05:34 ERROR django.request Internal Server Error: /api/v1/comments/job-comment/
Traceback (most recent call last):
  File "/home/suraj/.local/lib/python3.10/site-packages/django/core/handlers/exception.py", line 55, in inner
    response = get_response(request)
  File "/home/suraj/.local/lib/python3.10/site-packages/django/core/handlers/base.py", line 220, in _get_response
    response = response.render()
  File "/home/suraj/.local/lib/python3.10/site-packages/django/template/response.py", line 111, in render
    self.content = self.rendered_content
  File "/home/suraj/.local/lib/python3.10/site-packages/rest_framework/response.py", line 70, in rendered_content
    ret = renderer.render(self.data, accepted_media_type, context)
  File "/home/suraj/.local/lib/python3.10/site-packages/rest_framework/renderers.py", line 99, in render
    ret = json.dumps(
  File "/home/suraj/.local/lib/python3.10/site-packages/rest_framework/utils/json.py", line 25, in dumps
    return json.dumps(*args, **kwargs)
  File "/usr/lib/python3.10/json/__init__.py", line 238, in dumps
    **kw).encode(obj)
  File "/usr/lib/python3.10/json/encoder.py", line 199, in encode
    chunks = self.iterencode(o, _one_shot=True)
  File "/usr/lib/python3.10/json/encoder.py", line 257, in iterencode
    return _iterencode(o, 0)
  File "/home/suraj/.local/lib/python3.10/site-packages/rest_framework/utils/encoders.py", line 67, in default
    return super().default(obj)
  File "/usr/lib/python3.10/json/encoder.py", line 179, in default
    raise TypeError(f'Object of type {o.__class__.__name__} '
TypeError: Object of type type is not JSON serializable
2023-06-15 10:05:34 ERROR django.server "GET /api/v1/comments/job-comment/ HTTP/1.1" 500 20135
2023-06-15 10:10:00 WARNING django.request Unauthorized: /api/v1/comments/job-comment/
2023-06-15 10:10:00 WARNING django.server "GET /api/v1/comments/job-comment/ HTTP/1.1" 401 57
2023-06-15 10:10:06 ERROR django.request Internal Server Error: /api/v1/comments/job-comment/
Traceback (most recent call last):
  File "/home/suraj/.local/lib/python3.10/site-packages/django/core/handlers/exception.py", line 55, in inner
    response = get_response(request)
  File "/home/suraj/.local/lib/python3.10/site-packages/django/core/handlers/base.py", line 220, in _get_response
    response = response.render()
  File "/home/suraj/.local/lib/python3.10/site-packages/django/template/response.py", line 111, in render
    self.content = self.rendered_content
  File "/home/suraj/.local/lib/python3.10/site-packages/rest_framework/response.py", line 70, in rendered_content
    ret = renderer.render(self.data, accepted_media_type, context)
  File "/home/suraj/.local/lib/python3.10/site-packages/rest_framework/renderers.py", line 99, in render
    ret = json.dumps(
  File "/home/suraj/.local/lib/python3.10/site-packages/rest_framework/utils/json.py", line 25, in dumps
    return json.dumps(*args, **kwargs)
  File "/usr/lib/python3.10/json/__init__.py", line 238, in dumps
    **kw).encode(obj)
  File "/usr/lib/python3.10/json/encoder.py", line 199, in encode
    chunks = self.iterencode(o, _one_shot=True)
  File "/usr/lib/python3.10/json/encoder.py", line 257, in iterencode
    return _iterencode(o, 0)
  File "/home/suraj/.local/lib/python3.10/site-packages/rest_framework/utils/encoders.py", line 67, in default
    return super().default(obj)
  File "/usr/lib/python3.10/json/encoder.py", line 179, in default
    raise TypeError(f'Object of type {o.__class__.__name__} '
TypeError: Object of type type is not JSON serializable
2023-06-15 10:10:06 ERROR django.server "GET /api/v1/comments/job-comment/ HTTP/1.1" 500 20135
2023-06-15 10:10:34 ERROR django.request Internal Server Error: /api/v1/comments/job-comment/
Traceback (most recent call last):
  File "/home/suraj/.local/lib/python3.10/site-packages/django/core/handlers/exception.py", line 55, in inner
    response = get_response(request)
  File "/home/suraj/.local/lib/python3.10/site-packages/django/core/handlers/base.py", line 220, in _get_response
    response = response.render()
  File "/home/suraj/.local/lib/python3.10/site-packages/django/template/response.py", line 111, in render
    self.content = self.rendered_content
  File "/home/suraj/.local/lib/python3.10/site-packages/rest_framework/response.py", line 70, in rendered_content
    ret = renderer.render(self.data, accepted_media_type, context)
  File "/home/suraj/.local/lib/python3.10/site-packages/rest_framework/renderers.py", line 99, in render
    ret = json.dumps(
  File "/home/suraj/.local/lib/python3.10/site-packages/rest_framework/utils/json.py", line 25, in dumps
    return json.dumps(*args, **kwargs)
  File "/usr/lib/python3.10/json/__init__.py", line 238, in dumps
    **kw).encode(obj)
  File "/usr/lib/python3.10/json/encoder.py", line 199, in encode
    chunks = self.iterencode(o, _one_shot=True)
  File "/usr/lib/python3.10/json/encoder.py", line 257, in iterencode
    return _iterencode(o, 0)
  File "/home/suraj/.local/lib/python3.10/site-packages/rest_framework/utils/encoders.py", line 67, in default
    return super().default(obj)
  File "/usr/lib/python3.10/json/encoder.py", line 179, in default
    raise TypeError(f'Object of type {o.__class__.__name__} '
TypeError: Object of type type is not JSON serializable
2023-06-15 10:10:34 ERROR django.server "GET /api/v1/comments/job-comment/ HTTP/1.1" 500 20135
2023-06-15 10:11:03 ERROR django.request Internal Server Error: /api/v1/comments/job-comment/
Traceback (most recent call last):
  File "/home/suraj/.local/lib/python3.10/site-packages/django/core/handlers/exception.py", line 55, in inner
    response = get_response(request)
  File "/home/suraj/.local/lib/python3.10/site-packages/django/core/handlers/base.py", line 220, in _get_response
    response = response.render()
  File "/home/suraj/.local/lib/python3.10/site-packages/django/template/response.py", line 111, in render
    self.content = self.rendered_content
  File "/home/suraj/.local/lib/python3.10/site-packages/rest_framework/response.py", line 70, in rendered_content
    ret = renderer.render(self.data, accepted_media_type, context)
  File "/home/suraj/.local/lib/python3.10/site-packages/rest_framework/renderers.py", line 99, in render
    ret = json.dumps(
  File "/home/suraj/.local/lib/python3.10/site-packages/rest_framework/utils/json.py", line 25, in dumps
    return json.dumps(*args, **kwargs)
  File "/usr/lib/python3.10/json/__init__.py", line 238, in dumps
    **kw).encode(obj)
  File "/usr/lib/python3.10/json/encoder.py", line 199, in encode
    chunks = self.iterencode(o, _one_shot=True)
  File "/usr/lib/python3.10/json/encoder.py", line 257, in iterencode
    return _iterencode(o, 0)
  File "/home/suraj/.local/lib/python3.10/site-packages/rest_framework/utils/encoders.py", line 67, in default
    return super().default(obj)
  File "/usr/lib/python3.10/json/encoder.py", line 179, in default
    raise TypeError(f'Object of type {o.__class__.__name__} '
TypeError: Object of type type is not JSON serializable
2023-06-15 10:11:03 ERROR django.server "GET /api/v1/comments/job-comment/ HTTP/1.1" 500 20135
2023-06-15 10:11:51 ERROR django.request Internal Server Error: /api/v1/comments/job-comment/
Traceback (most recent call last):
  File "/home/suraj/.local/lib/python3.10/site-packages/django/core/handlers/exception.py", line 55, in inner
    response = get_response(request)
  File "/home/suraj/.local/lib/python3.10/site-packages/django/core/handlers/base.py", line 220, in _get_response
    response = response.render()
  File "/home/suraj/.local/lib/python3.10/site-packages/django/template/response.py", line 111, in render
    self.content = self.rendered_content
  File "/home/suraj/.local/lib/python3.10/site-packages/rest_framework/response.py", line 70, in rendered_content
    ret = renderer.render(self.data, accepted_media_type, context)
  File "/home/suraj/.local/lib/python3.10/site-packages/rest_framework/renderers.py", line 99, in render
    ret = json.dumps(
  File "/home/suraj/.local/lib/python3.10/site-packages/rest_framework/utils/json.py", line 25, in dumps
    return json.dumps(*args, **kwargs)
  File "/usr/lib/python3.10/json/__init__.py", line 238, in dumps
    **kw).encode(obj)
  File "/usr/lib/python3.10/json/encoder.py", line 199, in encode
    chunks = self.iterencode(o, _one_shot=True)
  File "/usr/lib/python3.10/json/encoder.py", line 257, in iterencode
    return _iterencode(o, 0)
  File "/home/suraj/.local/lib/python3.10/site-packages/rest_framework/utils/encoders.py", line 67, in default
    return super().default(obj)
  File "/usr/lib/python3.10/json/encoder.py", line 179, in default
    raise TypeError(f'Object of type {o.__class__.__name__} '
TypeError: Object of type type is not JSON serializable
2023-06-15 10:11:51 ERROR django.server "GET /api/v1/comments/job-comment/ HTTP/1.1" 500 20135
2023-06-15 10:14:13 ERROR django.request Internal Server Error: /api/v1/comments/job-comment/
Traceback (most recent call last):
  File "/home/suraj/.local/lib/python3.10/site-packages/django/core/handlers/exception.py", line 55, in inner
    response = get_response(request)
  File "/home/suraj/.local/lib/python3.10/site-packages/django/core/handlers/base.py", line 220, in _get_response
    response = response.render()
  File "/home/suraj/.local/lib/python3.10/site-packages/django/template/response.py", line 111, in render
    self.content = self.rendered_content
  File "/home/suraj/.local/lib/python3.10/site-packages/rest_framework/response.py", line 70, in rendered_content
    ret = renderer.render(self.data, accepted_media_type, context)
  File "/home/suraj/.local/lib/python3.10/site-packages/rest_framework/renderers.py", line 99, in render
    ret = json.dumps(
  File "/home/suraj/.local/lib/python3.10/site-packages/rest_framework/utils/json.py", line 25, in dumps
    return json.dumps(*args, **kwargs)
  File "/usr/lib/python3.10/json/__init__.py", line 238, in dumps
    **kw).encode(obj)
  File "/usr/lib/python3.10/json/encoder.py", line 199, in encode
    chunks = self.iterencode(o, _one_shot=True)
  File "/usr/lib/python3.10/json/encoder.py", line 257, in iterencode
    return _iterencode(o, 0)
  File "/home/suraj/.local/lib/python3.10/site-packages/rest_framework/utils/encoders.py", line 67, in default
    return super().default(obj)
  File "/usr/lib/python3.10/json/encoder.py", line 179, in default
    raise TypeError(f'Object of type {o.__class__.__name__} '
TypeError: Object of type type is not JSON serializable
2023-06-15 10:14:13 ERROR django.server "GET /api/v1/comments/job-comment/ HTTP/1.1" 500 20135
2023-06-15 10:16:35 ERROR django.request Internal Server Error: /api/v1/comments/job-comment/
Traceback (most recent call last):
  File "/home/suraj/.local/lib/python3.10/site-packages/django/core/handlers/exception.py", line 55, in inner
    response = get_response(request)
  File "/home/suraj/.local/lib/python3.10/site-packages/django/core/handlers/base.py", line 220, in _get_response
    response = response.render()
  File "/home/suraj/.local/lib/python3.10/site-packages/django/template/response.py", line 111, in render
    self.content = self.rendered_content
  File "/home/suraj/.local/lib/python3.10/site-packages/rest_framework/response.py", line 70, in rendered_content
    ret = renderer.render(self.data, accepted_media_type, context)
  File "/home/suraj/.local/lib/python3.10/site-packages/rest_framework/renderers.py", line 99, in render
    ret = json.dumps(
  File "/home/suraj/.local/lib/python3.10/site-packages/rest_framework/utils/json.py", line 25, in dumps
    return json.dumps(*args, **kwargs)
  File "/usr/lib/python3.10/json/__init__.py", line 238, in dumps
    **kw).encode(obj)
  File "/usr/lib/python3.10/json/encoder.py", line 199, in encode
    chunks = self.iterencode(o, _one_shot=True)
  File "/usr/lib/python3.10/json/encoder.py", line 257, in iterencode
    return _iterencode(o, 0)
  File "/home/suraj/.local/lib/python3.10/site-packages/rest_framework/utils/encoders.py", line 67, in default
    return super().default(obj)
  File "/usr/lib/python3.10/json/encoder.py", line 179, in default
    raise TypeError(f'Object of type {o.__class__.__name__} '
TypeError: Object of type type is not JSON serializable
2023-06-15 10:16:35 ERROR django.server "GET /api/v1/comments/job-comment/ HTTP/1.1" 500 20499
2023-06-15 10:16:48 ERROR django.request Internal Server Error: /api/v1/comments/job-comment/
Traceback (most recent call last):
  File "/home/suraj/.local/lib/python3.10/site-packages/django/core/handlers/exception.py", line 55, in inner
    response = get_response(request)
  File "/home/suraj/.local/lib/python3.10/site-packages/django/core/handlers/base.py", line 220, in _get_response
    response = response.render()
  File "/home/suraj/.local/lib/python3.10/site-packages/django/template/response.py", line 111, in render
    self.content = self.rendered_content
  File "/home/suraj/.local/lib/python3.10/site-packages/rest_framework/response.py", line 70, in rendered_content
    ret = renderer.render(self.data, accepted_media_type, context)
  File "/home/suraj/.local/lib/python3.10/site-packages/rest_framework/renderers.py", line 99, in render
    ret = json.dumps(
  File "/home/suraj/.local/lib/python3.10/site-packages/rest_framework/utils/json.py", line 25, in dumps
    return json.dumps(*args, **kwargs)
  File "/usr/lib/python3.10/json/__init__.py", line 238, in dumps
    **kw).encode(obj)
  File "/usr/lib/python3.10/json/encoder.py", line 199, in encode
    chunks = self.iterencode(o, _one_shot=True)
  File "/usr/lib/python3.10/json/encoder.py", line 257, in iterencode
    return _iterencode(o, 0)
  File "/home/suraj/.local/lib/python3.10/site-packages/rest_framework/utils/encoders.py", line 67, in default
    return super().default(obj)
  File "/usr/lib/python3.10/json/encoder.py", line 179, in default
    raise TypeError(f'Object of type {o.__class__.__name__} '
TypeError: Object of type Response is not JSON serializable
2023-06-15 10:16:48 ERROR django.server "GET /api/v1/comments/job-comment/ HTTP/1.1" 500 20507
2023-06-15 10:17:20 ERROR django.request Internal Server Error: /api/v1/comments/job-comment/
Traceback (most recent call last):
  File "/home/suraj/.local/lib/python3.10/site-packages/django/core/handlers/exception.py", line 55, in inner
    response = get_response(request)
  File "/home/suraj/.local/lib/python3.10/site-packages/django/core/handlers/base.py", line 220, in _get_response
    response = response.render()
  File "/home/suraj/.local/lib/python3.10/site-packages/django/template/response.py", line 111, in render
    self.content = self.rendered_content
  File "/home/suraj/.local/lib/python3.10/site-packages/rest_framework/response.py", line 70, in rendered_content
    ret = renderer.render(self.data, accepted_media_type, context)
  File "/home/suraj/.local/lib/python3.10/site-packages/rest_framework/renderers.py", line 99, in render
    ret = json.dumps(
  File "/home/suraj/.local/lib/python3.10/site-packages/rest_framework/utils/json.py", line 25, in dumps
    return json.dumps(*args, **kwargs)
  File "/usr/lib/python3.10/json/__init__.py", line 238, in dumps
    **kw).encode(obj)
  File "/usr/lib/python3.10/json/encoder.py", line 199, in encode
    chunks = self.iterencode(o, _one_shot=True)
  File "/usr/lib/python3.10/json/encoder.py", line 257, in iterencode
    return _iterencode(o, 0)
  File "/home/suraj/.local/lib/python3.10/site-packages/rest_framework/utils/encoders.py", line 67, in default
    return super().default(obj)
  File "/usr/lib/python3.10/json/encoder.py", line 179, in default
    raise TypeError(f'Object of type {o.__class__.__name__} '
TypeError: Object of type type is not JSON serializable
2023-06-15 10:17:20 ERROR django.server "GET /api/v1/comments/job-comment/ HTTP/1.1" 500 20499
2023-06-15 10:19:42 WARNING django.request Unauthorized: /api/v1/comments/job-comment/
2023-06-15 10:19:42 WARNING django.server "GET /api/v1/comments/job-comment/ HTTP/1.1" 401 57
2023-06-15 10:19:48 ERROR django.request Internal Server Error: /api/v1/comments/job-comment/
Traceback (most recent call last):
  File "/home/suraj/.local/lib/python3.10/site-packages/django/core/handlers/exception.py", line 55, in inner
    response = get_response(request)
  File "/home/suraj/.local/lib/python3.10/site-packages/django/core/handlers/base.py", line 220, in _get_response
    response = response.render()
  File "/home/suraj/.local/lib/python3.10/site-packages/django/template/response.py", line 111, in render
    self.content = self.rendered_content
  File "/home/suraj/.local/lib/python3.10/site-packages/rest_framework/response.py", line 70, in rendered_content
    ret = renderer.render(self.data, accepted_media_type, context)
  File "/home/suraj/.local/lib/python3.10/site-packages/rest_framework/renderers.py", line 99, in render
    ret = json.dumps(
  File "/home/suraj/.local/lib/python3.10/site-packages/rest_framework/utils/json.py", line 25, in dumps
    return json.dumps(*args, **kwargs)
  File "/usr/lib/python3.10/json/__init__.py", line 238, in dumps
    **kw).encode(obj)
  File "/usr/lib/python3.10/json/encoder.py", line 199, in encode
    chunks = self.iterencode(o, _one_shot=True)
  File "/usr/lib/python3.10/json/encoder.py", line 257, in iterencode
    return _iterencode(o, 0)
  File "/home/suraj/.local/lib/python3.10/site-packages/rest_framework/utils/encoders.py", line 67, in default
    return super().default(obj)
  File "/usr/lib/python3.10/json/encoder.py", line 179, in default
    raise TypeError(f'Object of type {o.__class__.__name__} '
TypeError: Object of type type is not JSON serializable
2023-06-15 10:19:48 ERROR django.server "GET /api/v1/comments/job-comment/ HTTP/1.1" 500 20499
2023-06-15 10:21:51 WARNING django.request Unauthorized: /api/v1/comments/job-comment/
2023-06-15 10:21:51 WARNING django.server "GET /api/v1/comments/job-comment/ HTTP/1.1" 401 57
2023-06-15 10:21:57 ERROR django.request Internal Server Error: /api/v1/comments/job-comment/
Traceback (most recent call last):
  File "/home/suraj/.local/lib/python3.10/site-packages/django/core/handlers/exception.py", line 55, in inner
    response = get_response(request)
  File "/home/suraj/.local/lib/python3.10/site-packages/django/core/handlers/base.py", line 220, in _get_response
    response = response.render()
  File "/home/suraj/.local/lib/python3.10/site-packages/django/template/response.py", line 111, in render
    self.content = self.rendered_content
  File "/home/suraj/.local/lib/python3.10/site-packages/rest_framework/response.py", line 70, in rendered_content
    ret = renderer.render(self.data, accepted_media_type, context)
  File "/home/suraj/.local/lib/python3.10/site-packages/rest_framework/renderers.py", line 99, in render
    ret = json.dumps(
  File "/home/suraj/.local/lib/python3.10/site-packages/rest_framework/utils/json.py", line 25, in dumps
    return json.dumps(*args, **kwargs)
  File "/usr/lib/python3.10/json/__init__.py", line 238, in dumps
    **kw).encode(obj)
  File "/usr/lib/python3.10/json/encoder.py", line 199, in encode
    chunks = self.iterencode(o, _one_shot=True)
  File "/usr/lib/python3.10/json/encoder.py", line 257, in iterencode
    return _iterencode(o, 0)
  File "/home/suraj/.local/lib/python3.10/site-packages/rest_framework/utils/encoders.py", line 67, in default
    return super().default(obj)
  File "/usr/lib/python3.10/json/encoder.py", line 179, in default
    raise TypeError(f'Object of type {o.__class__.__name__} '
TypeError: Object of type type is not JSON serializable
2023-06-15 10:21:57 ERROR django.server "GET /api/v1/comments/job-comment/ HTTP/1.1" 500 20499
2023-06-15 10:22:54 ERROR django.request Internal Server Error: /api/v1/comments/job-comment/
Traceback (most recent call last):
  File "/home/suraj/.local/lib/python3.10/site-packages/django/core/handlers/exception.py", line 55, in inner
    response = get_response(request)
  File "/home/suraj/.local/lib/python3.10/site-packages/django/core/handlers/base.py", line 220, in _get_response
    response = response.render()
  File "/home/suraj/.local/lib/python3.10/site-packages/django/template/response.py", line 111, in render
    self.content = self.rendered_content
  File "/home/suraj/.local/lib/python3.10/site-packages/rest_framework/response.py", line 70, in rendered_content
    ret = renderer.render(self.data, accepted_media_type, context)
  File "/home/suraj/.local/lib/python3.10/site-packages/rest_framework/renderers.py", line 99, in render
    ret = json.dumps(
  File "/home/suraj/.local/lib/python3.10/site-packages/rest_framework/utils/json.py", line 25, in dumps
    return json.dumps(*args, **kwargs)
  File "/usr/lib/python3.10/json/__init__.py", line 238, in dumps
    **kw).encode(obj)
  File "/usr/lib/python3.10/json/encoder.py", line 199, in encode
    chunks = self.iterencode(o, _one_shot=True)
  File "/usr/lib/python3.10/json/encoder.py", line 257, in iterencode
    return _iterencode(o, 0)
  File "/home/suraj/.local/lib/python3.10/site-packages/rest_framework/utils/encoders.py", line 67, in default
    return super().default(obj)
  File "/usr/lib/python3.10/json/encoder.py", line 179, in default
    raise TypeError(f'Object of type {o.__class__.__name__} '
TypeError: Object of type type is not JSON serializable
2023-06-15 10:22:54 ERROR django.server "GET /api/v1/comments/job-comment/ HTTP/1.1" 500 20499
2023-06-15 10:25:56 ERROR django.request Internal Server Error: /api/v1/comments/job-comment/
Traceback (most recent call last):
  File "/home/suraj/.local/lib/python3.10/site-packages/django/core/handlers/exception.py", line 55, in inner
    response = get_response(request)
  File "/home/suraj/.local/lib/python3.10/site-packages/django/core/handlers/base.py", line 220, in _get_response
    response = response.render()
  File "/home/suraj/.local/lib/python3.10/site-packages/django/template/response.py", line 111, in render
    self.content = self.rendered_content
  File "/home/suraj/.local/lib/python3.10/site-packages/rest_framework/response.py", line 70, in rendered_content
    ret = renderer.render(self.data, accepted_media_type, context)
  File "/home/suraj/.local/lib/python3.10/site-packages/rest_framework/renderers.py", line 99, in render
    ret = json.dumps(
  File "/home/suraj/.local/lib/python3.10/site-packages/rest_framework/utils/json.py", line 25, in dumps
    return json.dumps(*args, **kwargs)
  File "/usr/lib/python3.10/json/__init__.py", line 238, in dumps
    **kw).encode(obj)
  File "/usr/lib/python3.10/json/encoder.py", line 199, in encode
    chunks = self.iterencode(o, _one_shot=True)
  File "/usr/lib/python3.10/json/encoder.py", line 257, in iterencode
    return _iterencode(o, 0)
  File "/home/suraj/.local/lib/python3.10/site-packages/rest_framework/utils/encoders.py", line 67, in default
    return super().default(obj)
  File "/usr/lib/python3.10/json/encoder.py", line 179, in default
    raise TypeError(f'Object of type {o.__class__.__name__} '
TypeError: Object of type type is not JSON serializable
2023-06-15 10:25:56 ERROR django.server "GET /api/v1/comments/job-comment/ HTTP/1.1" 500 20499
2023-06-15 10:28:35 ERROR django.request Internal Server Error: /api/v1/comments/job-comment/
Traceback (most recent call last):
  File "/home/suraj/.local/lib/python3.10/site-packages/django/core/handlers/exception.py", line 55, in inner
    response = get_response(request)
  File "/home/suraj/.local/lib/python3.10/site-packages/django/core/handlers/base.py", line 220, in _get_response
    response = response.render()
  File "/home/suraj/.local/lib/python3.10/site-packages/django/template/response.py", line 111, in render
    self.content = self.rendered_content
  File "/home/suraj/.local/lib/python3.10/site-packages/rest_framework/response.py", line 70, in rendered_content
    ret = renderer.render(self.data, accepted_media_type, context)
  File "/home/suraj/.local/lib/python3.10/site-packages/rest_framework/renderers.py", line 99, in render
    ret = json.dumps(
  File "/home/suraj/.local/lib/python3.10/site-packages/rest_framework/utils/json.py", line 25, in dumps
    return json.dumps(*args, **kwargs)
  File "/usr/lib/python3.10/json/__init__.py", line 238, in dumps
    **kw).encode(obj)
  File "/usr/lib/python3.10/json/encoder.py", line 199, in encode
    chunks = self.iterencode(o, _one_shot=True)
  File "/usr/lib/python3.10/json/encoder.py", line 257, in iterencode
    return _iterencode(o, 0)
  File "/home/suraj/.local/lib/python3.10/site-packages/rest_framework/utils/encoders.py", line 67, in default
    return super().default(obj)
  File "/usr/lib/python3.10/json/encoder.py", line 179, in default
    raise TypeError(f'Object of type {o.__class__.__name__} '
TypeError: Object of type type is not JSON serializable
2023-06-15 10:28:35 ERROR django.server "GET /api/v1/comments/job-comment/ HTTP/1.1" 500 20499
2023-06-15 10:31:47 ERROR django.request Internal Server Error: /db/admin/comments/comments/76f9fac1-3a24-44fb-874d-8902dfab8a7f/change/
Traceback (most recent call last):
  File "/home/suraj/.local/lib/python3.10/site-packages/django/db/backends/utils.py", line 89, in _execute
    return self.cursor.execute(sql, params)
  File "/home/suraj/.local/lib/python3.10/site-packages/django/db/backends/sqlite3/base.py", line 328, in execute
    return super().execute(query, params)
sqlite3.OperationalError: no such column: comments_comments.body

The above exception was the direct cause of the following exception:

Traceback (most recent call last):
  File "/home/suraj/.local/lib/python3.10/site-packages/django/core/handlers/exception.py", line 55, in inner
    response = get_response(request)
  File "/home/suraj/.local/lib/python3.10/site-packages/django/core/handlers/base.py", line 197, in _get_response
    response = wrapped_callback(request, *callback_args, **callback_kwargs)
  File "/home/suraj/.local/lib/python3.10/site-packages/django/contrib/admin/options.py", line 688, in wrapper
    return self.admin_site.admin_view(view)(*args, **kwargs)
  File "/home/suraj/.local/lib/python3.10/site-packages/django/utils/decorators.py", line 134, in _wrapper_view
    response = view_func(request, *args, **kwargs)
  File "/home/suraj/.local/lib/python3.10/site-packages/django/views/decorators/cache.py", line 62, in _wrapper_view_func
    response = view_func(request, *args, **kwargs)
  File "/home/suraj/.local/lib/python3.10/site-packages/django/contrib/admin/sites.py", line 242, in inner
    return view(request, *args, **kwargs)
  File "/home/suraj/.local/lib/python3.10/site-packages/django/contrib/admin/options.py", line 1889, in change_view
    return self.changeform_view(request, object_id, form_url, extra_context)
  File "/home/suraj/.local/lib/python3.10/site-packages/django/utils/decorators.py", line 46, in _wrapper
    return bound_method(*args, **kwargs)
  File "/home/suraj/.local/lib/python3.10/site-packages/django/utils/decorators.py", line 134, in _wrapper_view
    response = view_func(request, *args, **kwargs)
  File "/home/suraj/.local/lib/python3.10/site-packages/django/contrib/admin/options.py", line 1747, in changeform_view
    return self._changeform_view(request, object_id, form_url, extra_context)
  File "/home/suraj/.local/lib/python3.10/site-packages/django/contrib/admin/options.py", line 1767, in _changeform_view
    obj = self.get_object(request, unquote(object_id), to_field)
  File "/home/suraj/.local/lib/python3.10/site-packages/django/contrib/admin/options.py", line 866, in get_object
    return queryset.get(**{field.name: object_id})
  File "/home/suraj/.local/lib/python3.10/site-packages/django/db/models/query.py", line 633, in get
    num = len(clone)
  File "/home/suraj/.local/lib/python3.10/site-packages/django/db/models/query.py", line 380, in __len__
    self._fetch_all()
  File "/home/suraj/.local/lib/python3.10/site-packages/django/db/models/query.py", line 1881, in _fetch_all
    self._result_cache = list(self._iterable_class(self))
  File "/home/suraj/.local/lib/python3.10/site-packages/django/db/models/query.py", line 91, in __iter__
    results = compiler.execute_sql(
  File "/home/suraj/.local/lib/python3.10/site-packages/django/db/models/sql/compiler.py", line 1560, in execute_sql
    cursor.execute(sql, params)
  File "/home/suraj/.local/lib/python3.10/site-packages/django/db/backends/utils.py", line 102, in execute
    return super().execute(sql, params)
  File "/home/suraj/.local/lib/python3.10/site-packages/django/db/backends/utils.py", line 67, in execute
    return self._execute_with_wrappers(
  File "/home/suraj/.local/lib/python3.10/site-packages/django/db/backends/utils.py", line 80, in _execute_with_wrappers
    return executor(sql, params, many, context)
  File "/home/suraj/.local/lib/python3.10/site-packages/django/db/backends/utils.py", line 84, in _execute
    with self.db.wrap_database_errors:
  File "/home/suraj/.local/lib/python3.10/site-packages/django/db/utils.py", line 91, in __exit__
    raise dj_exc_value.with_traceback(traceback) from exc_value
  File "/home/suraj/.local/lib/python3.10/site-packages/django/db/backends/utils.py", line 89, in _execute
    return self.cursor.execute(sql, params)
  File "/home/suraj/.local/lib/python3.10/site-packages/django/db/backends/sqlite3/base.py", line 328, in execute
    return super().execute(query, params)
django.db.utils.OperationalError: no such column: comments_comments.body
2023-06-15 10:31:47 ERROR django.server "GET /db/admin/comments/comments/76f9fac1-3a24-44fb-874d-8902dfab8a7f/change/ HTTP/1.1" 500 184608
2023-06-15 10:31:50 ERROR django.request Internal Server Error: /db/admin/comments/comments/76f9fac1-3a24-44fb-874d-8902dfab8a7f/change/
Traceback (most recent call last):
  File "/home/suraj/.local/lib/python3.10/site-packages/django/db/backends/utils.py", line 89, in _execute
    return self.cursor.execute(sql, params)
  File "/home/suraj/.local/lib/python3.10/site-packages/django/db/backends/sqlite3/base.py", line 328, in execute
    return super().execute(query, params)
sqlite3.OperationalError: no such column: comments_comments.body

The above exception was the direct cause of the following exception:

Traceback (most recent call last):
  File "/home/suraj/.local/lib/python3.10/site-packages/django/core/handlers/exception.py", line 55, in inner
    response = get_response(request)
  File "/home/suraj/.local/lib/python3.10/site-packages/django/core/handlers/base.py", line 197, in _get_response
    response = wrapped_callback(request, *callback_args, **callback_kwargs)
  File "/home/suraj/.local/lib/python3.10/site-packages/django/contrib/admin/options.py", line 688, in wrapper
    return self.admin_site.admin_view(view)(*args, **kwargs)
  File "/home/suraj/.local/lib/python3.10/site-packages/django/utils/decorators.py", line 134, in _wrapper_view
    response = view_func(request, *args, **kwargs)
  File "/home/suraj/.local/lib/python3.10/site-packages/django/views/decorators/cache.py", line 62, in _wrapper_view_func
    response = view_func(request, *args, **kwargs)
  File "/home/suraj/.local/lib/python3.10/site-packages/django/contrib/admin/sites.py", line 242, in inner
    return view(request, *args, **kwargs)
  File "/home/suraj/.local/lib/python3.10/site-packages/django/contrib/admin/options.py", line 1889, in change_view
    return self.changeform_view(request, object_id, form_url, extra_context)
  File "/home/suraj/.local/lib/python3.10/site-packages/django/utils/decorators.py", line 46, in _wrapper
    return bound_method(*args, **kwargs)
  File "/home/suraj/.local/lib/python3.10/site-packages/django/utils/decorators.py", line 134, in _wrapper_view
    response = view_func(request, *args, **kwargs)
  File "/home/suraj/.local/lib/python3.10/site-packages/django/contrib/admin/options.py", line 1747, in changeform_view
    return self._changeform_view(request, object_id, form_url, extra_context)
  File "/home/suraj/.local/lib/python3.10/site-packages/django/contrib/admin/options.py", line 1767, in _changeform_view
    obj = self.get_object(request, unquote(object_id), to_field)
  File "/home/suraj/.local/lib/python3.10/site-packages/django/contrib/admin/options.py", line 866, in get_object
    return queryset.get(**{field.name: object_id})
  File "/home/suraj/.local/lib/python3.10/site-packages/django/db/models/query.py", line 633, in get
    num = len(clone)
  File "/home/suraj/.local/lib/python3.10/site-packages/django/db/models/query.py", line 380, in __len__
    self._fetch_all()
  File "/home/suraj/.local/lib/python3.10/site-packages/django/db/models/query.py", line 1881, in _fetch_all
    self._result_cache = list(self._iterable_class(self))
  File "/home/suraj/.local/lib/python3.10/site-packages/django/db/models/query.py", line 91, in __iter__
    results = compiler.execute_sql(
  File "/home/suraj/.local/lib/python3.10/site-packages/django/db/models/sql/compiler.py", line 1560, in execute_sql
    cursor.execute(sql, params)
  File "/home/suraj/.local/lib/python3.10/site-packages/django/db/backends/utils.py", line 102, in execute
    return super().execute(sql, params)
  File "/home/suraj/.local/lib/python3.10/site-packages/django/db/backends/utils.py", line 67, in execute
    return self._execute_with_wrappers(
  File "/home/suraj/.local/lib/python3.10/site-packages/django/db/backends/utils.py", line 80, in _execute_with_wrappers
    return executor(sql, params, many, context)
  File "/home/suraj/.local/lib/python3.10/site-packages/django/db/backends/utils.py", line 84, in _execute
    with self.db.wrap_database_errors:
  File "/home/suraj/.local/lib/python3.10/site-packages/django/db/utils.py", line 91, in __exit__
    raise dj_exc_value.with_traceback(traceback) from exc_value
  File "/home/suraj/.local/lib/python3.10/site-packages/django/db/backends/utils.py", line 89, in _execute
    return self.cursor.execute(sql, params)
  File "/home/suraj/.local/lib/python3.10/site-packages/django/db/backends/sqlite3/base.py", line 328, in execute
    return super().execute(query, params)
django.db.utils.OperationalError: no such column: comments_comments.body
2023-06-15 10:31:50 ERROR django.server "GET /db/admin/comments/comments/76f9fac1-3a24-44fb-874d-8902dfab8a7f/change/ HTTP/1.1" 500 184567
2023-06-15 10:44:17 ERROR django.request Internal Server Error: /api/v1/comments/job-comment/
Traceback (most recent call last):
  File "/home/suraj/.local/lib/python3.10/site-packages/django/core/handlers/exception.py", line 55, in inner
    response = get_response(request)
  File "/home/suraj/.local/lib/python3.10/site-packages/django/core/handlers/base.py", line 197, in _get_response
    response = wrapped_callback(request, *callback_args, **callback_kwargs)
  File "/home/suraj/.local/lib/python3.10/site-packages/django/views/decorators/csrf.py", line 56, in wrapper_view
    return view_func(*args, **kwargs)
  File "/home/suraj/.local/lib/python3.10/site-packages/rest_framework/viewsets.py", line 125, in view
    return self.dispatch(request, *args, **kwargs)
  File "/home/suraj/.local/lib/python3.10/site-packages/rest_framework/views.py", line 509, in dispatch
    response = self.handle_exception(exc)
  File "/home/suraj/.local/lib/python3.10/site-packages/rest_framework/views.py", line 469, in handle_exception
    self.raise_uncaught_exception(exc)
  File "/home/suraj/.local/lib/python3.10/site-packages/rest_framework/views.py", line 480, in raise_uncaught_exception
    raise exc
  File "/home/suraj/.local/lib/python3.10/site-packages/rest_framework/views.py", line 506, in dispatch
    response = handler(request, *args, **kwargs)
  File "/home/suraj/Desktop/Python/JobBackend/JobPortalBackend/common/permissions.py", line 72, in decorated_func
    return func(self, *args, **kwargs)
  File "/home/suraj/Desktop/Python/JobBackend/JobPortalBackend/comments/api/viewsets/comments.py", line 114, in create
    super().create(request, *args, **kwargs)
  File "/home/suraj/.local/lib/python3.10/site-packages/rest_framework/mixins.py", line 17, in create
    serializer = self.get_serializer(data=request.data)
  File "/home/suraj/.local/lib/python3.10/site-packages/rest_framework/generics.py", line 110, in get_serializer
    return serializer_class(*args, **kwargs)
TypeError: 'NoneType' object is not callable
2023-06-15 10:44:17 ERROR django.server "POST /api/v1/comments/job-comment/ HTTP/1.1" 500 20962
2023-06-15 10:44:25 WARNING django.request Bad Request: /api/v1/comments/job-comment/
2023-06-15 10:44:25 WARNING django.server "POST /api/v1/comments/job-comment/ HTTP/1.1" 400 75
2023-06-15 10:44:32 ERROR django.request Internal Server Error: /api/v1/comments/job-comment/
Traceback (most recent call last):
  File "/home/suraj/.local/lib/python3.10/site-packages/django/core/handlers/exception.py", line 55, in inner
    response = get_response(request)
  File "/home/suraj/.local/lib/python3.10/site-packages/django/core/handlers/base.py", line 197, in _get_response
    response = wrapped_callback(request, *callback_args, **callback_kwargs)
  File "/home/suraj/.local/lib/python3.10/site-packages/django/views/decorators/csrf.py", line 56, in wrapper_view
    return view_func(*args, **kwargs)
  File "/home/suraj/.local/lib/python3.10/site-packages/rest_framework/viewsets.py", line 125, in view
    return self.dispatch(request, *args, **kwargs)
  File "/home/suraj/.local/lib/python3.10/site-packages/rest_framework/views.py", line 509, in dispatch
    response = self.handle_exception(exc)
  File "/home/suraj/.local/lib/python3.10/site-packages/rest_framework/views.py", line 469, in handle_exception
    self.raise_uncaught_exception(exc)
  File "/home/suraj/.local/lib/python3.10/site-packages/rest_framework/views.py", line 480, in raise_uncaught_exception
    raise exc
  File "/home/suraj/.local/lib/python3.10/site-packages/rest_framework/views.py", line 506, in dispatch
    response = handler(request, *args, **kwargs)
  File "/home/suraj/Desktop/Python/JobBackend/JobPortalBackend/common/permissions.py", line 72, in decorated_func
    return func(self, *args, **kwargs)
  File "/home/suraj/Desktop/Python/JobBackend/JobPortalBackend/comments/api/viewsets/comments.py", line 114, in create
    super().create(request, *args, **kwargs)
  File "/home/suraj/.local/lib/python3.10/site-packages/rest_framework/mixins.py", line 17, in create
    serializer = self.get_serializer(data=request.data)
  File "/home/suraj/.local/lib/python3.10/site-packages/rest_framework/generics.py", line 110, in get_serializer
    return serializer_class(*args, **kwargs)
TypeError: 'NoneType' object is not callable
2023-06-15 10:44:32 ERROR django.server "POST /api/v1/comments/job-comment/ HTTP/1.1" 500 20962
2023-06-15 10:45:18 ERROR django.request Internal Server Error: /api/v1/comments/job-comment/
Traceback (most recent call last):
  File "/home/suraj/.local/lib/python3.10/site-packages/django/core/handlers/exception.py", line 55, in inner
    response = get_response(request)
  File "/home/suraj/.local/lib/python3.10/site-packages/django/core/handlers/base.py", line 197, in _get_response
    response = wrapped_callback(request, *callback_args, **callback_kwargs)
  File "/home/suraj/.local/lib/python3.10/site-packages/django/views/decorators/csrf.py", line 56, in wrapper_view
    return view_func(*args, **kwargs)
  File "/home/suraj/.local/lib/python3.10/site-packages/rest_framework/viewsets.py", line 125, in view
    return self.dispatch(request, *args, **kwargs)
  File "/home/suraj/.local/lib/python3.10/site-packages/rest_framework/views.py", line 509, in dispatch
    response = self.handle_exception(exc)
  File "/home/suraj/.local/lib/python3.10/site-packages/rest_framework/views.py", line 469, in handle_exception
    self.raise_uncaught_exception(exc)
  File "/home/suraj/.local/lib/python3.10/site-packages/rest_framework/views.py", line 480, in raise_uncaught_exception
    raise exc
  File "/home/suraj/.local/lib/python3.10/site-packages/rest_framework/views.py", line 506, in dispatch
    response = handler(request, *args, **kwargs)
  File "/home/suraj/Desktop/Python/JobBackend/JobPortalBackend/common/permissions.py", line 72, in decorated_func
    return func(self, *args, **kwargs)
  File "/home/suraj/Desktop/Python/JobBackend/JobPortalBackend/comments/api/viewsets/comments.py", line 114, in create
    super().create(request, *args, **kwargs)
  File "/home/suraj/.local/lib/python3.10/site-packages/rest_framework/mixins.py", line 17, in create
    serializer = self.get_serializer(data=request.data)
  File "/home/suraj/.local/lib/python3.10/site-packages/rest_framework/generics.py", line 110, in get_serializer
    return serializer_class(*args, **kwargs)
TypeError: 'NoneType' object is not callable
2023-06-15 10:45:18 ERROR django.server "POST /api/v1/comments/job-comment/ HTTP/1.1" 500 20962
2023-06-15 10:45:29 WARNING django.request Bad Request: /api/v1/comments/job-comment/
2023-06-15 10:45:29 WARNING django.server "POST /api/v1/comments/job-comment/ HTTP/1.1" 400 75
2023-06-15 10:45:52 WARNING django.request Bad Request: /api/v1/comments/job-comment/
2023-06-15 10:45:52 WARNING django.server "POST /api/v1/comments/job-comment/ HTTP/1.1" 400 74
2023-06-15 10:46:00 ERROR django.request Internal Server Error: /api/v1/comments/job-comment/
Traceback (most recent call last):
  File "/home/suraj/.local/lib/python3.10/site-packages/django/core/handlers/exception.py", line 55, in inner
    response = get_response(request)
  File "/home/suraj/.local/lib/python3.10/site-packages/django/core/handlers/base.py", line 197, in _get_response
    response = wrapped_callback(request, *callback_args, **callback_kwargs)
  File "/home/suraj/.local/lib/python3.10/site-packages/django/views/decorators/csrf.py", line 56, in wrapper_view
    return view_func(*args, **kwargs)
  File "/home/suraj/.local/lib/python3.10/site-packages/rest_framework/viewsets.py", line 125, in view
    return self.dispatch(request, *args, **kwargs)
  File "/home/suraj/.local/lib/python3.10/site-packages/rest_framework/views.py", line 509, in dispatch
    response = self.handle_exception(exc)
  File "/home/suraj/.local/lib/python3.10/site-packages/rest_framework/views.py", line 469, in handle_exception
    self.raise_uncaught_exception(exc)
  File "/home/suraj/.local/lib/python3.10/site-packages/rest_framework/views.py", line 480, in raise_uncaught_exception
    raise exc
  File "/home/suraj/.local/lib/python3.10/site-packages/rest_framework/views.py", line 506, in dispatch
    response = handler(request, *args, **kwargs)
  File "/home/suraj/Desktop/Python/JobBackend/JobPortalBackend/common/permissions.py", line 72, in decorated_func
    return func(self, *args, **kwargs)
  File "/home/suraj/Desktop/Python/JobBackend/JobPortalBackend/comments/api/viewsets/comments.py", line 114, in create
    super().create(request, *args, **kwargs)
  File "/home/suraj/.local/lib/python3.10/site-packages/rest_framework/mixins.py", line 17, in create
    serializer = self.get_serializer(data=request.data)
  File "/home/suraj/.local/lib/python3.10/site-packages/rest_framework/generics.py", line 110, in get_serializer
    return serializer_class(*args, **kwargs)
TypeError: 'NoneType' object is not callable
2023-06-15 10:46:00 ERROR django.server "POST /api/v1/comments/job-comment/ HTTP/1.1" 500 20962
2023-06-15 10:46:25 ERROR django.request Internal Server Error: /api/v1/comments/job-comment/
Traceback (most recent call last):
  File "/home/suraj/.local/lib/python3.10/site-packages/django/core/handlers/exception.py", line 55, in inner
    response = get_response(request)
  File "/home/suraj/.local/lib/python3.10/site-packages/django/core/handlers/base.py", line 197, in _get_response
    response = wrapped_callback(request, *callback_args, **callback_kwargs)
  File "/home/suraj/.local/lib/python3.10/site-packages/django/views/decorators/csrf.py", line 56, in wrapper_view
    return view_func(*args, **kwargs)
  File "/home/suraj/.local/lib/python3.10/site-packages/rest_framework/viewsets.py", line 125, in view
    return self.dispatch(request, *args, **kwargs)
  File "/home/suraj/.local/lib/python3.10/site-packages/rest_framework/views.py", line 509, in dispatch
    response = self.handle_exception(exc)
  File "/home/suraj/.local/lib/python3.10/site-packages/rest_framework/views.py", line 469, in handle_exception
    self.raise_uncaught_exception(exc)
  File "/home/suraj/.local/lib/python3.10/site-packages/rest_framework/views.py", line 480, in raise_uncaught_exception
    raise exc
  File "/home/suraj/.local/lib/python3.10/site-packages/rest_framework/views.py", line 506, in dispatch
    response = handler(request, *args, **kwargs)
  File "/home/suraj/Desktop/Python/JobBackend/JobPortalBackend/common/permissions.py", line 72, in decorated_func
    return func(self, *args, **kwargs)
  File "/home/suraj/Desktop/Python/JobBackend/JobPortalBackend/comments/api/viewsets/comments.py", line 114, in create
    super().create(request, *args, **kwargs)
  File "/home/suraj/.local/lib/python3.10/site-packages/rest_framework/mixins.py", line 17, in create
    serializer = self.get_serializer(data=request.data)
  File "/home/suraj/.local/lib/python3.10/site-packages/rest_framework/generics.py", line 110, in get_serializer
    return serializer_class(*args, **kwargs)
TypeError: 'NoneType' object is not callable
2023-06-15 10:46:25 ERROR django.server "POST /api/v1/comments/job-comment/ HTTP/1.1" 500 20962
2023-06-15 10:46:56 ERROR django.request Internal Server Error: /api/v1/comments/job-comment/
Traceback (most recent call last):
  File "/home/suraj/.local/lib/python3.10/site-packages/django/core/handlers/exception.py", line 55, in inner
    response = get_response(request)
  File "/home/suraj/.local/lib/python3.10/site-packages/django/core/handlers/base.py", line 197, in _get_response
    response = wrapped_callback(request, *callback_args, **callback_kwargs)
  File "/home/suraj/.local/lib/python3.10/site-packages/django/views/decorators/csrf.py", line 56, in wrapper_view
    return view_func(*args, **kwargs)
  File "/home/suraj/.local/lib/python3.10/site-packages/rest_framework/viewsets.py", line 125, in view
    return self.dispatch(request, *args, **kwargs)
  File "/home/suraj/.local/lib/python3.10/site-packages/rest_framework/views.py", line 509, in dispatch
    response = self.handle_exception(exc)
  File "/home/suraj/.local/lib/python3.10/site-packages/rest_framework/views.py", line 469, in handle_exception
    self.raise_uncaught_exception(exc)
  File "/home/suraj/.local/lib/python3.10/site-packages/rest_framework/views.py", line 480, in raise_uncaught_exception
    raise exc
  File "/home/suraj/.local/lib/python3.10/site-packages/rest_framework/views.py", line 506, in dispatch
    response = handler(request, *args, **kwargs)
  File "/home/suraj/Desktop/Python/JobBackend/JobPortalBackend/common/permissions.py", line 72, in decorated_func
    return func(self, *args, **kwargs)
  File "/home/suraj/Desktop/Python/JobBackend/JobPortalBackend/comments/api/viewsets/comments.py", line 114, in create
    super().create(request, *args, **kwargs)
  File "/home/suraj/.local/lib/python3.10/site-packages/rest_framework/mixins.py", line 17, in create
    serializer = self.get_serializer(data=request.data)
  File "/home/suraj/.local/lib/python3.10/site-packages/rest_framework/generics.py", line 110, in get_serializer
    return serializer_class(*args, **kwargs)
TypeError: 'NoneType' object is not callable
2023-06-15 10:46:56 ERROR django.server "POST /api/v1/comments/job-comment/ HTTP/1.1" 500 20962
2023-06-15 10:47:27 WARNING django.request Bad Request: /api/v1/comments/job-comment/
2023-06-15 10:47:27 WARNING django.server "POST /api/v1/comments/job-comment/ HTTP/1.1" 400 55
2023-06-15 10:48:29 ERROR django.request Internal Server Error: /api/v1/comments/job-comment/
Traceback (most recent call last):
  File "/home/suraj/.local/lib/python3.10/site-packages/django/core/handlers/exception.py", line 55, in inner
    response = get_response(request)
  File "/home/suraj/.local/lib/python3.10/site-packages/django/core/handlers/base.py", line 197, in _get_response
    response = wrapped_callback(request, *callback_args, **callback_kwargs)
  File "/home/suraj/.local/lib/python3.10/site-packages/django/views/decorators/csrf.py", line 56, in wrapper_view
    return view_func(*args, **kwargs)
  File "/home/suraj/.local/lib/python3.10/site-packages/rest_framework/viewsets.py", line 125, in view
    return self.dispatch(request, *args, **kwargs)
  File "/home/suraj/.local/lib/python3.10/site-packages/rest_framework/views.py", line 509, in dispatch
    response = self.handle_exception(exc)
  File "/home/suraj/.local/lib/python3.10/site-packages/rest_framework/views.py", line 469, in handle_exception
    self.raise_uncaught_exception(exc)
  File "/home/suraj/.local/lib/python3.10/site-packages/rest_framework/views.py", line 480, in raise_uncaught_exception
    raise exc
  File "/home/suraj/.local/lib/python3.10/site-packages/rest_framework/views.py", line 506, in dispatch
    response = handler(request, *args, **kwargs)
  File "/home/suraj/Desktop/Python/JobBackend/JobPortalBackend/common/permissions.py", line 72, in decorated_func
    return func(self, *args, **kwargs)
  File "/home/suraj/Desktop/Python/JobBackend/JobPortalBackend/comments/api/viewsets/comments.py", line 116, in create
    super().create(request, *args, **kwargs)
  File "/home/suraj/.local/lib/python3.10/site-packages/rest_framework/mixins.py", line 17, in create
    serializer = self.get_serializer(data=request.data)
  File "/home/suraj/.local/lib/python3.10/site-packages/rest_framework/generics.py", line 110, in get_serializer
    return serializer_class(*args, **kwargs)
TypeError: 'NoneType' object is not callable
2023-06-15 10:48:29 ERROR django.server "POST /api/v1/comments/job-comment/ HTTP/1.1" 500 20962
2023-06-15 10:49:34 WARNING django.request Unauthorized: /api/v1/comments/job-comment/
2023-06-15 10:49:34 WARNING django.server "POST /api/v1/comments/job-comment/ HTTP/1.1" 401 57
2023-06-15 10:49:39 WARNING django.request Bad Request: /api/v1/comments/job-comment/
2023-06-15 10:49:39 WARNING django.server "POST /api/v1/comments/job-comment/ HTTP/1.1" 400 55
2023-06-15 10:49:39 WARNING django.request Bad Request: /api/v1/comments/job-comment/
2023-06-15 10:49:39 WARNING django.server "POST /api/v1/comments/job-comment/ HTTP/1.1" 400 55
2023-06-15 10:50:08 WARNING django.request Bad Request: /api/v1/comments/job-comment/
2023-06-15 10:50:08 WARNING django.server "POST /api/v1/comments/job-comment/ HTTP/1.1" 400 74
2023-06-15 10:50:20 WARNING django.request Bad Request: /api/v1/comments/job-comment/
2023-06-15 10:50:20 WARNING django.server "POST /api/v1/comments/job-comment/ HTTP/1.1" 400 159
2023-06-15 10:50:42 WARNING django.request Bad Request: /api/v1/comments/job-comment/
2023-06-15 10:50:42 WARNING django.server "POST /api/v1/comments/job-comment/ HTTP/1.1" 400 159
2023-06-15 10:51:45 WARNING django.request Bad Request: /api/v1/comments/job-comment/
2023-06-15 10:51:45 WARNING django.server "POST /api/v1/comments/job-comment/ HTTP/1.1" 400 55
2023-06-15 10:53:59 WARNING django.request Bad Request: /api/v1/comments/job-comment/
2023-06-15 10:53:59 WARNING django.server "POST /api/v1/comments/job-comment/ HTTP/1.1" 400 54
2023-06-15 10:54:05 WARNING django.request Bad Request: /api/v1/comments/job-comment/
2023-06-15 10:54:05 WARNING django.server "POST /api/v1/comments/job-comment/ HTTP/1.1" 400 146
2023-06-15 10:54:30 WARNING django.request Bad Request: /api/v1/comments/job-comment/
2023-06-15 10:54:30 WARNING django.server "POST /api/v1/comments/job-comment/ HTTP/1.1" 400 146
2023-06-15 10:55:05 WARNING django.request Bad Request: /api/v1/comments/job-comment/
2023-06-15 10:55:05 WARNING django.server "POST /api/v1/comments/job-comment/ HTTP/1.1" 400 51
2023-06-15 10:57:29 WARNING django.request Bad Request: /api/v1/comments/job-comment/
2023-06-15 10:57:29 WARNING django.server "POST /api/v1/comments/job-comment/ HTTP/1.1" 400 76
2023-06-15 10:58:59 WARNING django.request Bad Request: /api/v1/comments/job-comment/
2023-06-15 10:58:59 WARNING django.server "POST /api/v1/comments/job-comment/ HTTP/1.1" 400 76
2023-06-15 10:59:04 WARNING django.request Bad Request: /api/v1/comments/job-comment/
2023-06-15 10:59:04 WARNING django.server "POST /api/v1/comments/job-comment/ HTTP/1.1" 400 51
2023-06-15 10:59:13 WARNING django.request Bad Request: /api/v1/comments/job-comment/
2023-06-15 10:59:13 WARNING django.server "POST /api/v1/comments/job-comment/ HTTP/1.1" 400 91
2023-06-15 11:00:41 WARNING django.request Bad Request: /api/v1/comments/job-comment/
2023-06-15 11:00:41 WARNING django.server "POST /api/v1/comments/job-comment/ HTTP/1.1" 400 54
2023-06-15 11:00:52 ERROR django.request Internal Server Error: /api/v1/comments/job-comment/
Traceback (most recent call last):
  File "/home/suraj/.local/lib/python3.10/site-packages/django/db/models/fields/__init__.py", line 2690, in to_python
    return uuid.UUID(**{input_form: value})
  File "/usr/lib/python3.10/uuid.py", line 177, in __init__
    raise ValueError('badly formed hexadecimal UUID string')
ValueError: badly formed hexadecimal UUID string

During handling of the above exception, another exception occurred:

Traceback (most recent call last):
  File "/home/suraj/.local/lib/python3.10/site-packages/django/core/handlers/exception.py", line 55, in inner
    response = get_response(request)
  File "/home/suraj/.local/lib/python3.10/site-packages/django/core/handlers/base.py", line 197, in _get_response
    response = wrapped_callback(request, *callback_args, **callback_kwargs)
  File "/home/suraj/.local/lib/python3.10/site-packages/django/views/decorators/csrf.py", line 56, in wrapper_view
    return view_func(*args, **kwargs)
  File "/home/suraj/.local/lib/python3.10/site-packages/rest_framework/viewsets.py", line 125, in view
    return self.dispatch(request, *args, **kwargs)
  File "/home/suraj/.local/lib/python3.10/site-packages/rest_framework/views.py", line 509, in dispatch
    response = self.handle_exception(exc)
  File "/home/suraj/.local/lib/python3.10/site-packages/rest_framework/views.py", line 469, in handle_exception
    self.raise_uncaught_exception(exc)
  File "/home/suraj/.local/lib/python3.10/site-packages/rest_framework/views.py", line 480, in raise_uncaught_exception
    raise exc
  File "/home/suraj/.local/lib/python3.10/site-packages/rest_framework/views.py", line 506, in dispatch
    response = handler(request, *args, **kwargs)
  File "/home/suraj/Desktop/Python/JobBackend/JobPortalBackend/common/permissions.py", line 72, in decorated_func
    return func(self, *args, **kwargs)
  File "/home/suraj/Desktop/Python/JobBackend/JobPortalBackend/comments/api/viewsets/comments.py", line 116, in create
    super().create(request, *args, **kwargs)
  File "/home/suraj/.local/lib/python3.10/site-packages/rest_framework/mixins.py", line 18, in create
    serializer.is_valid(raise_exception=True)
  File "/home/suraj/Desktop/Python/JobBackend/JobPortalBackend/comments/api/serializers/comments.py", line 62, in is_valid
    parent = Comments.objects.filter(id=data.get("parent"))
  File "/home/suraj/.local/lib/python3.10/site-packages/django/db/models/manager.py", line 87, in manager_method
    return getattr(self.get_queryset(), name)(*args, **kwargs)
  File "/home/suraj/.local/lib/python3.10/site-packages/django/db/models/query.py", line 1436, in filter
    return self._filter_or_exclude(False, args, kwargs)
  File "/home/suraj/.local/lib/python3.10/site-packages/django/db/models/query.py", line 1454, in _filter_or_exclude
    clone._filter_or_exclude_inplace(negate, args, kwargs)
  File "/home/suraj/.local/lib/python3.10/site-packages/django/db/models/query.py", line 1461, in _filter_or_exclude_inplace
    self._query.add_q(Q(*args, **kwargs))
  File "/home/suraj/.local/lib/python3.10/site-packages/django/db/models/sql/query.py", line 1498, in add_q
    clause, _ = self._add_q(q_object, self.used_aliases)
  File "/home/suraj/.local/lib/python3.10/site-packages/django/db/models/sql/query.py", line 1529, in _add_q
    child_clause, needed_inner = self.build_filter(
  File "/home/suraj/.local/lib/python3.10/site-packages/django/db/models/sql/query.py", line 1444, in build_filter
    condition = self.build_lookup(lookups, col, value)
  File "/home/suraj/.local/lib/python3.10/site-packages/django/db/models/sql/query.py", line 1271, in build_lookup
    lookup = lookup_class(lhs, rhs)
  File "/home/suraj/.local/lib/python3.10/site-packages/django/db/models/lookups.py", line 27, in __init__
    self.rhs = self.get_prep_lookup()
  File "/home/suraj/.local/lib/python3.10/site-packages/django/db/models/lookups.py", line 341, in get_prep_lookup
    return super().get_prep_lookup()
  File "/home/suraj/.local/lib/python3.10/site-packages/django/db/models/lookups.py", line 85, in get_prep_lookup
    return self.lhs.output_field.get_prep_value(self.rhs)
  File "/home/suraj/.local/lib/python3.10/site-packages/django/db/models/fields/__init__.py", line 2674, in get_prep_value
    return self.to_python(value)
  File "/home/suraj/.local/lib/python3.10/site-packages/django/db/models/fields/__init__.py", line 2692, in to_python
    raise exceptions.ValidationError(
django.core.exceptions.ValidationError: ['“” is not a valid UUID.']
2023-06-15 11:00:52 ERROR django.server "POST /api/v1/comments/job-comment/ HTTP/1.1" 500 23484
2023-06-15 11:02:12 ERROR django.request Internal Server Error: /api/v1/comments/job-comment/
Traceback (most recent call last):
  File "/home/suraj/.local/lib/python3.10/site-packages/django/db/models/fields/__init__.py", line 2690, in to_python
    return uuid.UUID(**{input_form: value})
  File "/usr/lib/python3.10/uuid.py", line 177, in __init__
    raise ValueError('badly formed hexadecimal UUID string')
ValueError: badly formed hexadecimal UUID string

During handling of the above exception, another exception occurred:

Traceback (most recent call last):
  File "/home/suraj/.local/lib/python3.10/site-packages/django/core/handlers/exception.py", line 55, in inner
    response = get_response(request)
  File "/home/suraj/.local/lib/python3.10/site-packages/django/core/handlers/base.py", line 197, in _get_response
    response = wrapped_callback(request, *callback_args, **callback_kwargs)
  File "/home/suraj/.local/lib/python3.10/site-packages/django/views/decorators/csrf.py", line 56, in wrapper_view
    return view_func(*args, **kwargs)
  File "/home/suraj/.local/lib/python3.10/site-packages/rest_framework/viewsets.py", line 125, in view
    return self.dispatch(request, *args, **kwargs)
  File "/home/suraj/.local/lib/python3.10/site-packages/rest_framework/views.py", line 509, in dispatch
    response = self.handle_exception(exc)
  File "/home/suraj/.local/lib/python3.10/site-packages/rest_framework/views.py", line 469, in handle_exception
    self.raise_uncaught_exception(exc)
  File "/home/suraj/.local/lib/python3.10/site-packages/rest_framework/views.py", line 480, in raise_uncaught_exception
    raise exc
  File "/home/suraj/.local/lib/python3.10/site-packages/rest_framework/views.py", line 506, in dispatch
    response = handler(request, *args, **kwargs)
  File "/home/suraj/Desktop/Python/JobBackend/JobPortalBackend/common/permissions.py", line 72, in decorated_func
    return func(self, *args, **kwargs)
  File "/home/suraj/Desktop/Python/JobBackend/JobPortalBackend/comments/api/viewsets/comments.py", line 116, in create
    super().create(request, *args, **kwargs)
  File "/home/suraj/.local/lib/python3.10/site-packages/rest_framework/mixins.py", line 18, in create
    serializer.is_valid(raise_exception=True)
  File "/home/suraj/Desktop/Python/JobBackend/JobPortalBackend/comments/api/serializers/comments.py", line 62, in is_valid
    parent = Comments.objects.filter(id=data.get("parent"))
  File "/home/suraj/.local/lib/python3.10/site-packages/django/db/models/manager.py", line 87, in manager_method
    return getattr(self.get_queryset(), name)(*args, **kwargs)
  File "/home/suraj/.local/lib/python3.10/site-packages/django/db/models/query.py", line 1436, in filter
    return self._filter_or_exclude(False, args, kwargs)
  File "/home/suraj/.local/lib/python3.10/site-packages/django/db/models/query.py", line 1454, in _filter_or_exclude
    clone._filter_or_exclude_inplace(negate, args, kwargs)
  File "/home/suraj/.local/lib/python3.10/site-packages/django/db/models/query.py", line 1461, in _filter_or_exclude_inplace
    self._query.add_q(Q(*args, **kwargs))
  File "/home/suraj/.local/lib/python3.10/site-packages/django/db/models/sql/query.py", line 1498, in add_q
    clause, _ = self._add_q(q_object, self.used_aliases)
  File "/home/suraj/.local/lib/python3.10/site-packages/django/db/models/sql/query.py", line 1529, in _add_q
    child_clause, needed_inner = self.build_filter(
  File "/home/suraj/.local/lib/python3.10/site-packages/django/db/models/sql/query.py", line 1444, in build_filter
    condition = self.build_lookup(lookups, col, value)
  File "/home/suraj/.local/lib/python3.10/site-packages/django/db/models/sql/query.py", line 1271, in build_lookup
    lookup = lookup_class(lhs, rhs)
  File "/home/suraj/.local/lib/python3.10/site-packages/django/db/models/lookups.py", line 27, in __init__
    self.rhs = self.get_prep_lookup()
  File "/home/suraj/.local/lib/python3.10/site-packages/django/db/models/lookups.py", line 341, in get_prep_lookup
    return super().get_prep_lookup()
  File "/home/suraj/.local/lib/python3.10/site-packages/django/db/models/lookups.py", line 85, in get_prep_lookup
    return self.lhs.output_field.get_prep_value(self.rhs)
  File "/home/suraj/.local/lib/python3.10/site-packages/django/db/models/fields/__init__.py", line 2674, in get_prep_value
    return self.to_python(value)
  File "/home/suraj/.local/lib/python3.10/site-packages/django/db/models/fields/__init__.py", line 2692, in to_python
    raise exceptions.ValidationError(
django.core.exceptions.ValidationError: ['“” is not a valid UUID.']
2023-06-15 11:02:12 ERROR django.server "POST /api/v1/comments/job-comment/ HTTP/1.1" 500 23484
2023-06-15 11:03:25 ERROR django.request Internal Server Error: /api/v1/comments/job-comment/
Traceback (most recent call last):
  File "/home/suraj/.local/lib/python3.10/site-packages/django/db/models/fields/__init__.py", line 2690, in to_python
    return uuid.UUID(**{input_form: value})
  File "/usr/lib/python3.10/uuid.py", line 177, in __init__
    raise ValueError('badly formed hexadecimal UUID string')
ValueError: badly formed hexadecimal UUID string

During handling of the above exception, another exception occurred:

Traceback (most recent call last):
  File "/home/suraj/.local/lib/python3.10/site-packages/django/core/handlers/exception.py", line 55, in inner
    response = get_response(request)
  File "/home/suraj/.local/lib/python3.10/site-packages/django/core/handlers/base.py", line 197, in _get_response
    response = wrapped_callback(request, *callback_args, **callback_kwargs)
  File "/home/suraj/.local/lib/python3.10/site-packages/django/views/decorators/csrf.py", line 56, in wrapper_view
    return view_func(*args, **kwargs)
  File "/home/suraj/.local/lib/python3.10/site-packages/rest_framework/viewsets.py", line 125, in view
    return self.dispatch(request, *args, **kwargs)
  File "/home/suraj/.local/lib/python3.10/site-packages/rest_framework/views.py", line 509, in dispatch
    response = self.handle_exception(exc)
  File "/home/suraj/.local/lib/python3.10/site-packages/rest_framework/views.py", line 469, in handle_exception
    self.raise_uncaught_exception(exc)
  File "/home/suraj/.local/lib/python3.10/site-packages/rest_framework/views.py", line 480, in raise_uncaught_exception
    raise exc
  File "/home/suraj/.local/lib/python3.10/site-packages/rest_framework/views.py", line 506, in dispatch
    response = handler(request, *args, **kwargs)
  File "/home/suraj/Desktop/Python/JobBackend/JobPortalBackend/common/permissions.py", line 72, in decorated_func
    return func(self, *args, **kwargs)
  File "/home/suraj/Desktop/Python/JobBackend/JobPortalBackend/comments/api/viewsets/comments.py", line 116, in create
    super().create(request, *args, **kwargs)
  File "/home/suraj/.local/lib/python3.10/site-packages/rest_framework/mixins.py", line 18, in create
    serializer.is_valid(raise_exception=True)
  File "/home/suraj/Desktop/Python/JobBackend/JobPortalBackend/comments/api/serializers/comments.py", line 63, in is_valid
    parent = Comments.objects.filter(id=data.get("parent"))
  File "/home/suraj/.local/lib/python3.10/site-packages/django/db/models/manager.py", line 87, in manager_method
    return getattr(self.get_queryset(), name)(*args, **kwargs)
  File "/home/suraj/.local/lib/python3.10/site-packages/django/db/models/query.py", line 1436, in filter
    return self._filter_or_exclude(False, args, kwargs)
  File "/home/suraj/.local/lib/python3.10/site-packages/django/db/models/query.py", line 1454, in _filter_or_exclude
    clone._filter_or_exclude_inplace(negate, args, kwargs)
  File "/home/suraj/.local/lib/python3.10/site-packages/django/db/models/query.py", line 1461, in _filter_or_exclude_inplace
    self._query.add_q(Q(*args, **kwargs))
  File "/home/suraj/.local/lib/python3.10/site-packages/django/db/models/sql/query.py", line 1498, in add_q
    clause, _ = self._add_q(q_object, self.used_aliases)
  File "/home/suraj/.local/lib/python3.10/site-packages/django/db/models/sql/query.py", line 1529, in _add_q
    child_clause, needed_inner = self.build_filter(
  File "/home/suraj/.local/lib/python3.10/site-packages/django/db/models/sql/query.py", line 1444, in build_filter
    condition = self.build_lookup(lookups, col, value)
  File "/home/suraj/.local/lib/python3.10/site-packages/django/db/models/sql/query.py", line 1271, in build_lookup
    lookup = lookup_class(lhs, rhs)
  File "/home/suraj/.local/lib/python3.10/site-packages/django/db/models/lookups.py", line 27, in __init__
    self.rhs = self.get_prep_lookup()
  File "/home/suraj/.local/lib/python3.10/site-packages/django/db/models/lookups.py", line 341, in get_prep_lookup
    return super().get_prep_lookup()
  File "/home/suraj/.local/lib/python3.10/site-packages/django/db/models/lookups.py", line 85, in get_prep_lookup
    return self.lhs.output_field.get_prep_value(self.rhs)
  File "/home/suraj/.local/lib/python3.10/site-packages/django/db/models/fields/__init__.py", line 2674, in get_prep_value
    return self.to_python(value)
  File "/home/suraj/.local/lib/python3.10/site-packages/django/db/models/fields/__init__.py", line 2692, in to_python
    raise exceptions.ValidationError(
django.core.exceptions.ValidationError: ['“” is not a valid UUID.']
2023-06-15 11:03:25 ERROR django.server "POST /api/v1/comments/job-comment/ HTTP/1.1" 500 23484
2023-06-15 11:03:26 ERROR django.request Internal Server Error: /api/v1/comments/job-comment/
Traceback (most recent call last):
  File "/home/suraj/.local/lib/python3.10/site-packages/django/db/models/fields/__init__.py", line 2690, in to_python
    return uuid.UUID(**{input_form: value})
  File "/usr/lib/python3.10/uuid.py", line 177, in __init__
    raise ValueError('badly formed hexadecimal UUID string')
ValueError: badly formed hexadecimal UUID string

During handling of the above exception, another exception occurred:

Traceback (most recent call last):
  File "/home/suraj/.local/lib/python3.10/site-packages/django/core/handlers/exception.py", line 55, in inner
    response = get_response(request)
  File "/home/suraj/.local/lib/python3.10/site-packages/django/core/handlers/base.py", line 197, in _get_response
    response = wrapped_callback(request, *callback_args, **callback_kwargs)
  File "/home/suraj/.local/lib/python3.10/site-packages/django/views/decorators/csrf.py", line 56, in wrapper_view
    return view_func(*args, **kwargs)
  File "/home/suraj/.local/lib/python3.10/site-packages/rest_framework/viewsets.py", line 125, in view
    return self.dispatch(request, *args, **kwargs)
  File "/home/suraj/.local/lib/python3.10/site-packages/rest_framework/views.py", line 509, in dispatch
    response = self.handle_exception(exc)
  File "/home/suraj/.local/lib/python3.10/site-packages/rest_framework/views.py", line 469, in handle_exception
    self.raise_uncaught_exception(exc)
  File "/home/suraj/.local/lib/python3.10/site-packages/rest_framework/views.py", line 480, in raise_uncaught_exception
    raise exc
  File "/home/suraj/.local/lib/python3.10/site-packages/rest_framework/views.py", line 506, in dispatch
    response = handler(request, *args, **kwargs)
  File "/home/suraj/Desktop/Python/JobBackend/JobPortalBackend/common/permissions.py", line 72, in decorated_func
    return func(self, *args, **kwargs)
  File "/home/suraj/Desktop/Python/JobBackend/JobPortalBackend/comments/api/viewsets/comments.py", line 116, in create
    super().create(request, *args, **kwargs)
  File "/home/suraj/.local/lib/python3.10/site-packages/rest_framework/mixins.py", line 18, in create
    serializer.is_valid(raise_exception=True)
  File "/home/suraj/Desktop/Python/JobBackend/JobPortalBackend/comments/api/serializers/comments.py", line 63, in is_valid
    parent = Comments.objects.filter(id=data.get("parent"))
  File "/home/suraj/.local/lib/python3.10/site-packages/django/db/models/manager.py", line 87, in manager_method
    return getattr(self.get_queryset(), name)(*args, **kwargs)
  File "/home/suraj/.local/lib/python3.10/site-packages/django/db/models/query.py", line 1436, in filter
    return self._filter_or_exclude(False, args, kwargs)
  File "/home/suraj/.local/lib/python3.10/site-packages/django/db/models/query.py", line 1454, in _filter_or_exclude
    clone._filter_or_exclude_inplace(negate, args, kwargs)
  File "/home/suraj/.local/lib/python3.10/site-packages/django/db/models/query.py", line 1461, in _filter_or_exclude_inplace
    self._query.add_q(Q(*args, **kwargs))
  File "/home/suraj/.local/lib/python3.10/site-packages/django/db/models/sql/query.py", line 1498, in add_q
    clause, _ = self._add_q(q_object, self.used_aliases)
  File "/home/suraj/.local/lib/python3.10/site-packages/django/db/models/sql/query.py", line 1529, in _add_q
    child_clause, needed_inner = self.build_filter(
  File "/home/suraj/.local/lib/python3.10/site-packages/django/db/models/sql/query.py", line 1444, in build_filter
    condition = self.build_lookup(lookups, col, value)
  File "/home/suraj/.local/lib/python3.10/site-packages/django/db/models/sql/query.py", line 1271, in build_lookup
    lookup = lookup_class(lhs, rhs)
  File "/home/suraj/.local/lib/python3.10/site-packages/django/db/models/lookups.py", line 27, in __init__
    self.rhs = self.get_prep_lookup()
  File "/home/suraj/.local/lib/python3.10/site-packages/django/db/models/lookups.py", line 341, in get_prep_lookup
    return super().get_prep_lookup()
  File "/home/suraj/.local/lib/python3.10/site-packages/django/db/models/lookups.py", line 85, in get_prep_lookup
    return self.lhs.output_field.get_prep_value(self.rhs)
  File "/home/suraj/.local/lib/python3.10/site-packages/django/db/models/fields/__init__.py", line 2674, in get_prep_value
    return self.to_python(value)
  File "/home/suraj/.local/lib/python3.10/site-packages/django/db/models/fields/__init__.py", line 2692, in to_python
    raise exceptions.ValidationError(
django.core.exceptions.ValidationError: ['“” is not a valid UUID.']
2023-06-15 11:03:26 ERROR django.server "POST /api/v1/comments/job-comment/ HTTP/1.1" 500 23484
2023-06-15 11:04:31 ERROR django.request Internal Server Error: /api/v1/comments/job-comment/
Traceback (most recent call last):
  File "/home/suraj/.local/lib/python3.10/site-packages/django/db/models/fields/__init__.py", line 2690, in to_python
    return uuid.UUID(**{input_form: value})
  File "/usr/lib/python3.10/uuid.py", line 177, in __init__
    raise ValueError('badly formed hexadecimal UUID string')
ValueError: badly formed hexadecimal UUID string

During handling of the above exception, another exception occurred:

Traceback (most recent call last):
  File "/home/suraj/.local/lib/python3.10/site-packages/django/core/handlers/exception.py", line 55, in inner
    response = get_response(request)
  File "/home/suraj/.local/lib/python3.10/site-packages/django/core/handlers/base.py", line 197, in _get_response
    response = wrapped_callback(request, *callback_args, **callback_kwargs)
  File "/home/suraj/.local/lib/python3.10/site-packages/django/views/decorators/csrf.py", line 56, in wrapper_view
    return view_func(*args, **kwargs)
  File "/home/suraj/.local/lib/python3.10/site-packages/rest_framework/viewsets.py", line 125, in view
    return self.dispatch(request, *args, **kwargs)
  File "/home/suraj/.local/lib/python3.10/site-packages/rest_framework/views.py", line 509, in dispatch
    response = self.handle_exception(exc)
  File "/home/suraj/.local/lib/python3.10/site-packages/rest_framework/views.py", line 469, in handle_exception
    self.raise_uncaught_exception(exc)
  File "/home/suraj/.local/lib/python3.10/site-packages/rest_framework/views.py", line 480, in raise_uncaught_exception
    raise exc
  File "/home/suraj/.local/lib/python3.10/site-packages/rest_framework/views.py", line 506, in dispatch
    response = handler(request, *args, **kwargs)
  File "/home/suraj/Desktop/Python/JobBackend/JobPortalBackend/common/permissions.py", line 72, in decorated_func
    return func(self, *args, **kwargs)
  File "/home/suraj/Desktop/Python/JobBackend/JobPortalBackend/comments/api/viewsets/comments.py", line 116, in create
    super().create(request, *args, **kwargs)
  File "/home/suraj/.local/lib/python3.10/site-packages/rest_framework/mixins.py", line 18, in create
    serializer.is_valid(raise_exception=True)
  File "/home/suraj/Desktop/Python/JobBackend/JobPortalBackend/comments/api/serializers/comments.py", line 64, in is_valid
    parent = Comments.objects.filter(id=data.get("parent"))
  File "/home/suraj/.local/lib/python3.10/site-packages/django/db/models/manager.py", line 87, in manager_method
    return getattr(self.get_queryset(), name)(*args, **kwargs)
  File "/home/suraj/.local/lib/python3.10/site-packages/django/db/models/query.py", line 1436, in filter
    return self._filter_or_exclude(False, args, kwargs)
  File "/home/suraj/.local/lib/python3.10/site-packages/django/db/models/query.py", line 1454, in _filter_or_exclude
    clone._filter_or_exclude_inplace(negate, args, kwargs)
  File "/home/suraj/.local/lib/python3.10/site-packages/django/db/models/query.py", line 1461, in _filter_or_exclude_inplace
    self._query.add_q(Q(*args, **kwargs))
  File "/home/suraj/.local/lib/python3.10/site-packages/django/db/models/sql/query.py", line 1498, in add_q
    clause, _ = self._add_q(q_object, self.used_aliases)
  File "/home/suraj/.local/lib/python3.10/site-packages/django/db/models/sql/query.py", line 1529, in _add_q
    child_clause, needed_inner = self.build_filter(
  File "/home/suraj/.local/lib/python3.10/site-packages/django/db/models/sql/query.py", line 1444, in build_filter
    condition = self.build_lookup(lookups, col, value)
  File "/home/suraj/.local/lib/python3.10/site-packages/django/db/models/sql/query.py", line 1271, in build_lookup
    lookup = lookup_class(lhs, rhs)
  File "/home/suraj/.local/lib/python3.10/site-packages/django/db/models/lookups.py", line 27, in __init__
    self.rhs = self.get_prep_lookup()
  File "/home/suraj/.local/lib/python3.10/site-packages/django/db/models/lookups.py", line 341, in get_prep_lookup
    return super().get_prep_lookup()
  File "/home/suraj/.local/lib/python3.10/site-packages/django/db/models/lookups.py", line 85, in get_prep_lookup
    return self.lhs.output_field.get_prep_value(self.rhs)
  File "/home/suraj/.local/lib/python3.10/site-packages/django/db/models/fields/__init__.py", line 2674, in get_prep_value
    return self.to_python(value)
  File "/home/suraj/.local/lib/python3.10/site-packages/django/db/models/fields/__init__.py", line 2692, in to_python
    raise exceptions.ValidationError(
django.core.exceptions.ValidationError: ['“” is not a valid UUID.']
2023-06-15 11:04:31 ERROR django.server "POST /api/v1/comments/job-comment/ HTTP/1.1" 500 23484
2023-06-15 11:05:30 ERROR django.request Internal Server Error: /api/v1/comments/job-comment/
Traceback (most recent call last):
  File "/home/suraj/.local/lib/python3.10/site-packages/django/db/models/fields/__init__.py", line 2690, in to_python
    return uuid.UUID(**{input_form: value})
  File "/usr/lib/python3.10/uuid.py", line 177, in __init__
    raise ValueError('badly formed hexadecimal UUID string')
ValueError: badly formed hexadecimal UUID string

During handling of the above exception, another exception occurred:

Traceback (most recent call last):
  File "/home/suraj/.local/lib/python3.10/site-packages/django/core/handlers/exception.py", line 55, in inner
    response = get_response(request)
  File "/home/suraj/.local/lib/python3.10/site-packages/django/core/handlers/base.py", line 197, in _get_response
    response = wrapped_callback(request, *callback_args, **callback_kwargs)
  File "/home/suraj/.local/lib/python3.10/site-packages/django/views/decorators/csrf.py", line 56, in wrapper_view
    return view_func(*args, **kwargs)
  File "/home/suraj/.local/lib/python3.10/site-packages/rest_framework/viewsets.py", line 125, in view
    return self.dispatch(request, *args, **kwargs)
  File "/home/suraj/.local/lib/python3.10/site-packages/rest_framework/views.py", line 509, in dispatch
    response = self.handle_exception(exc)
  File "/home/suraj/.local/lib/python3.10/site-packages/rest_framework/views.py", line 469, in handle_exception
    self.raise_uncaught_exception(exc)
  File "/home/suraj/.local/lib/python3.10/site-packages/rest_framework/views.py", line 480, in raise_uncaught_exception
    raise exc
  File "/home/suraj/.local/lib/python3.10/site-packages/rest_framework/views.py", line 506, in dispatch
    response = handler(request, *args, **kwargs)
  File "/home/suraj/Desktop/Python/JobBackend/JobPortalBackend/common/permissions.py", line 72, in decorated_func
    return func(self, *args, **kwargs)
  File "/home/suraj/Desktop/Python/JobBackend/JobPortalBackend/comments/api/viewsets/comments.py", line 116, in create
    response = super().create(request, *args, **kwargs)
  File "/home/suraj/.local/lib/python3.10/site-packages/rest_framework/mixins.py", line 18, in create
    serializer.is_valid(raise_exception=True)
  File "/home/suraj/Desktop/Python/JobBackend/JobPortalBackend/comments/api/serializers/comments.py", line 64, in is_valid
    parent = Comments.objects.filter(id=data.get("parent"))
  File "/home/suraj/.local/lib/python3.10/site-packages/django/db/models/manager.py", line 87, in manager_method
    return getattr(self.get_queryset(), name)(*args, **kwargs)
  File "/home/suraj/.local/lib/python3.10/site-packages/django/db/models/query.py", line 1436, in filter
    return self._filter_or_exclude(False, args, kwargs)
  File "/home/suraj/.local/lib/python3.10/site-packages/django/db/models/query.py", line 1454, in _filter_or_exclude
    clone._filter_or_exclude_inplace(negate, args, kwargs)
  File "/home/suraj/.local/lib/python3.10/site-packages/django/db/models/query.py", line 1461, in _filter_or_exclude_inplace
    self._query.add_q(Q(*args, **kwargs))
  File "/home/suraj/.local/lib/python3.10/site-packages/django/db/models/sql/query.py", line 1498, in add_q
    clause, _ = self._add_q(q_object, self.used_aliases)
  File "/home/suraj/.local/lib/python3.10/site-packages/django/db/models/sql/query.py", line 1529, in _add_q
    child_clause, needed_inner = self.build_filter(
  File "/home/suraj/.local/lib/python3.10/site-packages/django/db/models/sql/query.py", line 1444, in build_filter
    condition = self.build_lookup(lookups, col, value)
  File "/home/suraj/.local/lib/python3.10/site-packages/django/db/models/sql/query.py", line 1271, in build_lookup
    lookup = lookup_class(lhs, rhs)
  File "/home/suraj/.local/lib/python3.10/site-packages/django/db/models/lookups.py", line 27, in __init__
    self.rhs = self.get_prep_lookup()
  File "/home/suraj/.local/lib/python3.10/site-packages/django/db/models/lookups.py", line 341, in get_prep_lookup
    return super().get_prep_lookup()
  File "/home/suraj/.local/lib/python3.10/site-packages/django/db/models/lookups.py", line 85, in get_prep_lookup
    return self.lhs.output_field.get_prep_value(self.rhs)
  File "/home/suraj/.local/lib/python3.10/site-packages/django/db/models/fields/__init__.py", line 2674, in get_prep_value
    return self.to_python(value)
  File "/home/suraj/.local/lib/python3.10/site-packages/django/db/models/fields/__init__.py", line 2692, in to_python
    raise exceptions.ValidationError(
django.core.exceptions.ValidationError: ['“” is not a valid UUID.']
2023-06-15 11:05:30 ERROR django.server "POST /api/v1/comments/job-comment/ HTTP/1.1" 500 23495
2023-06-15 11:05:36 WARNING django.request Bad Request: /api/v1/comments/job-comment/
2023-06-15 11:05:36 WARNING django.server "POST /api/v1/comments/job-comment/ HTTP/1.1" 400 54
2023-06-15 11:06:38 WARNING django.request Bad Request: /api/v1/comments/job-comment/
2023-06-15 11:06:38 WARNING django.server "POST /api/v1/comments/job-comment/ HTTP/1.1" 400 54
2023-06-15 11:07:10 WARNING django.request Bad Request: /api/v1/comments/job-comment/
2023-06-15 11:07:10 WARNING django.server "POST /api/v1/comments/job-comment/ HTTP/1.1" 400 54
2023-06-15 11:08:20 WARNING django.request Bad Request: /api/v1/comments/job-comment/
2023-06-15 11:08:20 WARNING django.server "POST /api/v1/comments/job-comment/ HTTP/1.1" 400 74
2023-06-15 11:30:32 ERROR django.request Internal Server Error: /api/v1/comments/job-comment/e0982ca6-8217-4a7e-a154-5eb397acff08/
Traceback (most recent call last):
  File "/home/suraj/.local/lib/python3.10/site-packages/django/core/handlers/exception.py", line 55, in inner
    response = get_response(request)
  File "/home/suraj/.local/lib/python3.10/site-packages/django/core/handlers/base.py", line 197, in _get_response
    response = wrapped_callback(request, *callback_args, **callback_kwargs)
  File "/home/suraj/.local/lib/python3.10/site-packages/django/views/decorators/csrf.py", line 56, in wrapper_view
    return view_func(*args, **kwargs)
  File "/home/suraj/.local/lib/python3.10/site-packages/rest_framework/viewsets.py", line 125, in view
    return self.dispatch(request, *args, **kwargs)
  File "/home/suraj/.local/lib/python3.10/site-packages/rest_framework/views.py", line 509, in dispatch
    response = self.handle_exception(exc)
  File "/home/suraj/.local/lib/python3.10/site-packages/rest_framework/views.py", line 469, in handle_exception
    self.raise_uncaught_exception(exc)
  File "/home/suraj/.local/lib/python3.10/site-packages/rest_framework/views.py", line 480, in raise_uncaught_exception
    raise exc
  File "/home/suraj/.local/lib/python3.10/site-packages/rest_framework/views.py", line 506, in dispatch
    response = handler(request, *args, **kwargs)
  File "/home/suraj/Desktop/Python/JobBackend/JobPortalBackend/common/permissions.py", line 72, in decorated_func
    return func(self, *args, **kwargs)
  File "/home/suraj/Desktop/Python/JobBackend/JobPortalBackend/comments/api/viewsets/comments.py", line 176, in destroy
    if request.user.role == "U":
AttributeError: 'User' object has no attribute 'role'
2023-06-15 11:30:32 ERROR django.server "DELETE /api/v1/comments/job-comment/e0982ca6-8217-4a7e-a154-5eb397acff08/ HTTP/1.1" 500 20797
