2023-05-28 05:12:22 WARNING django.request Not Found: /
2023-05-28 05:12:22 WARNING django.server "GET / HTTP/1.1" 404 2425
2023-05-28 05:12:22 WARNING django.request Not Found: /favicon.ico
2023-05-28 05:12:22 WARNING django.server "GET /favicon.ico HTTP/1.1" 404 2476
2023-05-28 06:21:57 ERROR django.request Internal Server Error: /api/v1/payment/verify-payment/
Traceback (most recent call last):
  File "/home/suraj/.local/lib/python3.10/site-packages/django/db/models/fields/__init__.py", line 2055, in get_prep_value
    return int(value)
  File "/home/suraj/.local/lib/python3.10/site-packages/django/contrib/auth/models.py", line 437, in __int__
    raise TypeError(
TypeError: Cannot cast AnonymousUser to int. Are you trying to use it in place of User?

The above exception was the direct cause of the following exception:

Traceback (most recent call last):
  File "/home/suraj/.local/lib/python3.10/site-packages/django/core/handlers/exception.py", line 55, in inner
    response = get_response(request)
  File "/home/suraj/.local/lib/python3.10/site-packages/django/core/handlers/base.py", line 197, in _get_response
    response = wrapped_callback(request, *callback_args, **callback_kwargs)
  File "/home/suraj/.local/lib/python3.10/site-packages/django/views/decorators/csrf.py", line 56, in wrapper_view
    return view_func(*args, **kwargs)
  File "/home/suraj/.local/lib/python3.10/site-packages/django/views/generic/base.py", line 104, in view
    return self.dispatch(request, *args, **kwargs)
  File "/home/suraj/.local/lib/python3.10/site-packages/rest_framework/views.py", line 509, in dispatch
    response = self.handle_exception(exc)
  File "/home/suraj/.local/lib/python3.10/site-packages/rest_framework/views.py", line 469, in handle_exception
    self.raise_uncaught_exception(exc)
  File "/home/suraj/.local/lib/python3.10/site-packages/rest_framework/views.py", line 480, in raise_uncaught_exception
    raise exc
  File "/home/suraj/.local/lib/python3.10/site-packages/rest_framework/views.py", line 506, in dispatch
    response = handler(request, *args, **kwargs)
  File "/home/suraj/.local/lib/python3.10/site-packages/drf_spectacular/drainage.py", line 193, in wrapped_method
    return method(self, request, *args, **kwargs)
  File "/home/suraj/.local/lib/python3.10/site-packages/rest_framework/generics.py", line 190, in post
    return self.create(request, *args, **kwargs)
  File "/home/suraj/Desktop/Python/JobBackend/JobPortalBackend/payment/api/viewsets/payment.py", line 69, in create
    response = super().create(request, *args, **kwargs)
  File "/home/suraj/.local/lib/python3.10/site-packages/rest_framework/mixins.py", line 19, in create
    self.perform_create(serializer)
  File "/home/suraj/.local/lib/python3.10/site-packages/rest_framework/mixins.py", line 24, in perform_create
    serializer.save()
  File "/home/suraj/.local/lib/python3.10/site-packages/rest_framework/serializers.py", line 212, in save
    self.instance = self.create(validated_data)
  File "/home/suraj/Desktop/Python/JobBackend/JobPortalBackend/payment/api/serializers/payment.py", line 73, in create
    pay = Payment.objects.filter(
  File "/home/suraj/.local/lib/python3.10/site-packages/django/db/models/manager.py", line 87, in manager_method
    return getattr(self.get_queryset(), name)(*args, **kwargs)
  File "/home/suraj/.local/lib/python3.10/site-packages/django/db/models/query.py", line 1436, in filter
    return self._filter_or_exclude(False, args, kwargs)
  File "/home/suraj/.local/lib/python3.10/site-packages/django/db/models/query.py", line 1454, in _filter_or_exclude
    clone._filter_or_exclude_inplace(negate, args, kwargs)
  File "/home/suraj/.local/lib/python3.10/site-packages/django/db/models/query.py", line 1461, in _filter_or_exclude_inplace
    self._query.add_q(Q(*args, **kwargs))
  File "/home/suraj/.local/lib/python3.10/site-packages/django/db/models/sql/query.py", line 1498, in add_q
    clause, _ = self._add_q(q_object, self.used_aliases)
  File "/home/suraj/.local/lib/python3.10/site-packages/django/db/models/sql/query.py", line 1529, in _add_q
    child_clause, needed_inner = self.build_filter(
  File "/home/suraj/.local/lib/python3.10/site-packages/django/db/models/sql/query.py", line 1444, in build_filter
    condition = self.build_lookup(lookups, col, value)
  File "/home/suraj/.local/lib/python3.10/site-packages/django/db/models/sql/query.py", line 1271, in build_lookup
    lookup = lookup_class(lhs, rhs)
  File "/home/suraj/.local/lib/python3.10/site-packages/django/db/models/lookups.py", line 27, in __init__
    self.rhs = self.get_prep_lookup()
  File "/home/suraj/.local/lib/python3.10/site-packages/django/db/models/fields/related_lookups.py", line 166, in get_prep_lookup
    self.rhs = target_field.get_prep_value(self.rhs)
  File "/home/suraj/.local/lib/python3.10/site-packages/django/db/models/fields/__init__.py", line 2057, in get_prep_value
    raise e.__class__(
TypeError: Field 'id' expected a number but got <django.contrib.auth.models.AnonymousUser object at 0x7f480ddcd360>.
2023-05-28 06:21:57 ERROR django.server "POST /api/v1/payment/verify-payment/ HTTP/1.1" 500 189363
2023-05-28 06:22:13 ERROR django.request Internal Server Error: /api/v1/payment/verify-payment/
Traceback (most recent call last):
  File "/home/suraj/.local/lib/python3.10/site-packages/django/db/models/fields/__init__.py", line 2055, in get_prep_value
    return int(value)
  File "/home/suraj/.local/lib/python3.10/site-packages/django/contrib/auth/models.py", line 437, in __int__
    raise TypeError(
TypeError: Cannot cast AnonymousUser to int. Are you trying to use it in place of User?

The above exception was the direct cause of the following exception:

Traceback (most recent call last):
  File "/home/suraj/.local/lib/python3.10/site-packages/django/core/handlers/exception.py", line 55, in inner
    response = get_response(request)
  File "/home/suraj/.local/lib/python3.10/site-packages/django/core/handlers/base.py", line 197, in _get_response
    response = wrapped_callback(request, *callback_args, **callback_kwargs)
  File "/home/suraj/.local/lib/python3.10/site-packages/django/views/decorators/csrf.py", line 56, in wrapper_view
    return view_func(*args, **kwargs)
  File "/home/suraj/.local/lib/python3.10/site-packages/django/views/generic/base.py", line 104, in view
    return self.dispatch(request, *args, **kwargs)
  File "/home/suraj/.local/lib/python3.10/site-packages/rest_framework/views.py", line 509, in dispatch
    response = self.handle_exception(exc)
  File "/home/suraj/.local/lib/python3.10/site-packages/rest_framework/views.py", line 469, in handle_exception
    self.raise_uncaught_exception(exc)
  File "/home/suraj/.local/lib/python3.10/site-packages/rest_framework/views.py", line 480, in raise_uncaught_exception
    raise exc
  File "/home/suraj/.local/lib/python3.10/site-packages/rest_framework/views.py", line 506, in dispatch
    response = handler(request, *args, **kwargs)
  File "/home/suraj/.local/lib/python3.10/site-packages/drf_spectacular/drainage.py", line 193, in wrapped_method
    return method(self, request, *args, **kwargs)
  File "/home/suraj/.local/lib/python3.10/site-packages/rest_framework/generics.py", line 190, in post
    return self.create(request, *args, **kwargs)
  File "/home/suraj/Desktop/Python/JobBackend/JobPortalBackend/payment/api/viewsets/payment.py", line 69, in create
    response = super().create(request, *args, **kwargs)
  File "/home/suraj/.local/lib/python3.10/site-packages/rest_framework/mixins.py", line 19, in create
    self.perform_create(serializer)
  File "/home/suraj/.local/lib/python3.10/site-packages/rest_framework/mixins.py", line 24, in perform_create
    serializer.save()
  File "/home/suraj/.local/lib/python3.10/site-packages/rest_framework/serializers.py", line 212, in save
    self.instance = self.create(validated_data)
  File "/home/suraj/Desktop/Python/JobBackend/JobPortalBackend/payment/api/serializers/payment.py", line 73, in create
    pay = Payment.objects.filter(
  File "/home/suraj/.local/lib/python3.10/site-packages/django/db/models/manager.py", line 87, in manager_method
    return getattr(self.get_queryset(), name)(*args, **kwargs)
  File "/home/suraj/.local/lib/python3.10/site-packages/django/db/models/query.py", line 1436, in filter
    return self._filter_or_exclude(False, args, kwargs)
  File "/home/suraj/.local/lib/python3.10/site-packages/django/db/models/query.py", line 1454, in _filter_or_exclude
    clone._filter_or_exclude_inplace(negate, args, kwargs)
  File "/home/suraj/.local/lib/python3.10/site-packages/django/db/models/query.py", line 1461, in _filter_or_exclude_inplace
    self._query.add_q(Q(*args, **kwargs))
  File "/home/suraj/.local/lib/python3.10/site-packages/django/db/models/sql/query.py", line 1498, in add_q
    clause, _ = self._add_q(q_object, self.used_aliases)
  File "/home/suraj/.local/lib/python3.10/site-packages/django/db/models/sql/query.py", line 1529, in _add_q
    child_clause, needed_inner = self.build_filter(
  File "/home/suraj/.local/lib/python3.10/site-packages/django/db/models/sql/query.py", line 1444, in build_filter
    condition = self.build_lookup(lookups, col, value)
  File "/home/suraj/.local/lib/python3.10/site-packages/django/db/models/sql/query.py", line 1271, in build_lookup
    lookup = lookup_class(lhs, rhs)
  File "/home/suraj/.local/lib/python3.10/site-packages/django/db/models/lookups.py", line 27, in __init__
    self.rhs = self.get_prep_lookup()
  File "/home/suraj/.local/lib/python3.10/site-packages/django/db/models/fields/related_lookups.py", line 166, in get_prep_lookup
    self.rhs = target_field.get_prep_value(self.rhs)
  File "/home/suraj/.local/lib/python3.10/site-packages/django/db/models/fields/__init__.py", line 2057, in get_prep_value
    raise e.__class__(
TypeError: Field 'id' expected a number but got <django.contrib.auth.models.AnonymousUser object at 0x7f480ddcd0c0>.
2023-05-28 06:22:13 ERROR django.server "POST /api/v1/payment/verify-payment/ HTTP/1.1" 500 189363
2023-05-28 06:22:33 ERROR django.request Internal Server Error: /api/v1/payment/verify-payment/
Traceback (most recent call last):
  File "/home/suraj/.local/lib/python3.10/site-packages/django/db/models/fields/__init__.py", line 2055, in get_prep_value
    return int(value)
  File "/home/suraj/.local/lib/python3.10/site-packages/django/contrib/auth/models.py", line 437, in __int__
    raise TypeError(
TypeError: Cannot cast AnonymousUser to int. Are you trying to use it in place of User?

The above exception was the direct cause of the following exception:

Traceback (most recent call last):
  File "/home/suraj/.local/lib/python3.10/site-packages/django/core/handlers/exception.py", line 55, in inner
    response = get_response(request)
  File "/home/suraj/.local/lib/python3.10/site-packages/django/core/handlers/base.py", line 197, in _get_response
    response = wrapped_callback(request, *callback_args, **callback_kwargs)
  File "/home/suraj/.local/lib/python3.10/site-packages/django/views/decorators/csrf.py", line 56, in wrapper_view
    return view_func(*args, **kwargs)
  File "/home/suraj/.local/lib/python3.10/site-packages/django/views/generic/base.py", line 104, in view
    return self.dispatch(request, *args, **kwargs)
  File "/home/suraj/.local/lib/python3.10/site-packages/rest_framework/views.py", line 509, in dispatch
    response = self.handle_exception(exc)
  File "/home/suraj/.local/lib/python3.10/site-packages/rest_framework/views.py", line 469, in handle_exception
    self.raise_uncaught_exception(exc)
  File "/home/suraj/.local/lib/python3.10/site-packages/rest_framework/views.py", line 480, in raise_uncaught_exception
    raise exc
  File "/home/suraj/.local/lib/python3.10/site-packages/rest_framework/views.py", line 506, in dispatch
    response = handler(request, *args, **kwargs)
  File "/home/suraj/.local/lib/python3.10/site-packages/drf_spectacular/drainage.py", line 193, in wrapped_method
    return method(self, request, *args, **kwargs)
  File "/home/suraj/.local/lib/python3.10/site-packages/rest_framework/generics.py", line 190, in post
    return self.create(request, *args, **kwargs)
  File "/home/suraj/Desktop/Python/JobBackend/JobPortalBackend/payment/api/viewsets/payment.py", line 69, in create
    response = super().create(request, *args, **kwargs)
  File "/home/suraj/.local/lib/python3.10/site-packages/rest_framework/mixins.py", line 19, in create
    self.perform_create(serializer)
  File "/home/suraj/.local/lib/python3.10/site-packages/rest_framework/mixins.py", line 24, in perform_create
    serializer.save()
  File "/home/suraj/.local/lib/python3.10/site-packages/rest_framework/serializers.py", line 212, in save
    self.instance = self.create(validated_data)
  File "/home/suraj/Desktop/Python/JobBackend/JobPortalBackend/payment/api/serializers/payment.py", line 73, in create
    pay = Payment.objects.filter(
  File "/home/suraj/.local/lib/python3.10/site-packages/django/db/models/manager.py", line 87, in manager_method
    return getattr(self.get_queryset(), name)(*args, **kwargs)
  File "/home/suraj/.local/lib/python3.10/site-packages/django/db/models/query.py", line 1436, in filter
    return self._filter_or_exclude(False, args, kwargs)
  File "/home/suraj/.local/lib/python3.10/site-packages/django/db/models/query.py", line 1454, in _filter_or_exclude
    clone._filter_or_exclude_inplace(negate, args, kwargs)
  File "/home/suraj/.local/lib/python3.10/site-packages/django/db/models/query.py", line 1461, in _filter_or_exclude_inplace
    self._query.add_q(Q(*args, **kwargs))
  File "/home/suraj/.local/lib/python3.10/site-packages/django/db/models/sql/query.py", line 1498, in add_q
    clause, _ = self._add_q(q_object, self.used_aliases)
  File "/home/suraj/.local/lib/python3.10/site-packages/django/db/models/sql/query.py", line 1529, in _add_q
    child_clause, needed_inner = self.build_filter(
  File "/home/suraj/.local/lib/python3.10/site-packages/django/db/models/sql/query.py", line 1444, in build_filter
    condition = self.build_lookup(lookups, col, value)
  File "/home/suraj/.local/lib/python3.10/site-packages/django/db/models/sql/query.py", line 1271, in build_lookup
    lookup = lookup_class(lhs, rhs)
  File "/home/suraj/.local/lib/python3.10/site-packages/django/db/models/lookups.py", line 27, in __init__
    self.rhs = self.get_prep_lookup()
  File "/home/suraj/.local/lib/python3.10/site-packages/django/db/models/fields/related_lookups.py", line 166, in get_prep_lookup
    self.rhs = target_field.get_prep_value(self.rhs)
  File "/home/suraj/.local/lib/python3.10/site-packages/django/db/models/fields/__init__.py", line 2057, in get_prep_value
    raise e.__class__(
TypeError: Field 'id' expected a number but got <django.contrib.auth.models.AnonymousUser object at 0x7f480c56a5c0>.
2023-05-28 06:22:33 ERROR django.server "POST /api/v1/payment/verify-payment/ HTTP/1.1" 500 189363
2023-05-28 06:23:01 ERROR django.request Internal Server Error: /api/v1/payment/verify-payment/
Traceback (most recent call last):
  File "/home/suraj/.local/lib/python3.10/site-packages/django/db/models/fields/__init__.py", line 2055, in get_prep_value
    return int(value)
  File "/home/suraj/.local/lib/python3.10/site-packages/django/contrib/auth/models.py", line 437, in __int__
    raise TypeError(
TypeError: Cannot cast AnonymousUser to int. Are you trying to use it in place of User?

The above exception was the direct cause of the following exception:

Traceback (most recent call last):
  File "/home/suraj/.local/lib/python3.10/site-packages/django/core/handlers/exception.py", line 55, in inner
    response = get_response(request)
  File "/home/suraj/.local/lib/python3.10/site-packages/django/core/handlers/base.py", line 197, in _get_response
    response = wrapped_callback(request, *callback_args, **callback_kwargs)
  File "/home/suraj/.local/lib/python3.10/site-packages/django/views/decorators/csrf.py", line 56, in wrapper_view
    return view_func(*args, **kwargs)
  File "/home/suraj/.local/lib/python3.10/site-packages/django/views/generic/base.py", line 104, in view
    return self.dispatch(request, *args, **kwargs)
  File "/home/suraj/.local/lib/python3.10/site-packages/rest_framework/views.py", line 509, in dispatch
    response = self.handle_exception(exc)
  File "/home/suraj/.local/lib/python3.10/site-packages/rest_framework/views.py", line 469, in handle_exception
    self.raise_uncaught_exception(exc)
  File "/home/suraj/.local/lib/python3.10/site-packages/rest_framework/views.py", line 480, in raise_uncaught_exception
    raise exc
  File "/home/suraj/.local/lib/python3.10/site-packages/rest_framework/views.py", line 506, in dispatch
    response = handler(request, *args, **kwargs)
  File "/home/suraj/.local/lib/python3.10/site-packages/drf_spectacular/drainage.py", line 193, in wrapped_method
    return method(self, request, *args, **kwargs)
  File "/home/suraj/.local/lib/python3.10/site-packages/rest_framework/generics.py", line 190, in post
    return self.create(request, *args, **kwargs)
  File "/home/suraj/Desktop/Python/JobBackend/JobPortalBackend/payment/api/viewsets/payment.py", line 69, in create
    response = super().create(request, *args, **kwargs)
  File "/home/suraj/.local/lib/python3.10/site-packages/rest_framework/mixins.py", line 19, in create
    self.perform_create(serializer)
  File "/home/suraj/.local/lib/python3.10/site-packages/rest_framework/mixins.py", line 24, in perform_create
    serializer.save()
  File "/home/suraj/.local/lib/python3.10/site-packages/rest_framework/serializers.py", line 212, in save
    self.instance = self.create(validated_data)
  File "/home/suraj/Desktop/Python/JobBackend/JobPortalBackend/payment/api/serializers/payment.py", line 73, in create
    pay = Payment.objects.filter(
  File "/home/suraj/.local/lib/python3.10/site-packages/django/db/models/manager.py", line 87, in manager_method
    return getattr(self.get_queryset(), name)(*args, **kwargs)
  File "/home/suraj/.local/lib/python3.10/site-packages/django/db/models/query.py", line 1436, in filter
    return self._filter_or_exclude(False, args, kwargs)
  File "/home/suraj/.local/lib/python3.10/site-packages/django/db/models/query.py", line 1454, in _filter_or_exclude
    clone._filter_or_exclude_inplace(negate, args, kwargs)
  File "/home/suraj/.local/lib/python3.10/site-packages/django/db/models/query.py", line 1461, in _filter_or_exclude_inplace
    self._query.add_q(Q(*args, **kwargs))
  File "/home/suraj/.local/lib/python3.10/site-packages/django/db/models/sql/query.py", line 1498, in add_q
    clause, _ = self._add_q(q_object, self.used_aliases)
  File "/home/suraj/.local/lib/python3.10/site-packages/django/db/models/sql/query.py", line 1529, in _add_q
    child_clause, needed_inner = self.build_filter(
  File "/home/suraj/.local/lib/python3.10/site-packages/django/db/models/sql/query.py", line 1444, in build_filter
    condition = self.build_lookup(lookups, col, value)
  File "/home/suraj/.local/lib/python3.10/site-packages/django/db/models/sql/query.py", line 1271, in build_lookup
    lookup = lookup_class(lhs, rhs)
  File "/home/suraj/.local/lib/python3.10/site-packages/django/db/models/lookups.py", line 27, in __init__
    self.rhs = self.get_prep_lookup()
  File "/home/suraj/.local/lib/python3.10/site-packages/django/db/models/fields/related_lookups.py", line 166, in get_prep_lookup
    self.rhs = target_field.get_prep_value(self.rhs)
  File "/home/suraj/.local/lib/python3.10/site-packages/django/db/models/fields/__init__.py", line 2057, in get_prep_value
    raise e.__class__(
TypeError: Field 'id' expected a number but got <django.contrib.auth.models.AnonymousUser object at 0x7f480c5af0a0>.
2023-05-28 06:23:01 ERROR django.server "POST /api/v1/payment/verify-payment/ HTTP/1.1" 500 189411
2023-05-28 06:23:18 WARNING django.request Bad Request: /api/v1/payment/verify-payment/
2023-05-28 06:23:18 WARNING django.server "POST /api/v1/payment/verify-payment/ HTTP/1.1" 400 75
2023-05-28 06:23:36 ERROR django.request Internal Server Error: /api/v1/payment/verify-payment/
Traceback (most recent call last):
  File "/home/suraj/.local/lib/python3.10/site-packages/django/db/models/fields/__init__.py", line 2055, in get_prep_value
    return int(value)
  File "/home/suraj/.local/lib/python3.10/site-packages/django/contrib/auth/models.py", line 437, in __int__
    raise TypeError(
TypeError: Cannot cast AnonymousUser to int. Are you trying to use it in place of User?

The above exception was the direct cause of the following exception:

Traceback (most recent call last):
  File "/home/suraj/.local/lib/python3.10/site-packages/django/core/handlers/exception.py", line 55, in inner
    response = get_response(request)
  File "/home/suraj/.local/lib/python3.10/site-packages/django/core/handlers/base.py", line 197, in _get_response
    response = wrapped_callback(request, *callback_args, **callback_kwargs)
  File "/home/suraj/.local/lib/python3.10/site-packages/django/views/decorators/csrf.py", line 56, in wrapper_view
    return view_func(*args, **kwargs)
  File "/home/suraj/.local/lib/python3.10/site-packages/django/views/generic/base.py", line 104, in view
    return self.dispatch(request, *args, **kwargs)
  File "/home/suraj/.local/lib/python3.10/site-packages/rest_framework/views.py", line 509, in dispatch
    response = self.handle_exception(exc)
  File "/home/suraj/.local/lib/python3.10/site-packages/rest_framework/views.py", line 469, in handle_exception
    self.raise_uncaught_exception(exc)
  File "/home/suraj/.local/lib/python3.10/site-packages/rest_framework/views.py", line 480, in raise_uncaught_exception
    raise exc
  File "/home/suraj/.local/lib/python3.10/site-packages/rest_framework/views.py", line 506, in dispatch
    response = handler(request, *args, **kwargs)
  File "/home/suraj/.local/lib/python3.10/site-packages/drf_spectacular/drainage.py", line 193, in wrapped_method
    return method(self, request, *args, **kwargs)
  File "/home/suraj/.local/lib/python3.10/site-packages/rest_framework/generics.py", line 190, in post
    return self.create(request, *args, **kwargs)
  File "/home/suraj/Desktop/Python/JobBackend/JobPortalBackend/payment/api/viewsets/payment.py", line 69, in create
    response = super().create(request, *args, **kwargs)
  File "/home/suraj/.local/lib/python3.10/site-packages/rest_framework/mixins.py", line 19, in create
    self.perform_create(serializer)
  File "/home/suraj/.local/lib/python3.10/site-packages/rest_framework/mixins.py", line 24, in perform_create
    serializer.save()
  File "/home/suraj/.local/lib/python3.10/site-packages/rest_framework/serializers.py", line 212, in save
    self.instance = self.create(validated_data)
  File "/home/suraj/Desktop/Python/JobBackend/JobPortalBackend/payment/api/serializers/payment.py", line 73, in create
    pay = Payment.objects.filter(
  File "/home/suraj/.local/lib/python3.10/site-packages/django/db/models/manager.py", line 87, in manager_method
    return getattr(self.get_queryset(), name)(*args, **kwargs)
  File "/home/suraj/.local/lib/python3.10/site-packages/django/db/models/query.py", line 1436, in filter
    return self._filter_or_exclude(False, args, kwargs)
  File "/home/suraj/.local/lib/python3.10/site-packages/django/db/models/query.py", line 1454, in _filter_or_exclude
    clone._filter_or_exclude_inplace(negate, args, kwargs)
  File "/home/suraj/.local/lib/python3.10/site-packages/django/db/models/query.py", line 1461, in _filter_or_exclude_inplace
    self._query.add_q(Q(*args, **kwargs))
  File "/home/suraj/.local/lib/python3.10/site-packages/django/db/models/sql/query.py", line 1498, in add_q
    clause, _ = self._add_q(q_object, self.used_aliases)
  File "/home/suraj/.local/lib/python3.10/site-packages/django/db/models/sql/query.py", line 1529, in _add_q
    child_clause, needed_inner = self.build_filter(
  File "/home/suraj/.local/lib/python3.10/site-packages/django/db/models/sql/query.py", line 1444, in build_filter
    condition = self.build_lookup(lookups, col, value)
  File "/home/suraj/.local/lib/python3.10/site-packages/django/db/models/sql/query.py", line 1271, in build_lookup
    lookup = lookup_class(lhs, rhs)
  File "/home/suraj/.local/lib/python3.10/site-packages/django/db/models/lookups.py", line 27, in __init__
    self.rhs = self.get_prep_lookup()
  File "/home/suraj/.local/lib/python3.10/site-packages/django/db/models/fields/related_lookups.py", line 166, in get_prep_lookup
    self.rhs = target_field.get_prep_value(self.rhs)
  File "/home/suraj/.local/lib/python3.10/site-packages/django/db/models/fields/__init__.py", line 2057, in get_prep_value
    raise e.__class__(
TypeError: Field 'id' expected a number but got <django.contrib.auth.models.AnonymousUser object at 0x7f480c568700>.
2023-05-28 06:23:36 ERROR django.server "POST /api/v1/payment/verify-payment/ HTTP/1.1" 500 189363
2023-05-28 06:24:59 ERROR django.request Internal Server Error: /api/v1/payment/verify-payment/
Traceback (most recent call last):
  File "/home/suraj/.local/lib/python3.10/site-packages/django/db/models/fields/__init__.py", line 2055, in get_prep_value
    return int(value)
  File "/home/suraj/.local/lib/python3.10/site-packages/django/contrib/auth/models.py", line 437, in __int__
    raise TypeError(
TypeError: Cannot cast AnonymousUser to int. Are you trying to use it in place of User?

The above exception was the direct cause of the following exception:

Traceback (most recent call last):
  File "/home/suraj/.local/lib/python3.10/site-packages/django/core/handlers/exception.py", line 55, in inner
    response = get_response(request)
  File "/home/suraj/.local/lib/python3.10/site-packages/django/core/handlers/base.py", line 197, in _get_response
    response = wrapped_callback(request, *callback_args, **callback_kwargs)
  File "/home/suraj/.local/lib/python3.10/site-packages/django/views/decorators/csrf.py", line 56, in wrapper_view
    return view_func(*args, **kwargs)
  File "/home/suraj/.local/lib/python3.10/site-packages/django/views/generic/base.py", line 104, in view
    return self.dispatch(request, *args, **kwargs)
  File "/home/suraj/.local/lib/python3.10/site-packages/rest_framework/views.py", line 509, in dispatch
    response = self.handle_exception(exc)
  File "/home/suraj/.local/lib/python3.10/site-packages/rest_framework/views.py", line 469, in handle_exception
    self.raise_uncaught_exception(exc)
  File "/home/suraj/.local/lib/python3.10/site-packages/rest_framework/views.py", line 480, in raise_uncaught_exception
    raise exc
  File "/home/suraj/.local/lib/python3.10/site-packages/rest_framework/views.py", line 506, in dispatch
    response = handler(request, *args, **kwargs)
  File "/home/suraj/.local/lib/python3.10/site-packages/drf_spectacular/drainage.py", line 193, in wrapped_method
    return method(self, request, *args, **kwargs)
  File "/home/suraj/.local/lib/python3.10/site-packages/rest_framework/generics.py", line 190, in post
    return self.create(request, *args, **kwargs)
  File "/home/suraj/Desktop/Python/JobBackend/JobPortalBackend/payment/api/viewsets/payment.py", line 69, in create
    response = super().create(request, *args, **kwargs)
  File "/home/suraj/.local/lib/python3.10/site-packages/rest_framework/mixins.py", line 19, in create
    self.perform_create(serializer)
  File "/home/suraj/.local/lib/python3.10/site-packages/rest_framework/mixins.py", line 24, in perform_create
    serializer.save()
  File "/home/suraj/.local/lib/python3.10/site-packages/rest_framework/serializers.py", line 212, in save
    self.instance = self.create(validated_data)
  File "/home/suraj/Desktop/Python/JobBackend/JobPortalBackend/payment/api/serializers/payment.py", line 74, in create
    pay = Payment.objects.filter(
  File "/home/suraj/.local/lib/python3.10/site-packages/django/db/models/manager.py", line 87, in manager_method
    return getattr(self.get_queryset(), name)(*args, **kwargs)
  File "/home/suraj/.local/lib/python3.10/site-packages/django/db/models/query.py", line 1436, in filter
    return self._filter_or_exclude(False, args, kwargs)
  File "/home/suraj/.local/lib/python3.10/site-packages/django/db/models/query.py", line 1454, in _filter_or_exclude
    clone._filter_or_exclude_inplace(negate, args, kwargs)
  File "/home/suraj/.local/lib/python3.10/site-packages/django/db/models/query.py", line 1461, in _filter_or_exclude_inplace
    self._query.add_q(Q(*args, **kwargs))
  File "/home/suraj/.local/lib/python3.10/site-packages/django/db/models/sql/query.py", line 1498, in add_q
    clause, _ = self._add_q(q_object, self.used_aliases)
  File "/home/suraj/.local/lib/python3.10/site-packages/django/db/models/sql/query.py", line 1529, in _add_q
    child_clause, needed_inner = self.build_filter(
  File "/home/suraj/.local/lib/python3.10/site-packages/django/db/models/sql/query.py", line 1444, in build_filter
    condition = self.build_lookup(lookups, col, value)
  File "/home/suraj/.local/lib/python3.10/site-packages/django/db/models/sql/query.py", line 1271, in build_lookup
    lookup = lookup_class(lhs, rhs)
  File "/home/suraj/.local/lib/python3.10/site-packages/django/db/models/lookups.py", line 27, in __init__
    self.rhs = self.get_prep_lookup()
  File "/home/suraj/.local/lib/python3.10/site-packages/django/db/models/fields/related_lookups.py", line 166, in get_prep_lookup
    self.rhs = target_field.get_prep_value(self.rhs)
  File "/home/suraj/.local/lib/python3.10/site-packages/django/db/models/fields/__init__.py", line 2057, in get_prep_value
    raise e.__class__(
TypeError: Field 'id' expected a number but got <django.contrib.auth.models.AnonymousUser object at 0x7fd85576a110>.
2023-05-28 06:24:59 ERROR django.server "POST /api/v1/payment/verify-payment/ HTTP/1.1" 500 189363
2023-05-28 06:25:04 ERROR django.request Internal Server Error: /api/v1/payment/verify-payment/
Traceback (most recent call last):
  File "/home/suraj/.local/lib/python3.10/site-packages/django/db/models/fields/__init__.py", line 2055, in get_prep_value
    return int(value)
  File "/home/suraj/.local/lib/python3.10/site-packages/django/contrib/auth/models.py", line 437, in __int__
    raise TypeError(
TypeError: Cannot cast AnonymousUser to int. Are you trying to use it in place of User?

The above exception was the direct cause of the following exception:

Traceback (most recent call last):
  File "/home/suraj/.local/lib/python3.10/site-packages/django/core/handlers/exception.py", line 55, in inner
    response = get_response(request)
  File "/home/suraj/.local/lib/python3.10/site-packages/django/core/handlers/base.py", line 197, in _get_response
    response = wrapped_callback(request, *callback_args, **callback_kwargs)
  File "/home/suraj/.local/lib/python3.10/site-packages/django/views/decorators/csrf.py", line 56, in wrapper_view
    return view_func(*args, **kwargs)
  File "/home/suraj/.local/lib/python3.10/site-packages/django/views/generic/base.py", line 104, in view
    return self.dispatch(request, *args, **kwargs)
  File "/home/suraj/.local/lib/python3.10/site-packages/rest_framework/views.py", line 509, in dispatch
    response = self.handle_exception(exc)
  File "/home/suraj/.local/lib/python3.10/site-packages/rest_framework/views.py", line 469, in handle_exception
    self.raise_uncaught_exception(exc)
  File "/home/suraj/.local/lib/python3.10/site-packages/rest_framework/views.py", line 480, in raise_uncaught_exception
    raise exc
  File "/home/suraj/.local/lib/python3.10/site-packages/rest_framework/views.py", line 506, in dispatch
    response = handler(request, *args, **kwargs)
  File "/home/suraj/.local/lib/python3.10/site-packages/drf_spectacular/drainage.py", line 193, in wrapped_method
    return method(self, request, *args, **kwargs)
  File "/home/suraj/.local/lib/python3.10/site-packages/rest_framework/generics.py", line 190, in post
    return self.create(request, *args, **kwargs)
  File "/home/suraj/Desktop/Python/JobBackend/JobPortalBackend/payment/api/viewsets/payment.py", line 69, in create
    response = super().create(request, *args, **kwargs)
  File "/home/suraj/.local/lib/python3.10/site-packages/rest_framework/mixins.py", line 19, in create
    self.perform_create(serializer)
  File "/home/suraj/.local/lib/python3.10/site-packages/rest_framework/mixins.py", line 24, in perform_create
    serializer.save()
  File "/home/suraj/.local/lib/python3.10/site-packages/rest_framework/serializers.py", line 212, in save
    self.instance = self.create(validated_data)
  File "/home/suraj/Desktop/Python/JobBackend/JobPortalBackend/payment/api/serializers/payment.py", line 74, in create
    pay = Payment.objects.filter(
  File "/home/suraj/.local/lib/python3.10/site-packages/django/db/models/manager.py", line 87, in manager_method
    return getattr(self.get_queryset(), name)(*args, **kwargs)
  File "/home/suraj/.local/lib/python3.10/site-packages/django/db/models/query.py", line 1436, in filter
    return self._filter_or_exclude(False, args, kwargs)
  File "/home/suraj/.local/lib/python3.10/site-packages/django/db/models/query.py", line 1454, in _filter_or_exclude
    clone._filter_or_exclude_inplace(negate, args, kwargs)
  File "/home/suraj/.local/lib/python3.10/site-packages/django/db/models/query.py", line 1461, in _filter_or_exclude_inplace
    self._query.add_q(Q(*args, **kwargs))
  File "/home/suraj/.local/lib/python3.10/site-packages/django/db/models/sql/query.py", line 1498, in add_q
    clause, _ = self._add_q(q_object, self.used_aliases)
  File "/home/suraj/.local/lib/python3.10/site-packages/django/db/models/sql/query.py", line 1529, in _add_q
    child_clause, needed_inner = self.build_filter(
  File "/home/suraj/.local/lib/python3.10/site-packages/django/db/models/sql/query.py", line 1444, in build_filter
    condition = self.build_lookup(lookups, col, value)
  File "/home/suraj/.local/lib/python3.10/site-packages/django/db/models/sql/query.py", line 1271, in build_lookup
    lookup = lookup_class(lhs, rhs)
  File "/home/suraj/.local/lib/python3.10/site-packages/django/db/models/lookups.py", line 27, in __init__
    self.rhs = self.get_prep_lookup()
  File "/home/suraj/.local/lib/python3.10/site-packages/django/db/models/fields/related_lookups.py", line 166, in get_prep_lookup
    self.rhs = target_field.get_prep_value(self.rhs)
  File "/home/suraj/.local/lib/python3.10/site-packages/django/db/models/fields/__init__.py", line 2057, in get_prep_value
    raise e.__class__(
TypeError: Field 'id' expected a number but got <django.contrib.auth.models.AnonymousUser object at 0x7fd854b48a60>.
2023-05-28 06:25:04 ERROR django.server "POST /api/v1/payment/verify-payment/ HTTP/1.1" 500 189363
2023-05-28 06:25:33 ERROR django.request Internal Server Error: /api/v1/payment/verify-payment/
Traceback (most recent call last):
  File "/home/suraj/.local/lib/python3.10/site-packages/django/db/models/fields/__init__.py", line 2055, in get_prep_value
    return int(value)
  File "/home/suraj/.local/lib/python3.10/site-packages/django/contrib/auth/models.py", line 437, in __int__
    raise TypeError(
TypeError: Cannot cast AnonymousUser to int. Are you trying to use it in place of User?

The above exception was the direct cause of the following exception:

Traceback (most recent call last):
  File "/home/suraj/.local/lib/python3.10/site-packages/django/core/handlers/exception.py", line 55, in inner
    response = get_response(request)
  File "/home/suraj/.local/lib/python3.10/site-packages/django/core/handlers/base.py", line 197, in _get_response
    response = wrapped_callback(request, *callback_args, **callback_kwargs)
  File "/home/suraj/.local/lib/python3.10/site-packages/django/views/decorators/csrf.py", line 56, in wrapper_view
    return view_func(*args, **kwargs)
  File "/home/suraj/.local/lib/python3.10/site-packages/django/views/generic/base.py", line 104, in view
    return self.dispatch(request, *args, **kwargs)
  File "/home/suraj/.local/lib/python3.10/site-packages/rest_framework/views.py", line 509, in dispatch
    response = self.handle_exception(exc)
  File "/home/suraj/.local/lib/python3.10/site-packages/rest_framework/views.py", line 469, in handle_exception
    self.raise_uncaught_exception(exc)
  File "/home/suraj/.local/lib/python3.10/site-packages/rest_framework/views.py", line 480, in raise_uncaught_exception
    raise exc
  File "/home/suraj/.local/lib/python3.10/site-packages/rest_framework/views.py", line 506, in dispatch
    response = handler(request, *args, **kwargs)
  File "/home/suraj/.local/lib/python3.10/site-packages/drf_spectacular/drainage.py", line 193, in wrapped_method
    return method(self, request, *args, **kwargs)
  File "/home/suraj/.local/lib/python3.10/site-packages/rest_framework/generics.py", line 190, in post
    return self.create(request, *args, **kwargs)
  File "/home/suraj/Desktop/Python/JobBackend/JobPortalBackend/payment/api/viewsets/payment.py", line 69, in create
    response = super().create(request, *args, **kwargs)
  File "/home/suraj/.local/lib/python3.10/site-packages/rest_framework/mixins.py", line 19, in create
    self.perform_create(serializer)
  File "/home/suraj/.local/lib/python3.10/site-packages/rest_framework/mixins.py", line 24, in perform_create
    serializer.save()
  File "/home/suraj/.local/lib/python3.10/site-packages/rest_framework/serializers.py", line 212, in save
    self.instance = self.create(validated_data)
  File "/home/suraj/Desktop/Python/JobBackend/JobPortalBackend/payment/api/serializers/payment.py", line 74, in create
    pay = Payment.objects.filter(
  File "/home/suraj/.local/lib/python3.10/site-packages/django/db/models/manager.py", line 87, in manager_method
    return getattr(self.get_queryset(), name)(*args, **kwargs)
  File "/home/suraj/.local/lib/python3.10/site-packages/django/db/models/query.py", line 1436, in filter
    return self._filter_or_exclude(False, args, kwargs)
  File "/home/suraj/.local/lib/python3.10/site-packages/django/db/models/query.py", line 1454, in _filter_or_exclude
    clone._filter_or_exclude_inplace(negate, args, kwargs)
  File "/home/suraj/.local/lib/python3.10/site-packages/django/db/models/query.py", line 1461, in _filter_or_exclude_inplace
    self._query.add_q(Q(*args, **kwargs))
  File "/home/suraj/.local/lib/python3.10/site-packages/django/db/models/sql/query.py", line 1498, in add_q
    clause, _ = self._add_q(q_object, self.used_aliases)
  File "/home/suraj/.local/lib/python3.10/site-packages/django/db/models/sql/query.py", line 1529, in _add_q
    child_clause, needed_inner = self.build_filter(
  File "/home/suraj/.local/lib/python3.10/site-packages/django/db/models/sql/query.py", line 1444, in build_filter
    condition = self.build_lookup(lookups, col, value)
  File "/home/suraj/.local/lib/python3.10/site-packages/django/db/models/sql/query.py", line 1271, in build_lookup
    lookup = lookup_class(lhs, rhs)
  File "/home/suraj/.local/lib/python3.10/site-packages/django/db/models/lookups.py", line 27, in __init__
    self.rhs = self.get_prep_lookup()
  File "/home/suraj/.local/lib/python3.10/site-packages/django/db/models/fields/related_lookups.py", line 166, in get_prep_lookup
    self.rhs = target_field.get_prep_value(self.rhs)
  File "/home/suraj/.local/lib/python3.10/site-packages/django/db/models/fields/__init__.py", line 2057, in get_prep_value
    raise e.__class__(
TypeError: Field 'id' expected a number but got <django.contrib.auth.models.AnonymousUser object at 0x7fe755575390>.
2023-05-28 06:25:33 ERROR django.server "POST /api/v1/payment/verify-payment/ HTTP/1.1" 500 190136
2023-05-28 06:26:21 WARNING django.request Bad Request: /api/v1/payment/verify-payment/
2023-05-28 06:26:21 WARNING django.server "POST /api/v1/payment/verify-payment/ HTTP/1.1" 400 74
2023-05-28 06:27:06 WARNING django.request Unauthorized: /api/v1/payment/verify-payment/
2023-05-28 06:27:06 WARNING django.server "POST /api/v1/payment/verify-payment/ HTTP/1.1" 401 57
2023-05-28 06:28:06 WARNING django.request Bad Request: /api/v1/payment/verify-payment/
2023-05-28 06:28:06 WARNING django.server "POST /api/v1/payment/verify-payment/ HTTP/1.1" 400 74
2023-05-28 06:28:22 WARNING django.request Bad Request: /api/v1/payment/verify-payment/
2023-05-28 06:28:22 WARNING django.server "POST /api/v1/payment/verify-payment/ HTTP/1.1" 400 74
2023-05-28 06:28:22 WARNING django.request Bad Request: /api/v1/payment/verify-payment/
2023-05-28 06:28:22 WARNING django.server "POST /api/v1/payment/verify-payment/ HTTP/1.1" 400 74
2023-05-28 07:13:10 ERROR django.request Internal Server Error: /api/v1/payment/verify-payment/
Traceback (most recent call last):
  File "/home/suraj/.local/lib/python3.10/site-packages/urllib3/connection.py", line 174, in _new_conn
    conn = connection.create_connection(
  File "/home/suraj/.local/lib/python3.10/site-packages/urllib3/util/connection.py", line 72, in create_connection
    for res in socket.getaddrinfo(host, port, family, socket.SOCK_STREAM):
  File "/usr/lib/python3.10/socket.py", line 955, in getaddrinfo
    for res in _socket.getaddrinfo(host, port, family, type, proto, flags):
socket.gaierror: [Errno -3] Temporary failure in name resolution

During handling of the above exception, another exception occurred:

Traceback (most recent call last):
  File "/home/suraj/.local/lib/python3.10/site-packages/urllib3/connectionpool.py", line 703, in urlopen
    httplib_response = self._make_request(
  File "/home/suraj/.local/lib/python3.10/site-packages/urllib3/connectionpool.py", line 386, in _make_request
    self._validate_conn(conn)
  File "/home/suraj/.local/lib/python3.10/site-packages/urllib3/connectionpool.py", line 1042, in _validate_conn
    conn.connect()
  File "/home/suraj/.local/lib/python3.10/site-packages/urllib3/connection.py", line 363, in connect
    self.sock = conn = self._new_conn()
  File "/home/suraj/.local/lib/python3.10/site-packages/urllib3/connection.py", line 186, in _new_conn
    raise NewConnectionError(
urllib3.exceptions.NewConnectionError: <urllib3.connection.HTTPSConnection object at 0x7fae60858a60>: Failed to establish a new connection: [Errno -3] Temporary failure in name resolution

During handling of the above exception, another exception occurred:

Traceback (most recent call last):
  File "/usr/lib/python3/dist-packages/requests/adapters.py", line 439, in send
    resp = conn.urlopen(
  File "/home/suraj/.local/lib/python3.10/site-packages/urllib3/connectionpool.py", line 787, in urlopen
    retries = retries.increment(
  File "/home/suraj/.local/lib/python3.10/site-packages/urllib3/util/retry.py", line 592, in increment
    raise MaxRetryError(_pool, url, error or ResponseError(cause))
urllib3.exceptions.MaxRetryError: HTTPSConnectionPool(host='a.khalti.com', port=443): Max retries exceeded with url: /api/v2/epayment/lookup/ (Caused by NewConnectionError('<urllib3.connection.HTTPSConnection object at 0x7fae60858a60>: Failed to establish a new connection: [Errno -3] Temporary failure in name resolution'))

During handling of the above exception, another exception occurred:

Traceback (most recent call last):
  File "/home/suraj/.local/lib/python3.10/site-packages/django/core/handlers/exception.py", line 55, in inner
    response = get_response(request)
  File "/home/suraj/.local/lib/python3.10/site-packages/django/core/handlers/base.py", line 197, in _get_response
    response = wrapped_callback(request, *callback_args, **callback_kwargs)
  File "/home/suraj/.local/lib/python3.10/site-packages/django/views/decorators/csrf.py", line 56, in wrapper_view
    return view_func(*args, **kwargs)
  File "/home/suraj/.local/lib/python3.10/site-packages/django/views/generic/base.py", line 104, in view
    return self.dispatch(request, *args, **kwargs)
  File "/home/suraj/.local/lib/python3.10/site-packages/rest_framework/views.py", line 509, in dispatch
    response = self.handle_exception(exc)
  File "/home/suraj/.local/lib/python3.10/site-packages/rest_framework/views.py", line 469, in handle_exception
    self.raise_uncaught_exception(exc)
  File "/home/suraj/.local/lib/python3.10/site-packages/rest_framework/views.py", line 480, in raise_uncaught_exception
    raise exc
  File "/home/suraj/.local/lib/python3.10/site-packages/rest_framework/views.py", line 506, in dispatch
    response = handler(request, *args, **kwargs)
  File "/home/suraj/.local/lib/python3.10/site-packages/drf_spectacular/drainage.py", line 193, in wrapped_method
    return method(self, request, *args, **kwargs)
  File "/home/suraj/.local/lib/python3.10/site-packages/rest_framework/generics.py", line 190, in post
    return self.create(request, *args, **kwargs)
  File "/home/suraj/Desktop/Python/JobBackend/JobPortalBackend/payment/api/viewsets/payment.py", line 70, in create
    response = super().create(request, *args, **kwargs)
  File "/home/suraj/.local/lib/python3.10/site-packages/rest_framework/mixins.py", line 19, in create
    self.perform_create(serializer)
  File "/home/suraj/.local/lib/python3.10/site-packages/rest_framework/mixins.py", line 24, in perform_create
    serializer.save()
  File "/home/suraj/.local/lib/python3.10/site-packages/rest_framework/serializers.py", line 212, in save
    self.instance = self.create(validated_data)
  File "/home/suraj/Desktop/Python/JobBackend/JobPortalBackend/payment/api/serializers/payment.py", line 70, in create
    response = req.post(url, headers=headers, json=data)
  File "/usr/lib/python3/dist-packages/requests/api.py", line 119, in post
    return request('post', url, data=data, json=json, **kwargs)
  File "/usr/lib/python3/dist-packages/requests/api.py", line 61, in request
    return session.request(method=method, url=url, **kwargs)
  File "/usr/lib/python3/dist-packages/requests/sessions.py", line 542, in request
    resp = self.send(prep, **send_kwargs)
  File "/usr/lib/python3/dist-packages/requests/sessions.py", line 655, in send
    r = adapter.send(request, **kwargs)
  File "/usr/lib/python3/dist-packages/requests/adapters.py", line 516, in send
    raise ConnectionError(e, request=request)
requests.exceptions.ConnectionError: HTTPSConnectionPool(host='a.khalti.com', port=443): Max retries exceeded with url: /api/v2/epayment/lookup/ (Caused by NewConnectionError('<urllib3.connection.HTTPSConnection object at 0x7fae60858a60>: Failed to establish a new connection: [Errno -3] Temporary failure in name resolution'))
2023-05-28 07:13:10 ERROR django.server "POST /api/v1/payment/verify-payment/ HTTP/1.1" 500 213606
2023-05-28 07:13:12 ERROR django.request Internal Server Error: /api/v1/payment/verify-payment/
Traceback (most recent call last):
  File "/home/suraj/.local/lib/python3.10/site-packages/urllib3/connection.py", line 174, in _new_conn
    conn = connection.create_connection(
  File "/home/suraj/.local/lib/python3.10/site-packages/urllib3/util/connection.py", line 72, in create_connection
    for res in socket.getaddrinfo(host, port, family, socket.SOCK_STREAM):
  File "/usr/lib/python3.10/socket.py", line 955, in getaddrinfo
    for res in _socket.getaddrinfo(host, port, family, type, proto, flags):
socket.gaierror: [Errno -3] Temporary failure in name resolution

During handling of the above exception, another exception occurred:

Traceback (most recent call last):
  File "/home/suraj/.local/lib/python3.10/site-packages/urllib3/connectionpool.py", line 703, in urlopen
    httplib_response = self._make_request(
  File "/home/suraj/.local/lib/python3.10/site-packages/urllib3/connectionpool.py", line 386, in _make_request
    self._validate_conn(conn)
  File "/home/suraj/.local/lib/python3.10/site-packages/urllib3/connectionpool.py", line 1042, in _validate_conn
    conn.connect()
  File "/home/suraj/.local/lib/python3.10/site-packages/urllib3/connection.py", line 363, in connect
    self.sock = conn = self._new_conn()
  File "/home/suraj/.local/lib/python3.10/site-packages/urllib3/connection.py", line 186, in _new_conn
    raise NewConnectionError(
urllib3.exceptions.NewConnectionError: <urllib3.connection.HTTPSConnection object at 0x7fae6250ff70>: Failed to establish a new connection: [Errno -3] Temporary failure in name resolution

During handling of the above exception, another exception occurred:

Traceback (most recent call last):
  File "/usr/lib/python3/dist-packages/requests/adapters.py", line 439, in send
    resp = conn.urlopen(
  File "/home/suraj/.local/lib/python3.10/site-packages/urllib3/connectionpool.py", line 787, in urlopen
    retries = retries.increment(
  File "/home/suraj/.local/lib/python3.10/site-packages/urllib3/util/retry.py", line 592, in increment
    raise MaxRetryError(_pool, url, error or ResponseError(cause))
urllib3.exceptions.MaxRetryError: HTTPSConnectionPool(host='a.khalti.com', port=443): Max retries exceeded with url: /api/v2/epayment/lookup/ (Caused by NewConnectionError('<urllib3.connection.HTTPSConnection object at 0x7fae6250ff70>: Failed to establish a new connection: [Errno -3] Temporary failure in name resolution'))

During handling of the above exception, another exception occurred:

Traceback (most recent call last):
  File "/home/suraj/.local/lib/python3.10/site-packages/django/core/handlers/exception.py", line 55, in inner
    response = get_response(request)
  File "/home/suraj/.local/lib/python3.10/site-packages/django/core/handlers/base.py", line 197, in _get_response
    response = wrapped_callback(request, *callback_args, **callback_kwargs)
  File "/home/suraj/.local/lib/python3.10/site-packages/django/views/decorators/csrf.py", line 56, in wrapper_view
    return view_func(*args, **kwargs)
  File "/home/suraj/.local/lib/python3.10/site-packages/django/views/generic/base.py", line 104, in view
    return self.dispatch(request, *args, **kwargs)
  File "/home/suraj/.local/lib/python3.10/site-packages/rest_framework/views.py", line 509, in dispatch
    response = self.handle_exception(exc)
  File "/home/suraj/.local/lib/python3.10/site-packages/rest_framework/views.py", line 469, in handle_exception
    self.raise_uncaught_exception(exc)
  File "/home/suraj/.local/lib/python3.10/site-packages/rest_framework/views.py", line 480, in raise_uncaught_exception
    raise exc
  File "/home/suraj/.local/lib/python3.10/site-packages/rest_framework/views.py", line 506, in dispatch
    response = handler(request, *args, **kwargs)
  File "/home/suraj/.local/lib/python3.10/site-packages/drf_spectacular/drainage.py", line 193, in wrapped_method
    return method(self, request, *args, **kwargs)
  File "/home/suraj/.local/lib/python3.10/site-packages/rest_framework/generics.py", line 190, in post
    return self.create(request, *args, **kwargs)
  File "/home/suraj/Desktop/Python/JobBackend/JobPortalBackend/payment/api/viewsets/payment.py", line 70, in create
    response = super().create(request, *args, **kwargs)
  File "/home/suraj/.local/lib/python3.10/site-packages/rest_framework/mixins.py", line 19, in create
    self.perform_create(serializer)
  File "/home/suraj/.local/lib/python3.10/site-packages/rest_framework/mixins.py", line 24, in perform_create
    serializer.save()
  File "/home/suraj/.local/lib/python3.10/site-packages/rest_framework/serializers.py", line 212, in save
    self.instance = self.create(validated_data)
  File "/home/suraj/Desktop/Python/JobBackend/JobPortalBackend/payment/api/serializers/payment.py", line 70, in create
    response = req.post(url, headers=headers, json=data)
  File "/usr/lib/python3/dist-packages/requests/api.py", line 119, in post
    return request('post', url, data=data, json=json, **kwargs)
  File "/usr/lib/python3/dist-packages/requests/api.py", line 61, in request
    return session.request(method=method, url=url, **kwargs)
  File "/usr/lib/python3/dist-packages/requests/sessions.py", line 542, in request
    resp = self.send(prep, **send_kwargs)
  File "/usr/lib/python3/dist-packages/requests/sessions.py", line 655, in send
    r = adapter.send(request, **kwargs)
  File "/usr/lib/python3/dist-packages/requests/adapters.py", line 516, in send
    raise ConnectionError(e, request=request)
requests.exceptions.ConnectionError: HTTPSConnectionPool(host='a.khalti.com', port=443): Max retries exceeded with url: /api/v2/epayment/lookup/ (Caused by NewConnectionError('<urllib3.connection.HTTPSConnection object at 0x7fae6250ff70>: Failed to establish a new connection: [Errno -3] Temporary failure in name resolution'))
2023-05-28 07:13:12 ERROR django.server "POST /api/v1/payment/verify-payment/ HTTP/1.1" 500 213607
2023-05-28 07:13:20 ERROR django.request Internal Server Error: /api/v1/payment/verify-payment/
Traceback (most recent call last):
  File "/home/suraj/.local/lib/python3.10/site-packages/urllib3/connection.py", line 174, in _new_conn
    conn = connection.create_connection(
  File "/home/suraj/.local/lib/python3.10/site-packages/urllib3/util/connection.py", line 72, in create_connection
    for res in socket.getaddrinfo(host, port, family, socket.SOCK_STREAM):
  File "/usr/lib/python3.10/socket.py", line 955, in getaddrinfo
    for res in _socket.getaddrinfo(host, port, family, type, proto, flags):
socket.gaierror: [Errno -3] Temporary failure in name resolution

During handling of the above exception, another exception occurred:

Traceback (most recent call last):
  File "/home/suraj/.local/lib/python3.10/site-packages/urllib3/connectionpool.py", line 703, in urlopen
    httplib_response = self._make_request(
  File "/home/suraj/.local/lib/python3.10/site-packages/urllib3/connectionpool.py", line 386, in _make_request
    self._validate_conn(conn)
  File "/home/suraj/.local/lib/python3.10/site-packages/urllib3/connectionpool.py", line 1042, in _validate_conn
    conn.connect()
  File "/home/suraj/.local/lib/python3.10/site-packages/urllib3/connection.py", line 363, in connect
    self.sock = conn = self._new_conn()
  File "/home/suraj/.local/lib/python3.10/site-packages/urllib3/connection.py", line 186, in _new_conn
    raise NewConnectionError(
urllib3.exceptions.NewConnectionError: <urllib3.connection.HTTPSConnection object at 0x7fae607c8550>: Failed to establish a new connection: [Errno -3] Temporary failure in name resolution

During handling of the above exception, another exception occurred:

Traceback (most recent call last):
  File "/usr/lib/python3/dist-packages/requests/adapters.py", line 439, in send
    resp = conn.urlopen(
  File "/home/suraj/.local/lib/python3.10/site-packages/urllib3/connectionpool.py", line 787, in urlopen
    retries = retries.increment(
  File "/home/suraj/.local/lib/python3.10/site-packages/urllib3/util/retry.py", line 592, in increment
    raise MaxRetryError(_pool, url, error or ResponseError(cause))
urllib3.exceptions.MaxRetryError: HTTPSConnectionPool(host='a.khalti.com', port=443): Max retries exceeded with url: /api/v2/epayment/lookup/ (Caused by NewConnectionError('<urllib3.connection.HTTPSConnection object at 0x7fae607c8550>: Failed to establish a new connection: [Errno -3] Temporary failure in name resolution'))

During handling of the above exception, another exception occurred:

Traceback (most recent call last):
  File "/home/suraj/.local/lib/python3.10/site-packages/django/core/handlers/exception.py", line 55, in inner
    response = get_response(request)
  File "/home/suraj/.local/lib/python3.10/site-packages/django/core/handlers/base.py", line 197, in _get_response
    response = wrapped_callback(request, *callback_args, **callback_kwargs)
  File "/home/suraj/.local/lib/python3.10/site-packages/django/views/decorators/csrf.py", line 56, in wrapper_view
    return view_func(*args, **kwargs)
  File "/home/suraj/.local/lib/python3.10/site-packages/django/views/generic/base.py", line 104, in view
    return self.dispatch(request, *args, **kwargs)
  File "/home/suraj/.local/lib/python3.10/site-packages/rest_framework/views.py", line 509, in dispatch
    response = self.handle_exception(exc)
  File "/home/suraj/.local/lib/python3.10/site-packages/rest_framework/views.py", line 469, in handle_exception
    self.raise_uncaught_exception(exc)
  File "/home/suraj/.local/lib/python3.10/site-packages/rest_framework/views.py", line 480, in raise_uncaught_exception
    raise exc
  File "/home/suraj/.local/lib/python3.10/site-packages/rest_framework/views.py", line 506, in dispatch
    response = handler(request, *args, **kwargs)
  File "/home/suraj/.local/lib/python3.10/site-packages/drf_spectacular/drainage.py", line 193, in wrapped_method
    return method(self, request, *args, **kwargs)
  File "/home/suraj/.local/lib/python3.10/site-packages/rest_framework/generics.py", line 190, in post
    return self.create(request, *args, **kwargs)
  File "/home/suraj/Desktop/Python/JobBackend/JobPortalBackend/payment/api/viewsets/payment.py", line 70, in create
    response = super().create(request, *args, **kwargs)
  File "/home/suraj/.local/lib/python3.10/site-packages/rest_framework/mixins.py", line 19, in create
    self.perform_create(serializer)
  File "/home/suraj/.local/lib/python3.10/site-packages/rest_framework/mixins.py", line 24, in perform_create
    serializer.save()
  File "/home/suraj/.local/lib/python3.10/site-packages/rest_framework/serializers.py", line 212, in save
    self.instance = self.create(validated_data)
  File "/home/suraj/Desktop/Python/JobBackend/JobPortalBackend/payment/api/serializers/payment.py", line 70, in create
    response = req.post(url, headers=headers, json=data)
  File "/usr/lib/python3/dist-packages/requests/api.py", line 119, in post
    return request('post', url, data=data, json=json, **kwargs)
  File "/usr/lib/python3/dist-packages/requests/api.py", line 61, in request
    return session.request(method=method, url=url, **kwargs)
  File "/usr/lib/python3/dist-packages/requests/sessions.py", line 542, in request
    resp = self.send(prep, **send_kwargs)
  File "/usr/lib/python3/dist-packages/requests/sessions.py", line 655, in send
    r = adapter.send(request, **kwargs)
  File "/usr/lib/python3/dist-packages/requests/adapters.py", line 516, in send
    raise ConnectionError(e, request=request)
requests.exceptions.ConnectionError: HTTPSConnectionPool(host='a.khalti.com', port=443): Max retries exceeded with url: /api/v2/epayment/lookup/ (Caused by NewConnectionError('<urllib3.connection.HTTPSConnection object at 0x7fae607c8550>: Failed to establish a new connection: [Errno -3] Temporary failure in name resolution'))
2023-05-28 07:13:20 ERROR django.server "POST /api/v1/payment/verify-payment/ HTTP/1.1" 500 213607
2023-05-28 07:13:36 WARNING django.request Unauthorized: /api/v1/payment/verify-payment/
2023-05-28 07:13:36 WARNING django.server "POST /api/v1/payment/verify-payment/ HTTP/1.1" 401 57
2023-05-28 07:13:51 WARNING django.request Unauthorized: /api/v1/payment/verify-payment/
2023-05-28 07:13:51 WARNING django.server "POST /api/v1/payment/verify-payment/ HTTP/1.1" 401 57
2023-05-28 07:14:38 WARNING django.request Unauthorized: /api/v1/payment/verify-payment/
2023-05-28 07:14:38 WARNING django.server "POST /api/v1/payment/verify-payment/ HTTP/1.1" 401 57
2023-05-28 07:15:10 WARNING django.request Unauthorized: /api/v1/payment/verify-payment/
2023-05-28 07:15:10 WARNING django.server "POST /api/v1/payment/verify-payment/ HTTP/1.1" 401 57
2023-05-28 07:15:15 WARNING django.request Unauthorized: /api/v1/payment/verify-payment/
2023-05-28 07:15:15 WARNING django.server "POST /api/v1/payment/verify-payment/ HTTP/1.1" 401 57
2023-05-28 07:16:10 WARNING django.request Unauthorized: /api/v1/payment/verify-payment/
2023-05-28 07:16:10 WARNING django.server "POST /api/v1/payment/verify-payment/ HTTP/1.1" 401 57
2023-05-28 07:16:13 WARNING django.request Unauthorized: /api/v1/payment/verify-payment/
2023-05-28 07:16:13 WARNING django.server "POST /api/v1/payment/verify-payment/ HTTP/1.1" 401 57
2023-05-28 07:16:18 WARNING django.request Unauthorized: /api/v1/payment/verify-payment/
2023-05-28 07:16:18 WARNING django.server "POST /api/v1/payment/verify-payment/ HTTP/1.1" 401 57
2023-05-28 07:17:08 WARNING django.request Unauthorized: /api/v1/payment/verify-payment/
2023-05-28 07:17:08 WARNING django.server "POST /api/v1/payment/verify-payment/ HTTP/1.1" 401 57
2023-05-28 07:17:09 WARNING django.request Unauthorized: /api/v1/payment/verify-payment/
2023-05-28 07:17:09 WARNING django.server "POST /api/v1/payment/verify-payment/ HTTP/1.1" 401 183
2023-05-28 07:17:12 WARNING django.request Unauthorized: /api/v1/payment/verify-payment/
2023-05-28 07:17:12 WARNING django.server "POST /api/v1/payment/verify-payment/ HTTP/1.1" 401 183
2023-05-28 07:18:00 ERROR django.request Internal Server Error: /api/v1/payment/verify-payment/
Traceback (most recent call last):
  File "/home/suraj/.local/lib/python3.10/site-packages/urllib3/connection.py", line 174, in _new_conn
    conn = connection.create_connection(
  File "/home/suraj/.local/lib/python3.10/site-packages/urllib3/util/connection.py", line 72, in create_connection
    for res in socket.getaddrinfo(host, port, family, socket.SOCK_STREAM):
  File "/usr/lib/python3.10/socket.py", line 955, in getaddrinfo
    for res in _socket.getaddrinfo(host, port, family, type, proto, flags):
socket.gaierror: [Errno -3] Temporary failure in name resolution

During handling of the above exception, another exception occurred:

Traceback (most recent call last):
  File "/home/suraj/.local/lib/python3.10/site-packages/urllib3/connectionpool.py", line 703, in urlopen
    httplib_response = self._make_request(
  File "/home/suraj/.local/lib/python3.10/site-packages/urllib3/connectionpool.py", line 386, in _make_request
    self._validate_conn(conn)
  File "/home/suraj/.local/lib/python3.10/site-packages/urllib3/connectionpool.py", line 1042, in _validate_conn
    conn.connect()
  File "/home/suraj/.local/lib/python3.10/site-packages/urllib3/connection.py", line 363, in connect
    self.sock = conn = self._new_conn()
  File "/home/suraj/.local/lib/python3.10/site-packages/urllib3/connection.py", line 186, in _new_conn
    raise NewConnectionError(
urllib3.exceptions.NewConnectionError: <urllib3.connection.HTTPSConnection object at 0x7fae607b30d0>: Failed to establish a new connection: [Errno -3] Temporary failure in name resolution

During handling of the above exception, another exception occurred:

Traceback (most recent call last):
  File "/usr/lib/python3/dist-packages/requests/adapters.py", line 439, in send
    resp = conn.urlopen(
  File "/home/suraj/.local/lib/python3.10/site-packages/urllib3/connectionpool.py", line 787, in urlopen
    retries = retries.increment(
  File "/home/suraj/.local/lib/python3.10/site-packages/urllib3/util/retry.py", line 592, in increment
    raise MaxRetryError(_pool, url, error or ResponseError(cause))
urllib3.exceptions.MaxRetryError: HTTPSConnectionPool(host='a.khalti.com', port=443): Max retries exceeded with url: /api/v2/epayment/lookup/ (Caused by NewConnectionError('<urllib3.connection.HTTPSConnection object at 0x7fae607b30d0>: Failed to establish a new connection: [Errno -3] Temporary failure in name resolution'))

During handling of the above exception, another exception occurred:

Traceback (most recent call last):
  File "/home/suraj/.local/lib/python3.10/site-packages/django/core/handlers/exception.py", line 55, in inner
    response = get_response(request)
  File "/home/suraj/.local/lib/python3.10/site-packages/django/core/handlers/base.py", line 197, in _get_response
    response = wrapped_callback(request, *callback_args, **callback_kwargs)
  File "/home/suraj/.local/lib/python3.10/site-packages/django/views/decorators/csrf.py", line 56, in wrapper_view
    return view_func(*args, **kwargs)
  File "/home/suraj/.local/lib/python3.10/site-packages/django/views/generic/base.py", line 104, in view
    return self.dispatch(request, *args, **kwargs)
  File "/home/suraj/.local/lib/python3.10/site-packages/rest_framework/views.py", line 509, in dispatch
    response = self.handle_exception(exc)
  File "/home/suraj/.local/lib/python3.10/site-packages/rest_framework/views.py", line 469, in handle_exception
    self.raise_uncaught_exception(exc)
  File "/home/suraj/.local/lib/python3.10/site-packages/rest_framework/views.py", line 480, in raise_uncaught_exception
    raise exc
  File "/home/suraj/.local/lib/python3.10/site-packages/rest_framework/views.py", line 506, in dispatch
    response = handler(request, *args, **kwargs)
  File "/home/suraj/.local/lib/python3.10/site-packages/drf_spectacular/drainage.py", line 193, in wrapped_method
    return method(self, request, *args, **kwargs)
  File "/home/suraj/.local/lib/python3.10/site-packages/rest_framework/generics.py", line 190, in post
    return self.create(request, *args, **kwargs)
  File "/home/suraj/Desktop/Python/JobBackend/JobPortalBackend/payment/api/viewsets/payment.py", line 70, in create
    response = super().create(request, *args, **kwargs)
  File "/home/suraj/.local/lib/python3.10/site-packages/rest_framework/mixins.py", line 19, in create
    self.perform_create(serializer)
  File "/home/suraj/.local/lib/python3.10/site-packages/rest_framework/mixins.py", line 24, in perform_create
    serializer.save()
  File "/home/suraj/.local/lib/python3.10/site-packages/rest_framework/serializers.py", line 212, in save
    self.instance = self.create(validated_data)
  File "/home/suraj/Desktop/Python/JobBackend/JobPortalBackend/payment/api/serializers/payment.py", line 70, in create
    response = req.post(url, headers=headers, json=data)
  File "/usr/lib/python3/dist-packages/requests/api.py", line 119, in post
    return request('post', url, data=data, json=json, **kwargs)
  File "/usr/lib/python3/dist-packages/requests/api.py", line 61, in request
    return session.request(method=method, url=url, **kwargs)
  File "/usr/lib/python3/dist-packages/requests/sessions.py", line 542, in request
    resp = self.send(prep, **send_kwargs)
  File "/usr/lib/python3/dist-packages/requests/sessions.py", line 655, in send
    r = adapter.send(request, **kwargs)
  File "/usr/lib/python3/dist-packages/requests/adapters.py", line 516, in send
    raise ConnectionError(e, request=request)
requests.exceptions.ConnectionError: HTTPSConnectionPool(host='a.khalti.com', port=443): Max retries exceeded with url: /api/v2/epayment/lookup/ (Caused by NewConnectionError('<urllib3.connection.HTTPSConnection object at 0x7fae607b30d0>: Failed to establish a new connection: [Errno -3] Temporary failure in name resolution'))
2023-05-28 07:18:00 ERROR django.server "POST /api/v1/payment/verify-payment/ HTTP/1.1" 500 213606
2023-05-28 07:22:19 WARNING django.request Unauthorized: /api/v1/payment/verify-payment/
2023-05-28 07:22:19 WARNING django.server "POST /api/v1/payment/verify-payment/ HTTP/1.1" 401 183
2023-05-28 07:24:53 WARNING django.request Unauthorized: /api/v1/payment/verify-payment/
2023-05-28 07:24:53 WARNING django.server "POST /api/v1/payment/verify-payment/ HTTP/1.1" 401 183
2023-05-28 07:24:55 WARNING django.request Unauthorized: /api/v1/payment/verify-payment/
2023-05-28 07:24:55 WARNING django.server "POST /api/v1/payment/verify-payment/ HTTP/1.1" 401 183
2023-05-28 07:25:35 ERROR django.request Internal Server Error: /api/v1/payment/make-payment/
Traceback (most recent call last):
  File "/home/suraj/.local/lib/python3.10/site-packages/urllib3/connection.py", line 174, in _new_conn
    conn = connection.create_connection(
  File "/home/suraj/.local/lib/python3.10/site-packages/urllib3/util/connection.py", line 72, in create_connection
    for res in socket.getaddrinfo(host, port, family, socket.SOCK_STREAM):
  File "/usr/lib/python3.10/socket.py", line 955, in getaddrinfo
    for res in _socket.getaddrinfo(host, port, family, type, proto, flags):
socket.gaierror: [Errno -3] Temporary failure in name resolution

During handling of the above exception, another exception occurred:

Traceback (most recent call last):
  File "/home/suraj/.local/lib/python3.10/site-packages/urllib3/connectionpool.py", line 703, in urlopen
    httplib_response = self._make_request(
  File "/home/suraj/.local/lib/python3.10/site-packages/urllib3/connectionpool.py", line 386, in _make_request
    self._validate_conn(conn)
  File "/home/suraj/.local/lib/python3.10/site-packages/urllib3/connectionpool.py", line 1042, in _validate_conn
    conn.connect()
  File "/home/suraj/.local/lib/python3.10/site-packages/urllib3/connection.py", line 363, in connect
    self.sock = conn = self._new_conn()
  File "/home/suraj/.local/lib/python3.10/site-packages/urllib3/connection.py", line 186, in _new_conn
    raise NewConnectionError(
urllib3.exceptions.NewConnectionError: <urllib3.connection.HTTPSConnection object at 0x7fae611fd600>: Failed to establish a new connection: [Errno -3] Temporary failure in name resolution

During handling of the above exception, another exception occurred:

Traceback (most recent call last):
  File "/usr/lib/python3/dist-packages/requests/adapters.py", line 439, in send
    resp = conn.urlopen(
  File "/home/suraj/.local/lib/python3.10/site-packages/urllib3/connectionpool.py", line 787, in urlopen
    retries = retries.increment(
  File "/home/suraj/.local/lib/python3.10/site-packages/urllib3/util/retry.py", line 592, in increment
    raise MaxRetryError(_pool, url, error or ResponseError(cause))
urllib3.exceptions.MaxRetryError: HTTPSConnectionPool(host='a.khalti.com', port=443): Max retries exceeded with url: /api/v2/epayment/initiate/ (Caused by NewConnectionError('<urllib3.connection.HTTPSConnection object at 0x7fae611fd600>: Failed to establish a new connection: [Errno -3] Temporary failure in name resolution'))

During handling of the above exception, another exception occurred:

Traceback (most recent call last):
  File "/home/suraj/.local/lib/python3.10/site-packages/django/core/handlers/exception.py", line 55, in inner
    response = get_response(request)
  File "/home/suraj/.local/lib/python3.10/site-packages/django/core/handlers/base.py", line 197, in _get_response
    response = wrapped_callback(request, *callback_args, **callback_kwargs)
  File "/home/suraj/.local/lib/python3.10/site-packages/django/views/decorators/csrf.py", line 56, in wrapper_view
    return view_func(*args, **kwargs)
  File "/home/suraj/.local/lib/python3.10/site-packages/django/views/generic/base.py", line 104, in view
    return self.dispatch(request, *args, **kwargs)
  File "/home/suraj/.local/lib/python3.10/site-packages/rest_framework/views.py", line 509, in dispatch
    response = self.handle_exception(exc)
  File "/home/suraj/.local/lib/python3.10/site-packages/rest_framework/views.py", line 469, in handle_exception
    self.raise_uncaught_exception(exc)
  File "/home/suraj/.local/lib/python3.10/site-packages/rest_framework/views.py", line 480, in raise_uncaught_exception
    raise exc
  File "/home/suraj/.local/lib/python3.10/site-packages/rest_framework/views.py", line 506, in dispatch
    response = handler(request, *args, **kwargs)
  File "/home/suraj/.local/lib/python3.10/site-packages/drf_spectacular/drainage.py", line 193, in wrapped_method
    return method(self, request, *args, **kwargs)
  File "/home/suraj/.local/lib/python3.10/site-packages/rest_framework/generics.py", line 190, in post
    return self.create(request, *args, **kwargs)
  File "/home/suraj/Desktop/Python/JobBackend/JobPortalBackend/payment/api/viewsets/payment.py", line 38, in create
    response = super().create(request, *args, **kwargs)
  File "/home/suraj/.local/lib/python3.10/site-packages/rest_framework/mixins.py", line 20, in create
    headers = self.get_success_headers(serializer.data)
  File "/home/suraj/.local/lib/python3.10/site-packages/rest_framework/serializers.py", line 555, in data
    ret = super().data
  File "/home/suraj/.local/lib/python3.10/site-packages/rest_framework/serializers.py", line 253, in data
    self._data = self.to_representation(self.instance)
  File "/home/suraj/.local/lib/python3.10/site-packages/rest_framework/serializers.py", line 522, in to_representation
    ret[field.field_name] = field.to_representation(attribute)
  File "/home/suraj/.local/lib/python3.10/site-packages/rest_framework/fields.py", line 1838, in to_representation
    return method(value)
  File "/home/suraj/Desktop/Python/JobBackend/JobPortalBackend/payment/api/serializers/payment.py", line 31, in get_khalti
    verification_response = req.post(
  File "/usr/lib/python3/dist-packages/requests/api.py", line 119, in post
    return request('post', url, data=data, json=json, **kwargs)
  File "/usr/lib/python3/dist-packages/requests/api.py", line 61, in request
    return session.request(method=method, url=url, **kwargs)
  File "/usr/lib/python3/dist-packages/requests/sessions.py", line 542, in request
    resp = self.send(prep, **send_kwargs)
  File "/usr/lib/python3/dist-packages/requests/sessions.py", line 655, in send
    r = adapter.send(request, **kwargs)
  File "/usr/lib/python3/dist-packages/requests/adapters.py", line 516, in send
    raise ConnectionError(e, request=request)
requests.exceptions.ConnectionError: HTTPSConnectionPool(host='a.khalti.com', port=443): Max retries exceeded with url: /api/v2/epayment/initiate/ (Caused by NewConnectionError('<urllib3.connection.HTTPSConnection object at 0x7fae611fd600>: Failed to establish a new connection: [Errno -3] Temporary failure in name resolution'))
2023-05-28 07:25:35 ERROR django.server "POST /api/v1/payment/make-payment/ HTTP/1.1" 500 225741
2023-05-28 07:25:45 ERROR django.request Internal Server Error: /api/v1/payment/make-payment/
Traceback (most recent call last):
  File "/home/suraj/.local/lib/python3.10/site-packages/urllib3/connection.py", line 174, in _new_conn
    conn = connection.create_connection(
  File "/home/suraj/.local/lib/python3.10/site-packages/urllib3/util/connection.py", line 72, in create_connection
    for res in socket.getaddrinfo(host, port, family, socket.SOCK_STREAM):
  File "/usr/lib/python3.10/socket.py", line 955, in getaddrinfo
    for res in _socket.getaddrinfo(host, port, family, type, proto, flags):
socket.gaierror: [Errno -3] Temporary failure in name resolution

During handling of the above exception, another exception occurred:

Traceback (most recent call last):
  File "/home/suraj/.local/lib/python3.10/site-packages/urllib3/connectionpool.py", line 703, in urlopen
    httplib_response = self._make_request(
  File "/home/suraj/.local/lib/python3.10/site-packages/urllib3/connectionpool.py", line 386, in _make_request
    self._validate_conn(conn)
  File "/home/suraj/.local/lib/python3.10/site-packages/urllib3/connectionpool.py", line 1042, in _validate_conn
    conn.connect()
  File "/home/suraj/.local/lib/python3.10/site-packages/urllib3/connection.py", line 363, in connect
    self.sock = conn = self._new_conn()
  File "/home/suraj/.local/lib/python3.10/site-packages/urllib3/connection.py", line 186, in _new_conn
    raise NewConnectionError(
urllib3.exceptions.NewConnectionError: <urllib3.connection.HTTPSConnection object at 0x7fae607bff70>: Failed to establish a new connection: [Errno -3] Temporary failure in name resolution

During handling of the above exception, another exception occurred:

Traceback (most recent call last):
  File "/usr/lib/python3/dist-packages/requests/adapters.py", line 439, in send
    resp = conn.urlopen(
  File "/home/suraj/.local/lib/python3.10/site-packages/urllib3/connectionpool.py", line 787, in urlopen
    retries = retries.increment(
  File "/home/suraj/.local/lib/python3.10/site-packages/urllib3/util/retry.py", line 592, in increment
    raise MaxRetryError(_pool, url, error or ResponseError(cause))
urllib3.exceptions.MaxRetryError: HTTPSConnectionPool(host='a.khalti.com', port=443): Max retries exceeded with url: /api/v2/epayment/initiate/ (Caused by NewConnectionError('<urllib3.connection.HTTPSConnection object at 0x7fae607bff70>: Failed to establish a new connection: [Errno -3] Temporary failure in name resolution'))

During handling of the above exception, another exception occurred:

Traceback (most recent call last):
  File "/home/suraj/.local/lib/python3.10/site-packages/django/core/handlers/exception.py", line 55, in inner
    response = get_response(request)
  File "/home/suraj/.local/lib/python3.10/site-packages/django/core/handlers/base.py", line 197, in _get_response
    response = wrapped_callback(request, *callback_args, **callback_kwargs)
  File "/home/suraj/.local/lib/python3.10/site-packages/django/views/decorators/csrf.py", line 56, in wrapper_view
    return view_func(*args, **kwargs)
  File "/home/suraj/.local/lib/python3.10/site-packages/django/views/generic/base.py", line 104, in view
    return self.dispatch(request, *args, **kwargs)
  File "/home/suraj/.local/lib/python3.10/site-packages/rest_framework/views.py", line 509, in dispatch
    response = self.handle_exception(exc)
  File "/home/suraj/.local/lib/python3.10/site-packages/rest_framework/views.py", line 469, in handle_exception
    self.raise_uncaught_exception(exc)
  File "/home/suraj/.local/lib/python3.10/site-packages/rest_framework/views.py", line 480, in raise_uncaught_exception
    raise exc
  File "/home/suraj/.local/lib/python3.10/site-packages/rest_framework/views.py", line 506, in dispatch
    response = handler(request, *args, **kwargs)
  File "/home/suraj/.local/lib/python3.10/site-packages/drf_spectacular/drainage.py", line 193, in wrapped_method
    return method(self, request, *args, **kwargs)
  File "/home/suraj/.local/lib/python3.10/site-packages/rest_framework/generics.py", line 190, in post
    return self.create(request, *args, **kwargs)
  File "/home/suraj/Desktop/Python/JobBackend/JobPortalBackend/payment/api/viewsets/payment.py", line 38, in create
    response = super().create(request, *args, **kwargs)
  File "/home/suraj/.local/lib/python3.10/site-packages/rest_framework/mixins.py", line 20, in create
    headers = self.get_success_headers(serializer.data)
  File "/home/suraj/.local/lib/python3.10/site-packages/rest_framework/serializers.py", line 555, in data
    ret = super().data
  File "/home/suraj/.local/lib/python3.10/site-packages/rest_framework/serializers.py", line 253, in data
    self._data = self.to_representation(self.instance)
  File "/home/suraj/.local/lib/python3.10/site-packages/rest_framework/serializers.py", line 522, in to_representation
    ret[field.field_name] = field.to_representation(attribute)
  File "/home/suraj/.local/lib/python3.10/site-packages/rest_framework/fields.py", line 1838, in to_representation
    return method(value)
  File "/home/suraj/Desktop/Python/JobBackend/JobPortalBackend/payment/api/serializers/payment.py", line 31, in get_khalti
    verification_response = req.post(
  File "/usr/lib/python3/dist-packages/requests/api.py", line 119, in post
    return request('post', url, data=data, json=json, **kwargs)
  File "/usr/lib/python3/dist-packages/requests/api.py", line 61, in request
    return session.request(method=method, url=url, **kwargs)
  File "/usr/lib/python3/dist-packages/requests/sessions.py", line 542, in request
    resp = self.send(prep, **send_kwargs)
  File "/usr/lib/python3/dist-packages/requests/sessions.py", line 655, in send
    r = adapter.send(request, **kwargs)
  File "/usr/lib/python3/dist-packages/requests/adapters.py", line 516, in send
    raise ConnectionError(e, request=request)
requests.exceptions.ConnectionError: HTTPSConnectionPool(host='a.khalti.com', port=443): Max retries exceeded with url: /api/v2/epayment/initiate/ (Caused by NewConnectionError('<urllib3.connection.HTTPSConnection object at 0x7fae607bff70>: Failed to establish a new connection: [Errno -3] Temporary failure in name resolution'))
2023-05-28 07:25:45 ERROR django.server "POST /api/v1/payment/make-payment/ HTTP/1.1" 500 225741
2023-05-28 07:26:01 ERROR django.request Internal Server Error: /api/v1/payment/make-payment/
Traceback (most recent call last):
  File "/home/suraj/.local/lib/python3.10/site-packages/urllib3/connection.py", line 174, in _new_conn
    conn = connection.create_connection(
  File "/home/suraj/.local/lib/python3.10/site-packages/urllib3/util/connection.py", line 72, in create_connection
    for res in socket.getaddrinfo(host, port, family, socket.SOCK_STREAM):
  File "/usr/lib/python3.10/socket.py", line 955, in getaddrinfo
    for res in _socket.getaddrinfo(host, port, family, type, proto, flags):
socket.gaierror: [Errno -3] Temporary failure in name resolution

During handling of the above exception, another exception occurred:

Traceback (most recent call last):
  File "/home/suraj/.local/lib/python3.10/site-packages/urllib3/connectionpool.py", line 703, in urlopen
    httplib_response = self._make_request(
  File "/home/suraj/.local/lib/python3.10/site-packages/urllib3/connectionpool.py", line 386, in _make_request
    self._validate_conn(conn)
  File "/home/suraj/.local/lib/python3.10/site-packages/urllib3/connectionpool.py", line 1042, in _validate_conn
    conn.connect()
  File "/home/suraj/.local/lib/python3.10/site-packages/urllib3/connection.py", line 363, in connect
    self.sock = conn = self._new_conn()
  File "/home/suraj/.local/lib/python3.10/site-packages/urllib3/connection.py", line 186, in _new_conn
    raise NewConnectionError(
urllib3.exceptions.NewConnectionError: <urllib3.connection.HTTPSConnection object at 0x7fae605c5c90>: Failed to establish a new connection: [Errno -3] Temporary failure in name resolution

During handling of the above exception, another exception occurred:

Traceback (most recent call last):
  File "/usr/lib/python3/dist-packages/requests/adapters.py", line 439, in send
    resp = conn.urlopen(
  File "/home/suraj/.local/lib/python3.10/site-packages/urllib3/connectionpool.py", line 787, in urlopen
    retries = retries.increment(
  File "/home/suraj/.local/lib/python3.10/site-packages/urllib3/util/retry.py", line 592, in increment
    raise MaxRetryError(_pool, url, error or ResponseError(cause))
urllib3.exceptions.MaxRetryError: HTTPSConnectionPool(host='a.khalti.com', port=443): Max retries exceeded with url: /api/v2/epayment/initiate/ (Caused by NewConnectionError('<urllib3.connection.HTTPSConnection object at 0x7fae605c5c90>: Failed to establish a new connection: [Errno -3] Temporary failure in name resolution'))

During handling of the above exception, another exception occurred:

Traceback (most recent call last):
  File "/home/suraj/.local/lib/python3.10/site-packages/django/core/handlers/exception.py", line 55, in inner
    response = get_response(request)
  File "/home/suraj/.local/lib/python3.10/site-packages/django/core/handlers/base.py", line 197, in _get_response
    response = wrapped_callback(request, *callback_args, **callback_kwargs)
  File "/home/suraj/.local/lib/python3.10/site-packages/django/views/decorators/csrf.py", line 56, in wrapper_view
    return view_func(*args, **kwargs)
  File "/home/suraj/.local/lib/python3.10/site-packages/django/views/generic/base.py", line 104, in view
    return self.dispatch(request, *args, **kwargs)
  File "/home/suraj/.local/lib/python3.10/site-packages/rest_framework/views.py", line 509, in dispatch
    response = self.handle_exception(exc)
  File "/home/suraj/.local/lib/python3.10/site-packages/rest_framework/views.py", line 469, in handle_exception
    self.raise_uncaught_exception(exc)
  File "/home/suraj/.local/lib/python3.10/site-packages/rest_framework/views.py", line 480, in raise_uncaught_exception
    raise exc
  File "/home/suraj/.local/lib/python3.10/site-packages/rest_framework/views.py", line 506, in dispatch
    response = handler(request, *args, **kwargs)
  File "/home/suraj/.local/lib/python3.10/site-packages/drf_spectacular/drainage.py", line 193, in wrapped_method
    return method(self, request, *args, **kwargs)
  File "/home/suraj/.local/lib/python3.10/site-packages/rest_framework/generics.py", line 190, in post
    return self.create(request, *args, **kwargs)
  File "/home/suraj/Desktop/Python/JobBackend/JobPortalBackend/payment/api/viewsets/payment.py", line 38, in create
    response = super().create(request, *args, **kwargs)
  File "/home/suraj/.local/lib/python3.10/site-packages/rest_framework/mixins.py", line 20, in create
    headers = self.get_success_headers(serializer.data)
  File "/home/suraj/.local/lib/python3.10/site-packages/rest_framework/serializers.py", line 555, in data
    ret = super().data
  File "/home/suraj/.local/lib/python3.10/site-packages/rest_framework/serializers.py", line 253, in data
    self._data = self.to_representation(self.instance)
  File "/home/suraj/.local/lib/python3.10/site-packages/rest_framework/serializers.py", line 522, in to_representation
    ret[field.field_name] = field.to_representation(attribute)
  File "/home/suraj/.local/lib/python3.10/site-packages/rest_framework/fields.py", line 1838, in to_representation
    return method(value)
  File "/home/suraj/Desktop/Python/JobBackend/JobPortalBackend/payment/api/serializers/payment.py", line 31, in get_khalti
    verification_response = req.post(
  File "/usr/lib/python3/dist-packages/requests/api.py", line 119, in post
    return request('post', url, data=data, json=json, **kwargs)
  File "/usr/lib/python3/dist-packages/requests/api.py", line 61, in request
    return session.request(method=method, url=url, **kwargs)
  File "/usr/lib/python3/dist-packages/requests/sessions.py", line 542, in request
    resp = self.send(prep, **send_kwargs)
  File "/usr/lib/python3/dist-packages/requests/sessions.py", line 655, in send
    r = adapter.send(request, **kwargs)
  File "/usr/lib/python3/dist-packages/requests/adapters.py", line 516, in send
    raise ConnectionError(e, request=request)
requests.exceptions.ConnectionError: HTTPSConnectionPool(host='a.khalti.com', port=443): Max retries exceeded with url: /api/v2/epayment/initiate/ (Caused by NewConnectionError('<urllib3.connection.HTTPSConnection object at 0x7fae605c5c90>: Failed to establish a new connection: [Errno -3] Temporary failure in name resolution'))
2023-05-28 07:26:01 ERROR django.server "POST /api/v1/payment/make-payment/ HTTP/1.1" 500 225757
2023-05-28 07:26:10 ERROR django.request Internal Server Error: /api/v1/payment/make-payment/
Traceback (most recent call last):
  File "/home/suraj/.local/lib/python3.10/site-packages/urllib3/connection.py", line 174, in _new_conn
    conn = connection.create_connection(
  File "/home/suraj/.local/lib/python3.10/site-packages/urllib3/util/connection.py", line 72, in create_connection
    for res in socket.getaddrinfo(host, port, family, socket.SOCK_STREAM):
  File "/usr/lib/python3.10/socket.py", line 955, in getaddrinfo
    for res in _socket.getaddrinfo(host, port, family, type, proto, flags):
socket.gaierror: [Errno -3] Temporary failure in name resolution

During handling of the above exception, another exception occurred:

Traceback (most recent call last):
  File "/home/suraj/.local/lib/python3.10/site-packages/urllib3/connectionpool.py", line 703, in urlopen
    httplib_response = self._make_request(
  File "/home/suraj/.local/lib/python3.10/site-packages/urllib3/connectionpool.py", line 386, in _make_request
    self._validate_conn(conn)
  File "/home/suraj/.local/lib/python3.10/site-packages/urllib3/connectionpool.py", line 1042, in _validate_conn
    conn.connect()
  File "/home/suraj/.local/lib/python3.10/site-packages/urllib3/connection.py", line 363, in connect
    self.sock = conn = self._new_conn()
  File "/home/suraj/.local/lib/python3.10/site-packages/urllib3/connection.py", line 186, in _new_conn
    raise NewConnectionError(
urllib3.exceptions.NewConnectionError: <urllib3.connection.HTTPSConnection object at 0x7fae607b2d70>: Failed to establish a new connection: [Errno -3] Temporary failure in name resolution

During handling of the above exception, another exception occurred:

Traceback (most recent call last):
  File "/usr/lib/python3/dist-packages/requests/adapters.py", line 439, in send
    resp = conn.urlopen(
  File "/home/suraj/.local/lib/python3.10/site-packages/urllib3/connectionpool.py", line 787, in urlopen
    retries = retries.increment(
  File "/home/suraj/.local/lib/python3.10/site-packages/urllib3/util/retry.py", line 592, in increment
    raise MaxRetryError(_pool, url, error or ResponseError(cause))
urllib3.exceptions.MaxRetryError: HTTPSConnectionPool(host='a.khalti.com', port=443): Max retries exceeded with url: /api/v2/epayment/initiate/ (Caused by NewConnectionError('<urllib3.connection.HTTPSConnection object at 0x7fae607b2d70>: Failed to establish a new connection: [Errno -3] Temporary failure in name resolution'))

During handling of the above exception, another exception occurred:

Traceback (most recent call last):
  File "/home/suraj/.local/lib/python3.10/site-packages/django/core/handlers/exception.py", line 55, in inner
    response = get_response(request)
  File "/home/suraj/.local/lib/python3.10/site-packages/django/core/handlers/base.py", line 197, in _get_response
    response = wrapped_callback(request, *callback_args, **callback_kwargs)
  File "/home/suraj/.local/lib/python3.10/site-packages/django/views/decorators/csrf.py", line 56, in wrapper_view
    return view_func(*args, **kwargs)
  File "/home/suraj/.local/lib/python3.10/site-packages/django/views/generic/base.py", line 104, in view
    return self.dispatch(request, *args, **kwargs)
  File "/home/suraj/.local/lib/python3.10/site-packages/rest_framework/views.py", line 509, in dispatch
    response = self.handle_exception(exc)
  File "/home/suraj/.local/lib/python3.10/site-packages/rest_framework/views.py", line 469, in handle_exception
    self.raise_uncaught_exception(exc)
  File "/home/suraj/.local/lib/python3.10/site-packages/rest_framework/views.py", line 480, in raise_uncaught_exception
    raise exc
  File "/home/suraj/.local/lib/python3.10/site-packages/rest_framework/views.py", line 506, in dispatch
    response = handler(request, *args, **kwargs)
  File "/home/suraj/.local/lib/python3.10/site-packages/drf_spectacular/drainage.py", line 193, in wrapped_method
    return method(self, request, *args, **kwargs)
  File "/home/suraj/.local/lib/python3.10/site-packages/rest_framework/generics.py", line 190, in post
    return self.create(request, *args, **kwargs)
  File "/home/suraj/Desktop/Python/JobBackend/JobPortalBackend/payment/api/viewsets/payment.py", line 38, in create
    response = super().create(request, *args, **kwargs)
  File "/home/suraj/.local/lib/python3.10/site-packages/rest_framework/mixins.py", line 20, in create
    headers = self.get_success_headers(serializer.data)
  File "/home/suraj/.local/lib/python3.10/site-packages/rest_framework/serializers.py", line 555, in data
    ret = super().data
  File "/home/suraj/.local/lib/python3.10/site-packages/rest_framework/serializers.py", line 253, in data
    self._data = self.to_representation(self.instance)
  File "/home/suraj/.local/lib/python3.10/site-packages/rest_framework/serializers.py", line 522, in to_representation
    ret[field.field_name] = field.to_representation(attribute)
  File "/home/suraj/.local/lib/python3.10/site-packages/rest_framework/fields.py", line 1838, in to_representation
    return method(value)
  File "/home/suraj/Desktop/Python/JobBackend/JobPortalBackend/payment/api/serializers/payment.py", line 31, in get_khalti
    verification_response = req.post(
  File "/usr/lib/python3/dist-packages/requests/api.py", line 119, in post
    return request('post', url, data=data, json=json, **kwargs)
  File "/usr/lib/python3/dist-packages/requests/api.py", line 61, in request
    return session.request(method=method, url=url, **kwargs)
  File "/usr/lib/python3/dist-packages/requests/sessions.py", line 542, in request
    resp = self.send(prep, **send_kwargs)
  File "/usr/lib/python3/dist-packages/requests/sessions.py", line 655, in send
    r = adapter.send(request, **kwargs)
  File "/usr/lib/python3/dist-packages/requests/adapters.py", line 516, in send
    raise ConnectionError(e, request=request)
requests.exceptions.ConnectionError: HTTPSConnectionPool(host='a.khalti.com', port=443): Max retries exceeded with url: /api/v2/epayment/initiate/ (Caused by NewConnectionError('<urllib3.connection.HTTPSConnection object at 0x7fae607b2d70>: Failed to establish a new connection: [Errno -3] Temporary failure in name resolution'))
2023-05-28 07:26:10 ERROR django.server "POST /api/v1/payment/make-payment/ HTTP/1.1" 500 226148
2023-05-28 07:26:34 ERROR django.request Internal Server Error: /api/v1/payment/make-payment/
Traceback (most recent call last):
  File "/home/suraj/.local/lib/python3.10/site-packages/urllib3/connection.py", line 174, in _new_conn
    conn = connection.create_connection(
  File "/home/suraj/.local/lib/python3.10/site-packages/urllib3/util/connection.py", line 72, in create_connection
    for res in socket.getaddrinfo(host, port, family, socket.SOCK_STREAM):
  File "/usr/lib/python3.10/socket.py", line 955, in getaddrinfo
    for res in _socket.getaddrinfo(host, port, family, type, proto, flags):
socket.gaierror: [Errno -3] Temporary failure in name resolution

During handling of the above exception, another exception occurred:

Traceback (most recent call last):
  File "/home/suraj/.local/lib/python3.10/site-packages/urllib3/connectionpool.py", line 703, in urlopen
    httplib_response = self._make_request(
  File "/home/suraj/.local/lib/python3.10/site-packages/urllib3/connectionpool.py", line 386, in _make_request
    self._validate_conn(conn)
  File "/home/suraj/.local/lib/python3.10/site-packages/urllib3/connectionpool.py", line 1042, in _validate_conn
    conn.connect()
  File "/home/suraj/.local/lib/python3.10/site-packages/urllib3/connection.py", line 363, in connect
    self.sock = conn = self._new_conn()
  File "/home/suraj/.local/lib/python3.10/site-packages/urllib3/connection.py", line 186, in _new_conn
    raise NewConnectionError(
urllib3.exceptions.NewConnectionError: <urllib3.connection.HTTPSConnection object at 0x7f0e80f38850>: Failed to establish a new connection: [Errno -3] Temporary failure in name resolution

During handling of the above exception, another exception occurred:

Traceback (most recent call last):
  File "/usr/lib/python3/dist-packages/requests/adapters.py", line 439, in send
    resp = conn.urlopen(
  File "/home/suraj/.local/lib/python3.10/site-packages/urllib3/connectionpool.py", line 787, in urlopen
    retries = retries.increment(
  File "/home/suraj/.local/lib/python3.10/site-packages/urllib3/util/retry.py", line 592, in increment
    raise MaxRetryError(_pool, url, error or ResponseError(cause))
urllib3.exceptions.MaxRetryError: HTTPSConnectionPool(host='a.khalti.com', port=443): Max retries exceeded with url: /api/v2/epayment/initiate/ (Caused by NewConnectionError('<urllib3.connection.HTTPSConnection object at 0x7f0e80f38850>: Failed to establish a new connection: [Errno -3] Temporary failure in name resolution'))

During handling of the above exception, another exception occurred:

Traceback (most recent call last):
  File "/home/suraj/.local/lib/python3.10/site-packages/django/core/handlers/exception.py", line 55, in inner
    response = get_response(request)
  File "/home/suraj/.local/lib/python3.10/site-packages/django/core/handlers/base.py", line 197, in _get_response
    response = wrapped_callback(request, *callback_args, **callback_kwargs)
  File "/home/suraj/.local/lib/python3.10/site-packages/django/views/decorators/csrf.py", line 56, in wrapper_view
    return view_func(*args, **kwargs)
  File "/home/suraj/.local/lib/python3.10/site-packages/django/views/generic/base.py", line 104, in view
    return self.dispatch(request, *args, **kwargs)
  File "/home/suraj/.local/lib/python3.10/site-packages/rest_framework/views.py", line 509, in dispatch
    response = self.handle_exception(exc)
  File "/home/suraj/.local/lib/python3.10/site-packages/rest_framework/views.py", line 469, in handle_exception
    self.raise_uncaught_exception(exc)
  File "/home/suraj/.local/lib/python3.10/site-packages/rest_framework/views.py", line 480, in raise_uncaught_exception
    raise exc
  File "/home/suraj/.local/lib/python3.10/site-packages/rest_framework/views.py", line 506, in dispatch
    response = handler(request, *args, **kwargs)
  File "/home/suraj/.local/lib/python3.10/site-packages/drf_spectacular/drainage.py", line 193, in wrapped_method
    return method(self, request, *args, **kwargs)
  File "/home/suraj/.local/lib/python3.10/site-packages/rest_framework/generics.py", line 190, in post
    return self.create(request, *args, **kwargs)
  File "/home/suraj/Desktop/Python/JobBackend/JobPortalBackend/payment/api/viewsets/payment.py", line 38, in create
    response = super().create(request, *args, **kwargs)
  File "/home/suraj/.local/lib/python3.10/site-packages/rest_framework/mixins.py", line 20, in create
    headers = self.get_success_headers(serializer.data)
  File "/home/suraj/.local/lib/python3.10/site-packages/rest_framework/serializers.py", line 555, in data
    ret = super().data
  File "/home/suraj/.local/lib/python3.10/site-packages/rest_framework/serializers.py", line 253, in data
    self._data = self.to_representation(self.instance)
  File "/home/suraj/.local/lib/python3.10/site-packages/rest_framework/serializers.py", line 522, in to_representation
    ret[field.field_name] = field.to_representation(attribute)
  File "/home/suraj/.local/lib/python3.10/site-packages/rest_framework/fields.py", line 1838, in to_representation
    return method(value)
  File "/home/suraj/Desktop/Python/JobBackend/JobPortalBackend/payment/api/serializers/payment.py", line 31, in get_khalti
    verification_response = req.post(
  File "/usr/lib/python3/dist-packages/requests/api.py", line 119, in post
    return request('post', url, data=data, json=json, **kwargs)
  File "/usr/lib/python3/dist-packages/requests/api.py", line 61, in request
    return session.request(method=method, url=url, **kwargs)
  File "/usr/lib/python3/dist-packages/requests/sessions.py", line 542, in request
    resp = self.send(prep, **send_kwargs)
  File "/usr/lib/python3/dist-packages/requests/sessions.py", line 655, in send
    r = adapter.send(request, **kwargs)
  File "/usr/lib/python3/dist-packages/requests/adapters.py", line 516, in send
    raise ConnectionError(e, request=request)
requests.exceptions.ConnectionError: HTTPSConnectionPool(host='a.khalti.com', port=443): Max retries exceeded with url: /api/v2/epayment/initiate/ (Caused by NewConnectionError('<urllib3.connection.HTTPSConnection object at 0x7f0e80f38850>: Failed to establish a new connection: [Errno -3] Temporary failure in name resolution'))
2023-05-28 07:26:34 ERROR django.server "POST /api/v1/payment/make-payment/ HTTP/1.1" 500 226148
2023-05-28 07:42:31 WARNING django.request Not Found: /favicon.ico
2023-05-28 07:42:31 WARNING django.server "GET /favicon.ico HTTP/1.1" 404 2476
2023-05-28 07:42:41 ERROR django.request Internal Server Error: /db/admin/login/payment/
Traceback (most recent call last):
  File "/home/suraj/.local/lib/python3.10/site-packages/django/db/models/options.py", line 681, in get_field
    return self.fields_map[field_name]
KeyError: '__str__'

During handling of the above exception, another exception occurred:

Traceback (most recent call last):
  File "/home/suraj/.local/lib/python3.10/site-packages/django/contrib/admin/utils.py", line 272, in lookup_field
    f = _get_non_gfk_field(opts, name)
  File "/home/suraj/.local/lib/python3.10/site-packages/django/contrib/admin/utils.py", line 303, in _get_non_gfk_field
    field = opts.get_field(name)
  File "/home/suraj/.local/lib/python3.10/site-packages/django/db/models/options.py", line 683, in get_field
    raise FieldDoesNotExist(
django.core.exceptions.FieldDoesNotExist: Payment has no field named '__str__'

During handling of the above exception, another exception occurred:

Traceback (most recent call last):
  File "/home/suraj/.local/lib/python3.10/site-packages/django/core/handlers/exception.py", line 55, in inner
    response = get_response(request)
  File "/home/suraj/.local/lib/python3.10/site-packages/django/core/handlers/base.py", line 220, in _get_response
    response = response.render()
  File "/home/suraj/.local/lib/python3.10/site-packages/django/template/response.py", line 111, in render
    self.content = self.rendered_content
  File "/home/suraj/.local/lib/python3.10/site-packages/django/template/response.py", line 89, in rendered_content
    return template.render(context, self._request)
  File "/home/suraj/.local/lib/python3.10/site-packages/django/template/backends/django.py", line 61, in render
    return self.template.render(context)
  File "/home/suraj/.local/lib/python3.10/site-packages/django/template/base.py", line 175, in render
    return self._render(context)
  File "/home/suraj/.local/lib/python3.10/site-packages/django/template/base.py", line 167, in _render
    return self.nodelist.render(context)
  File "/home/suraj/.local/lib/python3.10/site-packages/django/template/base.py", line 1005, in render
    return SafeString("".join([node.render_annotated(context) for node in self]))
  File "/home/suraj/.local/lib/python3.10/site-packages/django/template/base.py", line 1005, in <listcomp>
    return SafeString("".join([node.render_annotated(context) for node in self]))
  File "/home/suraj/.local/lib/python3.10/site-packages/django/template/base.py", line 966, in render_annotated
    return self.render(context)
  File "/home/suraj/.local/lib/python3.10/site-packages/django/template/loader_tags.py", line 157, in render
    return compiled_parent._render(context)
  File "/home/suraj/.local/lib/python3.10/site-packages/django/template/base.py", line 167, in _render
    return self.nodelist.render(context)
  File "/home/suraj/.local/lib/python3.10/site-packages/django/template/base.py", line 1005, in render
    return SafeString("".join([node.render_annotated(context) for node in self]))
  File "/home/suraj/.local/lib/python3.10/site-packages/django/template/base.py", line 1005, in <listcomp>
    return SafeString("".join([node.render_annotated(context) for node in self]))
  File "/home/suraj/.local/lib/python3.10/site-packages/django/template/base.py", line 966, in render_annotated
    return self.render(context)
  File "/home/suraj/.local/lib/python3.10/site-packages/django/template/loader_tags.py", line 157, in render
    return compiled_parent._render(context)
  File "/home/suraj/.local/lib/python3.10/site-packages/django/template/base.py", line 167, in _render
    return self.nodelist.render(context)
  File "/home/suraj/.local/lib/python3.10/site-packages/django/template/base.py", line 1005, in render
    return SafeString("".join([node.render_annotated(context) for node in self]))
  File "/home/suraj/.local/lib/python3.10/site-packages/django/template/base.py", line 1005, in <listcomp>
    return SafeString("".join([node.render_annotated(context) for node in self]))
  File "/home/suraj/.local/lib/python3.10/site-packages/django/template/base.py", line 966, in render_annotated
    return self.render(context)
  File "/home/suraj/.local/lib/python3.10/site-packages/django/template/loader_tags.py", line 63, in render
    result = block.nodelist.render(context)
  File "/home/suraj/.local/lib/python3.10/site-packages/django/template/base.py", line 1005, in render
    return SafeString("".join([node.render_annotated(context) for node in self]))
  File "/home/suraj/.local/lib/python3.10/site-packages/django/template/base.py", line 1005, in <listcomp>
    return SafeString("".join([node.render_annotated(context) for node in self]))
  File "/home/suraj/.local/lib/python3.10/site-packages/django/template/base.py", line 966, in render_annotated
    return self.render(context)
  File "/home/suraj/.local/lib/python3.10/site-packages/django/template/loader_tags.py", line 63, in render
    result = block.nodelist.render(context)
  File "/home/suraj/.local/lib/python3.10/site-packages/django/template/base.py", line 1005, in render
    return SafeString("".join([node.render_annotated(context) for node in self]))
  File "/home/suraj/.local/lib/python3.10/site-packages/django/template/base.py", line 1005, in <listcomp>
    return SafeString("".join([node.render_annotated(context) for node in self]))
  File "/home/suraj/.local/lib/python3.10/site-packages/django/template/base.py", line 966, in render_annotated
    return self.render(context)
  File "/home/suraj/.local/lib/python3.10/site-packages/django/contrib/admin/templatetags/base.py", line 45, in render
    return super().render(context)
  File "/home/suraj/.local/lib/python3.10/site-packages/django/template/library.py", line 258, in render
    _dict = self.func(*resolved_args, **resolved_kwargs)
  File "/home/suraj/.local/lib/python3.10/site-packages/django/contrib/admin/templatetags/admin_list.py", line 336, in result_list
    "results": list(results(cl)),
  File "/home/suraj/.local/lib/python3.10/site-packages/django/contrib/admin/templatetags/admin_list.py", line 312, in results
    yield ResultList(None, items_for_result(cl, res, None))
  File "/home/suraj/.local/lib/python3.10/site-packages/django/contrib/admin/templatetags/admin_list.py", line 303, in __init__
    super().__init__(*items)
  File "/home/suraj/.local/lib/python3.10/site-packages/django/contrib/admin/templatetags/admin_list.py", line 213, in items_for_result
    f, attr, value = lookup_field(field_name, result, cl.model_admin)
  File "/home/suraj/.local/lib/python3.10/site-packages/django/contrib/admin/utils.py", line 285, in lookup_field
    value = attr()
  File "/home/suraj/Desktop/Python/JobBackend/JobPortalBackend/login/models.py", line 70, in __str__
    return f"{self.id}--{self.reference_code}"
AttributeError: 'Payment' object has no attribute 'reference_code'
2023-05-28 07:42:41 ERROR django.server "GET /db/admin/login/payment/ HTTP/1.1" 500 430648
2023-05-28 07:42:47 ERROR django.request Internal Server Error: /db/admin/login/payment/
Traceback (most recent call last):
  File "/home/suraj/.local/lib/python3.10/site-packages/django/db/models/options.py", line 681, in get_field
    return self.fields_map[field_name]
KeyError: '__str__'

During handling of the above exception, another exception occurred:

Traceback (most recent call last):
  File "/home/suraj/.local/lib/python3.10/site-packages/django/contrib/admin/utils.py", line 272, in lookup_field
    f = _get_non_gfk_field(opts, name)
  File "/home/suraj/.local/lib/python3.10/site-packages/django/contrib/admin/utils.py", line 303, in _get_non_gfk_field
    field = opts.get_field(name)
  File "/home/suraj/.local/lib/python3.10/site-packages/django/db/models/options.py", line 683, in get_field
    raise FieldDoesNotExist(
django.core.exceptions.FieldDoesNotExist: Payment has no field named '__str__'

During handling of the above exception, another exception occurred:

Traceback (most recent call last):
  File "/home/suraj/.local/lib/python3.10/site-packages/django/core/handlers/exception.py", line 55, in inner
    response = get_response(request)
  File "/home/suraj/.local/lib/python3.10/site-packages/django/core/handlers/base.py", line 220, in _get_response
    response = response.render()
  File "/home/suraj/.local/lib/python3.10/site-packages/django/template/response.py", line 111, in render
    self.content = self.rendered_content
  File "/home/suraj/.local/lib/python3.10/site-packages/django/template/response.py", line 89, in rendered_content
    return template.render(context, self._request)
  File "/home/suraj/.local/lib/python3.10/site-packages/django/template/backends/django.py", line 61, in render
    return self.template.render(context)
  File "/home/suraj/.local/lib/python3.10/site-packages/django/template/base.py", line 175, in render
    return self._render(context)
  File "/home/suraj/.local/lib/python3.10/site-packages/django/template/base.py", line 167, in _render
    return self.nodelist.render(context)
  File "/home/suraj/.local/lib/python3.10/site-packages/django/template/base.py", line 1005, in render
    return SafeString("".join([node.render_annotated(context) for node in self]))
  File "/home/suraj/.local/lib/python3.10/site-packages/django/template/base.py", line 1005, in <listcomp>
    return SafeString("".join([node.render_annotated(context) for node in self]))
  File "/home/suraj/.local/lib/python3.10/site-packages/django/template/base.py", line 966, in render_annotated
    return self.render(context)
  File "/home/suraj/.local/lib/python3.10/site-packages/django/template/loader_tags.py", line 157, in render
    return compiled_parent._render(context)
  File "/home/suraj/.local/lib/python3.10/site-packages/django/template/base.py", line 167, in _render
    return self.nodelist.render(context)
  File "/home/suraj/.local/lib/python3.10/site-packages/django/template/base.py", line 1005, in render
    return SafeString("".join([node.render_annotated(context) for node in self]))
  File "/home/suraj/.local/lib/python3.10/site-packages/django/template/base.py", line 1005, in <listcomp>
    return SafeString("".join([node.render_annotated(context) for node in self]))
  File "/home/suraj/.local/lib/python3.10/site-packages/django/template/base.py", line 966, in render_annotated
    return self.render(context)
  File "/home/suraj/.local/lib/python3.10/site-packages/django/template/loader_tags.py", line 157, in render
    return compiled_parent._render(context)
  File "/home/suraj/.local/lib/python3.10/site-packages/django/template/base.py", line 167, in _render
    return self.nodelist.render(context)
  File "/home/suraj/.local/lib/python3.10/site-packages/django/template/base.py", line 1005, in render
    return SafeString("".join([node.render_annotated(context) for node in self]))
  File "/home/suraj/.local/lib/python3.10/site-packages/django/template/base.py", line 1005, in <listcomp>
    return SafeString("".join([node.render_annotated(context) for node in self]))
  File "/home/suraj/.local/lib/python3.10/site-packages/django/template/base.py", line 966, in render_annotated
    return self.render(context)
  File "/home/suraj/.local/lib/python3.10/site-packages/django/template/loader_tags.py", line 63, in render
    result = block.nodelist.render(context)
  File "/home/suraj/.local/lib/python3.10/site-packages/django/template/base.py", line 1005, in render
    return SafeString("".join([node.render_annotated(context) for node in self]))
  File "/home/suraj/.local/lib/python3.10/site-packages/django/template/base.py", line 1005, in <listcomp>
    return SafeString("".join([node.render_annotated(context) for node in self]))
  File "/home/suraj/.local/lib/python3.10/site-packages/django/template/base.py", line 966, in render_annotated
    return self.render(context)
  File "/home/suraj/.local/lib/python3.10/site-packages/django/template/loader_tags.py", line 63, in render
    result = block.nodelist.render(context)
  File "/home/suraj/.local/lib/python3.10/site-packages/django/template/base.py", line 1005, in render
    return SafeString("".join([node.render_annotated(context) for node in self]))
  File "/home/suraj/.local/lib/python3.10/site-packages/django/template/base.py", line 1005, in <listcomp>
    return SafeString("".join([node.render_annotated(context) for node in self]))
  File "/home/suraj/.local/lib/python3.10/site-packages/django/template/base.py", line 966, in render_annotated
    return self.render(context)
  File "/home/suraj/.local/lib/python3.10/site-packages/django/contrib/admin/templatetags/base.py", line 45, in render
    return super().render(context)
  File "/home/suraj/.local/lib/python3.10/site-packages/django/template/library.py", line 258, in render
    _dict = self.func(*resolved_args, **resolved_kwargs)
  File "/home/suraj/.local/lib/python3.10/site-packages/django/contrib/admin/templatetags/admin_list.py", line 336, in result_list
    "results": list(results(cl)),
  File "/home/suraj/.local/lib/python3.10/site-packages/django/contrib/admin/templatetags/admin_list.py", line 312, in results
    yield ResultList(None, items_for_result(cl, res, None))
  File "/home/suraj/.local/lib/python3.10/site-packages/django/contrib/admin/templatetags/admin_list.py", line 303, in __init__
    super().__init__(*items)
  File "/home/suraj/.local/lib/python3.10/site-packages/django/contrib/admin/templatetags/admin_list.py", line 213, in items_for_result
    f, attr, value = lookup_field(field_name, result, cl.model_admin)
  File "/home/suraj/.local/lib/python3.10/site-packages/django/contrib/admin/utils.py", line 285, in lookup_field
    value = attr()
  File "/home/suraj/Desktop/Python/JobBackend/JobPortalBackend/login/models.py", line 70, in __str__
    return f"{self.id}--{self.reference_code}"
AttributeError: 'Payment' object has no attribute 'reference_code'
2023-05-28 07:42:47 ERROR django.server "GET /db/admin/login/payment/ HTTP/1.1" 500 430785
2023-05-28 07:43:03 ERROR django.request Internal Server Error: /db/admin/login/payment/
Traceback (most recent call last):
  File "/home/suraj/.local/lib/python3.10/site-packages/django/db/models/options.py", line 681, in get_field
    return self.fields_map[field_name]
KeyError: '__str__'

During handling of the above exception, another exception occurred:

Traceback (most recent call last):
  File "/home/suraj/.local/lib/python3.10/site-packages/django/contrib/admin/utils.py", line 272, in lookup_field
    f = _get_non_gfk_field(opts, name)
  File "/home/suraj/.local/lib/python3.10/site-packages/django/contrib/admin/utils.py", line 303, in _get_non_gfk_field
    field = opts.get_field(name)
  File "/home/suraj/.local/lib/python3.10/site-packages/django/db/models/options.py", line 683, in get_field
    raise FieldDoesNotExist(
django.core.exceptions.FieldDoesNotExist: Payment has no field named '__str__'

During handling of the above exception, another exception occurred:

Traceback (most recent call last):
  File "/home/suraj/.local/lib/python3.10/site-packages/django/core/handlers/exception.py", line 55, in inner
    response = get_response(request)
  File "/home/suraj/.local/lib/python3.10/site-packages/django/core/handlers/base.py", line 220, in _get_response
    response = response.render()
  File "/home/suraj/.local/lib/python3.10/site-packages/django/template/response.py", line 111, in render
    self.content = self.rendered_content
  File "/home/suraj/.local/lib/python3.10/site-packages/django/template/response.py", line 89, in rendered_content
    return template.render(context, self._request)
  File "/home/suraj/.local/lib/python3.10/site-packages/django/template/backends/django.py", line 61, in render
    return self.template.render(context)
  File "/home/suraj/.local/lib/python3.10/site-packages/django/template/base.py", line 175, in render
    return self._render(context)
  File "/home/suraj/.local/lib/python3.10/site-packages/django/template/base.py", line 167, in _render
    return self.nodelist.render(context)
  File "/home/suraj/.local/lib/python3.10/site-packages/django/template/base.py", line 1005, in render
    return SafeString("".join([node.render_annotated(context) for node in self]))
  File "/home/suraj/.local/lib/python3.10/site-packages/django/template/base.py", line 1005, in <listcomp>
    return SafeString("".join([node.render_annotated(context) for node in self]))
  File "/home/suraj/.local/lib/python3.10/site-packages/django/template/base.py", line 966, in render_annotated
    return self.render(context)
  File "/home/suraj/.local/lib/python3.10/site-packages/django/template/loader_tags.py", line 157, in render
    return compiled_parent._render(context)
  File "/home/suraj/.local/lib/python3.10/site-packages/django/template/base.py", line 167, in _render
    return self.nodelist.render(context)
  File "/home/suraj/.local/lib/python3.10/site-packages/django/template/base.py", line 1005, in render
    return SafeString("".join([node.render_annotated(context) for node in self]))
  File "/home/suraj/.local/lib/python3.10/site-packages/django/template/base.py", line 1005, in <listcomp>
    return SafeString("".join([node.render_annotated(context) for node in self]))
  File "/home/suraj/.local/lib/python3.10/site-packages/django/template/base.py", line 966, in render_annotated
    return self.render(context)
  File "/home/suraj/.local/lib/python3.10/site-packages/django/template/loader_tags.py", line 157, in render
    return compiled_parent._render(context)
  File "/home/suraj/.local/lib/python3.10/site-packages/django/template/base.py", line 167, in _render
    return self.nodelist.render(context)
  File "/home/suraj/.local/lib/python3.10/site-packages/django/template/base.py", line 1005, in render
    return SafeString("".join([node.render_annotated(context) for node in self]))
  File "/home/suraj/.local/lib/python3.10/site-packages/django/template/base.py", line 1005, in <listcomp>
    return SafeString("".join([node.render_annotated(context) for node in self]))
  File "/home/suraj/.local/lib/python3.10/site-packages/django/template/base.py", line 966, in render_annotated
    return self.render(context)
  File "/home/suraj/.local/lib/python3.10/site-packages/django/template/loader_tags.py", line 63, in render
    result = block.nodelist.render(context)
  File "/home/suraj/.local/lib/python3.10/site-packages/django/template/base.py", line 1005, in render
    return SafeString("".join([node.render_annotated(context) for node in self]))
  File "/home/suraj/.local/lib/python3.10/site-packages/django/template/base.py", line 1005, in <listcomp>
    return SafeString("".join([node.render_annotated(context) for node in self]))
  File "/home/suraj/.local/lib/python3.10/site-packages/django/template/base.py", line 966, in render_annotated
    return self.render(context)
  File "/home/suraj/.local/lib/python3.10/site-packages/django/template/loader_tags.py", line 63, in render
    result = block.nodelist.render(context)
  File "/home/suraj/.local/lib/python3.10/site-packages/django/template/base.py", line 1005, in render
    return SafeString("".join([node.render_annotated(context) for node in self]))
  File "/home/suraj/.local/lib/python3.10/site-packages/django/template/base.py", line 1005, in <listcomp>
    return SafeString("".join([node.render_annotated(context) for node in self]))
  File "/home/suraj/.local/lib/python3.10/site-packages/django/template/base.py", line 966, in render_annotated
    return self.render(context)
  File "/home/suraj/.local/lib/python3.10/site-packages/django/contrib/admin/templatetags/base.py", line 45, in render
    return super().render(context)
  File "/home/suraj/.local/lib/python3.10/site-packages/django/template/library.py", line 258, in render
    _dict = self.func(*resolved_args, **resolved_kwargs)
  File "/home/suraj/.local/lib/python3.10/site-packages/django/contrib/admin/templatetags/admin_list.py", line 336, in result_list
    "results": list(results(cl)),
  File "/home/suraj/.local/lib/python3.10/site-packages/django/contrib/admin/templatetags/admin_list.py", line 312, in results
    yield ResultList(None, items_for_result(cl, res, None))
  File "/home/suraj/.local/lib/python3.10/site-packages/django/contrib/admin/templatetags/admin_list.py", line 303, in __init__
    super().__init__(*items)
  File "/home/suraj/.local/lib/python3.10/site-packages/django/contrib/admin/templatetags/admin_list.py", line 213, in items_for_result
    f, attr, value = lookup_field(field_name, result, cl.model_admin)
  File "/home/suraj/.local/lib/python3.10/site-packages/django/contrib/admin/utils.py", line 285, in lookup_field
    value = attr()
  File "/home/suraj/Desktop/Python/JobBackend/JobPortalBackend/login/models.py", line 70, in __str__
    return f"{self.id}--{self.reference_code}"
AttributeError: 'Payment' object has no attribute 'reference_code'
2023-05-28 07:43:03 ERROR django.server "GET /db/admin/login/payment/ HTTP/1.1" 500 430648
